<mujoco model="humanoid">
  <compiler coordinate="local" angle="radian"/>
  <default>
    <joint damping="0.0" armature="0.01" stiffness="0.0" limited="true"/>
    <geom conaffinity="1" condim="3" contype="7" margin="0.001" rgba="0.8 0.6 .4 1"/>
  </default>
  <asset>
    <texture type="skybox" builtin="gradient" rgb1=".4 .5 .6" rgb2="0 0 0" width="100" height="100"/>
    <texture builtin="flat" height="1278" mark="cross" markrgb="1 1 1" name="texgeom" random="0.01" rgb1="0.8 0.6 0.4" rgb2="0.8 0.6 0.4" type="cube" width="127"/>
    <texture builtin="checker" height="100" name="texplane" rgb1="0 0 0" rgb2="0.8 0.8 0.8" type="2d" width="100"/>
    <material name="MatPlane" reflectance="0.5" shininess="1" specular="1" texrepeat="60 60" texture="texplane"/>
    <material name="geom" texture="texgeom" texuniform="true"/>
  </asset>
  <worldbody>
    <light cutoff="100" diffuse="1 1 1" dir="-0 0 -1.3" directional="true" exponent="1" pos="0 0 1.3" specular=".1 .1 .1"/>
    <geom conaffinity="1" condim="3" name="floor" pos="0 0 0" rgba="0.8 0.9 0.8 1" size="100 100 .2" type="plane" material="MatPlane"/>
    <body name="Pelvis" pos="0.0007 -0.3643 0.008">
      <freejoint name="Pelvis"/>
      <geom type="sphere" contype="1" conaffinity="1" density="500" size="0.0931" pos="0.0000 0.0000 0.0000" name="Pelvis"/>
      <body name="L_Hip" pos="-0.0288 0.0516 -0.0908">
        <joint name="L_Hip_x" type="hinge" pos="0 0 0" axis="1 0 0" stiffness="800" damping="80" armature="0.02" range="-180.0000 180.0000"/>
        <joint name="L_Hip_y" type="hinge" pos="0 0 0" axis="0 1 0" stiffness="800" damping="80" armature="0.02" range="-180.0000 180.0000"/>
        <joint name="L_Hip_z" type="hinge" pos="0 0 0" axis="0 0 1" stiffness="800" damping="80" armature="0.02" range="-180.0000 180.0000"/>
        <geom type="capsule" contype="1" conaffinity="1" density="500" fromto="-0.0009 0.0137 -0.0785 -0.0036 0.0548 -0.3142" size="0.058" name="L_Hip"/>
        <body name="L_Knee" pos="-0.0044 0.0685 -0.3927">
          <joint name="L_Knee_x" type="hinge" pos="0 0 0" axis="1 0 0" stiffness="800" damping="80" armature="0.02" range="-180.0000 180.0000"/>
          <joint name="L_Knee_y" type="hinge" pos="0 0 0" axis="0 1 0" stiffness="800" damping="80" armature="0.02" range="-180.0000 180.0000"/>
          <joint name="L_Knee_z" type="hinge" pos="0 0 0" axis="0 0 1" stiffness="800" damping="80" armature="0.02" range="-180.0000 180.0000"/>
          <geom type="capsule" contype="1" conaffinity="1" density="500" fromto="-0.0079 -0.0088 -0.0819 -0.0317 -0.0353 -0.3278" size="0.0532" name="L_Knee"/>
          <body name="L_Ankle" pos="-0.0396 -0.0441 -0.4097">
            <joint name="L_Ankle_x" type="hinge" pos="0 0 0" axis="1 0 0" stiffness="800" damping="80" armature="0.02" range="-180.0000 180.0000"/>
            <joint name="L_Ankle_y" type="hinge" pos="0 0 0" axis="0 1 0" stiffness="800" damping="80" armature="0.02" range="-180.0000 180.0000"/>
            <joint name="L_Ankle_z" type="hinge" pos="0 0 0" axis="0 0 1" stiffness="800" damping="80" armature="0.02" range="-180.0000 180.0000"/>
            <geom type="box" contype="1" conaffinity="1" density="500" pos="0.0677 0.0212 -0.0294" size="0.0935 0.0519 0.0207" quat="0.9885 0.0000 0.0000 0.1510" name="L_Ankle"/>
            <body name="L_Toe" pos="0.1354 0.0423 -0.0588">
              <joint name="L_Toe_x" type="hinge" pos="0 0 0" axis="1 0 0" stiffness="500" damping="50" armature="0.02" range="-180.0000 180.0000"/>
              <joint name="L_Toe_y" type="hinge" pos="0 0 0" axis="0 1 0" stiffness="500" damping="50" armature="0.02" range="-180.0000 180.0000"/>
              <joint name="L_Toe_z" type="hinge" pos="0 0 0" axis="0 0 1" stiffness="500" damping="50" armature="0.02" range="-180.0000 180.0000"/>
              <geom type="box" contype="1" conaffinity="1" density="500" pos="0.0000 0.0000 0.0300" size="0.001 0.0025 0.0011" quat="0.9878 0.0000 0.0000 0.1554" name="L_Toe"/>
            </body>
          </body>
        </body>
      </body>
      <body name="R_Hip" pos="-0.0218 -0.0531 -0.1009">
        <joint name="R_Hip_x" type="hinge" pos="0 0 0" axis="1 0 0" stiffness="800" damping="80" armature="0.02" range="-180.0000 180.0000"/>
        <joint name="R_Hip_y" type="hinge" pos="0 0 0" axis="0 1 0" stiffness="800" damping="80" armature="0.02" range="-180.0000 180.0000"/>
        <joint name="R_Hip_z" type="hinge" pos="0 0 0" axis="0 0 1" stiffness="800" damping="80" armature="0.02" range="-180.0000 180.0000"/>
        <geom type="capsule" contype="1" conaffinity="1" density="500" fromto="-0.0024 -0.0105 -0.0752 -0.0095 -0.0419 -0.3010" size="0.0579" name="R_Hip"/>
        <body name="R_Knee" pos="-0.0118 -0.0523 -0.3762">
          <joint name="R_Knee_x" type="hinge" pos="0 0 0" axis="1 0 0" stiffness="800" damping="80" armature="0.02" range="-180.0000 180.0000"/>
          <joint name="R_Knee_y" type="hinge" pos="0 0 0" axis="0 1 0" stiffness="800" damping="80" armature="0.02" range="-180.0000 180.0000"/>
          <joint name="R_Knee_z" type="hinge" pos="0 0 0" axis="0 0 1" stiffness="800" damping="80" armature="0.02" range="-180.0000 180.0000"/>
          <geom type="capsule" contype="1" conaffinity="1" density="500" fromto="-0.0078 0.0034 -0.0846 -0.0311 0.0138 -0.3385" size="0.0529" name="R_Knee"/>
          <body name="R_Ankle" pos="-0.0388 0.0172 -0.4231">
            <joint name="R_Ankle_x" type="hinge" pos="0 0 0" axis="1 0 0" stiffness="800" damping="80" armature="0.02" range="-180.0000 180.0000"/>
            <joint name="R_Ankle_y" type="hinge" pos="0 0 0" axis="0 1 0" stiffness="800" damping="80" armature="0.02" range="-180.0000 180.0000"/>
            <joint name="R_Ankle_z" type="hinge" pos="0 0 0" axis="0 0 1" stiffness="800" damping="80" armature="0.02" range="-180.0000 180.0000"/>
            <geom type="box" contype="1" conaffinity="1" density="500" pos="0.0709 -0.0168 -0.0291" size="0.0935 0.0519 0.0251" quat="0.9932 0.0000 0.0000 -0.1162" name="R_Ankle"/>
            <body name="R_Toe" pos="0.1418 -0.0336 -0.0583">
              <joint name="R_Toe_x" type="hinge" pos="0 0 0" axis="1 0 0" stiffness="500" damping="50" armature="0.02" range="-180.0000 180.0000"/>
              <joint name="R_Toe_y" type="hinge" pos="0 0 0" axis="0 1 0" stiffness="500" damping="50" armature="0.02" range="-180.0000 180.0000"/>
              <joint name="R_Toe_z" type="hinge" pos="0 0 0" axis="0 0 1" stiffness="500" damping="50" armature="0.02" range="-180.0000 180.0000"/>
              <geom type="box" contype="1" conaffinity="1" density="500" pos="0.0000 0.0000 0.0254" size="0.001 0.0025 0.0011" quat="0.9941 0.0000 0.0000 -0.1081" name="R_Toe"/>
            </body>
          </body>
        </body>
      </body>
      <body name="Torso" pos="-0.0318 -0.0018 0.1046">
        <joint name="Torso_x" type="hinge" pos="0 0 0" axis="1 0 0" stiffness="1000" damping="100" armature="0.02" range="-180.0000 180.0000"/>
        <joint name="Torso_y" type="hinge" pos="0 0 0" axis="0 1 0" stiffness="1000" damping="100" armature="0.02" range="-180.0000 180.0000"/>
        <joint name="Torso_z" type="hinge" pos="0 0 0" axis="0 0 1" stiffness="1000" damping="100" armature="0.02" range="-180.0000 180.0000"/>
        <geom type="capsule" contype="1" conaffinity="1" density="500" fromto="0.0026 0.0035 0.0875 0.0017 0.0023 0.0583" size="0.0588" name="Torso"/>
        <body name="Spine" pos="0.0043 0.0058 0.1458">
          <joint name="Spine_x" type="hinge" pos="0 0 0" axis="1 0 0" stiffness="1000" damping="100" armature="0.02" range="-180.0000 180.0000"/>
          <joint name="Spine_y" type="hinge" pos="0 0 0" axis="0 1 0" stiffness="1000" damping="100" armature="0.02" range="-180.0000 180.0000"/>
          <joint name="Spine_z" type="hinge" pos="0 0 0" axis="0 0 1" stiffness="1000" damping="100" armature="0.02" range="-180.0000 180.0000"/>
          <geom type="capsule" contype="1" conaffinity="1" density="500" fromto="0.0106 -0.0031 0.0337 0.0071 -0.0021 0.0224" size="0.077" name="Spine"/>
          <body name="Chest" pos="0.0177 -0.0051 0.0561">
            <joint name="Chest_x" type="hinge" pos="0 0 0" axis="1 0 0" stiffness="1000" damping="100" armature="0.02" range="-180.0000 180.0000"/>
            <joint name="Chest_y" type="hinge" pos="0 0 0" axis="0 1 0" stiffness="1000" damping="100" armature="0.02" range="-180.0000 180.0000"/>
            <joint name="Chest_z" type="hinge" pos="0 0 0" axis="0 0 1" stiffness="1000" damping="100" armature="0.02" range="-180.0000 180.0000"/>
            <geom type="capsule" contype="1" conaffinity="1" density="500" fromto="-0.0061 -0.0015 0.0626 -0.0041 -0.0010 0.0417" size="0.0958" name="Chest"/>
            <body name="Neck" pos="-0.0204 -0.0071 0.1632">
              <joint name="Neck_x" type="hinge" pos="0 0 0" axis="1 0 0" stiffness="500" damping="50" armature="0.02" range="-180.0000 180.0000"/>
              <joint name="Neck_y" type="hinge" pos="0 0 0" axis="0 1 0" stiffness="500" damping="50" armature="0.02" range="-180.0000 180.0000"/>
              <joint name="Neck_z" type="hinge" pos="0 0 0" axis="0 0 1" stiffness="500" damping="50" armature="0.02" range="-180.0000 180.0000"/>
              <geom type="capsule" contype="1" conaffinity="1" density="500" fromto="0.0040 0.0042 0.0367 0.0160 0.0167 0.1466" size="0.0418" name="Neck"/>
              <body name="Head" pos="0.0201 0.0208 0.1833">
                <joint name="Head_x" type="hinge" pos="0 0 0" axis="1 0 0" stiffness="500" damping="50" armature="0.02" range="-180.0000 180.0000"/>
                <joint name="Head_y" type="hinge" pos="0 0 0" axis="0 1 0" stiffness="500" damping="50" armature="0.02" range="-180.0000 180.0000"/>
                <joint name="Head_z" type="hinge" pos="0 0 0" axis="0 0 1" stiffness="500" damping="50" armature="0.02" range="-180.0000 180.0000"/>
                <geom type="sphere" contype="1" conaffinity="1" density="500" size="0.1044" pos="0.0000 0.0000 0.0000" name="Head"/>
              </body>
            </body>
            <body name="L_Thorax" pos="-0.0033 0.0393 0.0749">
              <joint name="L_Thorax_x" type="hinge" pos="0 0 0" axis="1 0 0" stiffness="500" damping="50" armature="0.02" range="-180.0000 180.0000"/>
              <joint name="L_Thorax_y" type="hinge" pos="0 0 0" axis="0 1 0" stiffness="500" damping="50" armature="0.02" range="-180.0000 180.0000"/>
              <joint name="L_Thorax_z" type="hinge" pos="0 0 0" axis="0 0 1" stiffness="500" damping="50" armature="0.02" range="-180.0000 180.0000"/>
              <geom type="capsule" contype="1" conaffinity="1" density="500" fromto="-0.0022 0.0255 0.0111 -0.0087 0.1022 0.0445" size="0.0463" name="L_Thorax"/>
              <body name="L_Shoulder" pos="-0.0108 0.1277 0.0557">
                <joint name="L_Shoulder_x" type="hinge" pos="0 0 0" axis="1 0 0" stiffness="500" damping="50" armature="0.02" range="-180.0000 180.0000"/>
                <joint name="L_Shoulder_y" type="hinge" pos="0 0 0" axis="0 1 0" stiffness="500" damping="50" armature="0.02" range="-180.0000 180.0000"/>
                <joint name="L_Shoulder_z" type="hinge" pos="0 0 0" axis="0 0 1" stiffness="500" damping="50" armature="0.02" range="-180.0000 180.0000"/>
                <geom type="capsule" contype="1" conaffinity="1" density="500" fromto="-0.0083 0.0502 -0.0152 -0.0332 0.2009 -0.0608" size="0.0521" name="L_Shoulder"/>
                <body name="L_Elbow" pos="-0.0414 0.2511 -0.076">
                  <joint name="L_Elbow_x" type="hinge" pos="0 0 0" axis="1 0 0" stiffness="500" damping="50" armature="0.02" range="-720.0000 720.0000"/>
                  <joint name="L_Elbow_y" type="hinge" pos="0 0 0" axis="0 1 0" stiffness="500" damping="50" armature="0.02" range="-720.0000 720.0000"/>
                  <joint name="L_Elbow_z" type="hinge" pos="0 0 0" axis="0 0 1" stiffness="500" damping="50" armature="0.02" range="-720.0000 720.0000"/>
                  <geom type="capsule" contype="1" conaffinity="1" density="500" fromto="-0.0003 0.0536 0.0044 -0.0013 0.2143 0.0175" size="0.0399" name="L_Elbow"/>
                  <body name="L_Wrist" pos="-0.0016 0.2679 0.0219">
                    <joint name="L_Wrist_x" type="hinge" pos="0 0 0" axis="1 0 0" stiffness="300" damping="30" armature="0.02" range="-180.0000 180.0000"/>
                    <joint name="L_Wrist_y" type="hinge" pos="0 0 0" axis="0 1 0" stiffness="300" damping="30" armature="0.02" range="-180.0000 180.0000"/>
                    <joint name="L_Wrist_z" type="hinge" pos="0 0 0" axis="0 0 1" stiffness="300" damping="30" armature="0.02" range="-180.0000 180.0000"/>
                    <geom type="box" contype="1" conaffinity="1" density="500" pos="-0.0030 0.0445 -0.0059" size="0.0424 0.0444 0.0077" quat="0.7303 0.0000 0.0000 -0.6831" name="L_Wrist"/>
                    <body name="L_Index1" pos="0.021 0.1046 -0.009">
                      <joint name="L_Index1_x" type="hinge" pos="0 0 0" axis="1 0 0" stiffness="100" damping="10" armature="0.02" range="-180.0000 180.0000"/>
                      <joint name="L_Index1_y" type="hinge" pos="0 0 0" axis="0 1 0" stiffness="100" damping="10" armature="0.02" range="-180.0000 180.0000"/>
                      <joint name="L_Index1_z" type="hinge" pos="0 0 0" axis="0 0 1" stiffness="100" damping="10" armature="0.02" range="-180.0000 180.0000"/>
                      <geom type="capsule" contype="1" conaffinity="1" density="500" fromto="0.0008 0.0067 0.0003 0.0031 0.0269 0.0012" size="0.0094" name="L_Index1"/>
                      <body name="L_Index2" pos="0.0039 0.0336 0.0015">
                        <joint name="L_Index2_x" type="hinge" pos="0 0 0" axis="1 0 0" stiffness="100" damping="10" armature="0.02" range="-180.0000 180.0000"/>
                        <joint name="L_Index2_y" type="hinge" pos="0 0 0" axis="0 1 0" stiffness="100" damping="10" armature="0.02" range="-180.0000 180.0000"/>
                        <joint name="L_Index2_z" type="hinge" pos="0 0 0" axis="0 0 1" stiffness="100" damping="10" armature="0.02" range="-180.0000 180.0000"/>
                        <geom type="capsule" contype="1" conaffinity="1" density="500" fromto="0.0000 0.0048 -0.0005 0.0001 0.0190 -0.0022" size="0.0078" name="L_Index2"/>
                        <body name="L_Index3" pos="0.0001 0.0238 -0.0027">
                          <joint name="L_Index3_x" type="hinge" pos="0 0 0" axis="1 0 0" stiffness="100" damping="10" armature="0.02" range="-180.0000 180.0000"/>
                          <joint name="L_Index3_y" type="hinge" pos="0 0 0" axis="0 1 0" stiffness="100" damping="10" armature="0.02" range="-180.0000 180.0000"/>
                          <joint name="L_Index3_z" type="hinge" pos="0 0 0" axis="0 0 1" stiffness="100" damping="10" armature="0.02" range="-180.0000 180.0000"/>
                          <geom type="capsule" contype="1" conaffinity="1" density="500" fromto="0.0004 0.0052 -0.0001 0.0017 0.0206 -0.0006" size="0.0067" name="L_Index3"/>
                        </body>
                      </body>
                    </body>
                    <body name="L_Middle1" pos="-0.0036 0.1126 -0.0064">
                      <joint name="L_Middle1_x" type="hinge" pos="0 0 0" axis="1 0 0" stiffness="100" damping="10" armature="0.02" range="-180.0000 180.0000"/>
                      <joint name="L_Middle1_y" type="hinge" pos="0 0 0" axis="0 1 0" stiffness="100" damping="10" armature="0.02" range="-180.0000 180.0000"/>
                      <joint name="L_Middle1_z" type="hinge" pos="0 0 0" axis="0 0 1" stiffness="100" damping="10" armature="0.02" range="-180.0000 180.0000"/>
                      <geom type="capsule" contype="1" conaffinity="1" density="500" fromto="-0.0009 0.0064 0.0000 -0.0035 0.0256 0.0001" size="0.0096" name="L_Middle1"/>
                      <body name="L_Middle2" pos="-0.0043 0.032 0.0002">
                        <joint name="L_Middle2_x" type="hinge" pos="0 0 0" axis="1 0 0" stiffness="100" damping="10" armature="0.02" range="-180.0000 180.0000"/>
                        <joint name="L_Middle2_y" type="hinge" pos="0 0 0" axis="0 1 0" stiffness="100" damping="10" armature="0.02" range="-180.0000 180.0000"/>
                        <joint name="L_Middle2_z" type="hinge" pos="0 0 0" axis="0 0 1" stiffness="100" damping="10" armature="0.02" range="-180.0000 180.0000"/>
                        <geom type="capsule" contype="1" conaffinity="1" density="500" fromto="-0.0009 0.0049 -0.0005 -0.0034 0.0196 -0.0020" size="0.0071" name="L_Middle2"/>
                        <body name="L_Middle3" pos="-0.0043 0.0245 -0.0025">
                          <joint name="L_Middle3_x" type="hinge" pos="0 0 0" axis="1 0 0" stiffness="100" damping="10" armature="0.02" range="-180.0000 180.0000"/>
                          <joint name="L_Middle3_y" type="hinge" pos="0 0 0" axis="0 1 0" stiffness="100" damping="10" armature="0.02" range="-180.0000 180.0000"/>
                          <joint name="L_Middle3_z" type="hinge" pos="0 0 0" axis="0 0 1" stiffness="100" damping="10" armature="0.02" range="-180.0000 180.0000"/>
                          <geom type="capsule" contype="1" conaffinity="1" density="500" fromto="-0.0005 0.0053 -0.0001 -0.0018 0.0212 -0.0004" size="0.0064" name="L_Middle3"/>
                        </body>
                      </body>
                    </body>
                    <body name="L_Pinky1" pos="-0.046 0.0863 -0.0145">
                      <joint name="L_Pinky1_x" type="hinge" pos="0 0 0" axis="1 0 0" stiffness="100" damping="10" armature="0.02" range="-180.0000 180.0000"/>
                      <joint name="L_Pinky1_y" type="hinge" pos="0 0 0" axis="0 1 0" stiffness="100" damping="10" armature="0.02" range="-180.0000 180.0000"/>
                      <joint name="L_Pinky1_z" type="hinge" pos="0 0 0" axis="0 0 1" stiffness="100" damping="10" armature="0.02" range="-180.0000 180.0000"/>
                      <geom type="capsule" contype="1" conaffinity="1" density="500" fromto="-0.0024 0.0034 -0.0004 -0.0096 0.0134 -0.0015" size="0.0069" name="L_Pinky1"/>
                      <body name="L_Pinky2" pos="-0.012 0.0168 -0.0019">
                        <joint name="L_Pinky2_x" type="hinge" pos="0 0 0" axis="1 0 0" stiffness="100" damping="10" armature="0.02" range="-180.0000 180.0000"/>
                        <joint name="L_Pinky2_y" type="hinge" pos="0 0 0" axis="0 1 0" stiffness="100" damping="10" armature="0.02" range="-180.0000 180.0000"/>
                        <joint name="L_Pinky2_z" type="hinge" pos="0 0 0" axis="0 0 1" stiffness="100" damping="10" armature="0.02" range="-180.0000 180.0000"/>
                        <geom type="capsule" contype="1" conaffinity="1" density="500" fromto="-0.0023 0.0033 -0.0004 -0.0091 0.0133 -0.0016" size="0.0066" name="L_Pinky2"/>
                        <body name="L_Pinky3" pos="-0.0113 0.0166 -0.002">
                          <joint name="L_Pinky3_x" type="hinge" pos="0 0 0" axis="1 0 0" stiffness="100" damping="10" armature="0.02" range="-180.0000 180.0000"/>
                          <joint name="L_Pinky3_y" type="hinge" pos="0 0 0" axis="0 1 0" stiffness="100" damping="10" armature="0.02" range="-180.0000 180.0000"/>
                          <joint name="L_Pinky3_z" type="hinge" pos="0 0 0" axis="0 0 1" stiffness="100" damping="10" armature="0.02" range="-180.0000 180.0000"/>
                          <geom type="capsule" contype="1" conaffinity="1" density="500" fromto="-0.0019 0.0037 -0.0000 -0.0075 0.0149 -0.0000" size="0.0051" name="L_Pinky3"/>
                        </body>
                      </body>
                    </body>
                    <body name="L_Ring1" pos="-0.0283 0.1001 -0.009">
                      <joint name="L_Ring1_x" type="hinge" pos="0 0 0" axis="1 0 0" stiffness="100" damping="10" armature="0.02" range="-180.0000 180.0000"/>
                      <joint name="L_Ring1_y" type="hinge" pos="0 0 0" axis="0 1 0" stiffness="100" damping="10" armature="0.02" range="-180.0000 180.0000"/>
                      <joint name="L_Ring1_z" type="hinge" pos="0 0 0" axis="0 0 1" stiffness="100" damping="10" armature="0.02" range="-180.0000 180.0000"/>
                      <geom type="capsule" contype="1" conaffinity="1" density="500" fromto="-0.0010 0.0059 0.0001 -0.0040 0.0237 0.0006" size="0.0082" name="L_Ring1"/>
                      <body name="L_Ring2" pos="-0.005 0.0297 0.0007">
                        <joint name="L_Ring2_x" type="hinge" pos="0 0 0" axis="1 0 0" stiffness="100" damping="10" armature="0.02" range="-180.0000 180.0000"/>
                        <joint name="L_Ring2_y" type="hinge" pos="0 0 0" axis="0 1 0" stiffness="100" damping="10" armature="0.02" range="-180.0000 180.0000"/>
                        <joint name="L_Ring2_z" type="hinge" pos="0 0 0" axis="0 0 1" stiffness="100" damping="10" armature="0.02" range="-180.0000 180.0000"/>
                        <geom type="capsule" contype="1" conaffinity="1" density="500" fromto="-0.0014 0.0048 -0.0004 -0.0054 0.0193 -0.0017" size="0.0076" name="L_Ring2"/>
                        <body name="L_Ring3" pos="-0.0068 0.0241 -0.0022">
                          <joint name="L_Ring3_x" type="hinge" pos="0 0 0" axis="1 0 0" stiffness="100" damping="10" armature="0.02" range="-180.0000 180.0000"/>
                          <joint name="L_Ring3_y" type="hinge" pos="0 0 0" axis="0 1 0" stiffness="100" damping="10" armature="0.02" range="-180.0000 180.0000"/>
                          <joint name="L_Ring3_z" type="hinge" pos="0 0 0" axis="0 0 1" stiffness="100" damping="10" armature="0.02" range="-180.0000 180.0000"/>
                          <geom type="capsule" contype="1" conaffinity="1" density="500" fromto="-0.0010 0.0052 -0.0000 -0.0038 0.0209 -0.0001" size="0.006" name="L_Ring3"/>
                        </body>
                      </body>
                    </body>
                    <body name="L_Thumb1" pos="0.0271 0.041 -0.0198">
                      <joint name="L_Thumb1_x" type="hinge" pos="0 0 0" axis="1 0 0" stiffness="100" damping="10" armature="0.02" range="-180.0000 180.0000"/>
                      <joint name="L_Thumb1_y" type="hinge" pos="0 0 0" axis="0 1 0" stiffness="100" damping="10" armature="0.02" range="-180.0000 180.0000"/>
                      <joint name="L_Thumb1_z" type="hinge" pos="0 0 0" axis="0 0 1" stiffness="100" damping="10" armature="0.02" range="-180.0000 180.0000"/>
                      <geom type="capsule" contype="1" conaffinity="1" density="500" fromto="0.0054 0.0035 0.0003 0.0218 0.0139 0.0013" size="0.0125" name="L_Thumb1"/>
                      <body name="L_Thumb2" pos="0.0272 0.0173 0.0016">
                        <joint name="L_Thumb2_x" type="hinge" pos="0 0 0" axis="1 0 0" stiffness="100" damping="10" armature="0.02" range="-180.0000 180.0000"/>
                        <joint name="L_Thumb2_y" type="hinge" pos="0 0 0" axis="0 1 0" stiffness="100" damping="10" armature="0.02" range="-180.0000 180.0000"/>
                        <joint name="L_Thumb2_z" type="hinge" pos="0 0 0" axis="0 0 1" stiffness="100" damping="10" armature="0.02" range="-180.0000 180.0000"/>
                        <geom type="capsule" contype="1" conaffinity="1" density="500" fromto="0.0034 0.0043 -0.0009 0.0137 0.0170 -0.0036" size="0.01" name="L_Thumb2"/>
                        <body name="L_Thumb3" pos="0.0171 0.0213 -0.0045">
                          <joint name="L_Thumb3_x" type="hinge" pos="0 0 0" axis="1 0 0" stiffness="100" damping="10" armature="0.02" range="-180.0000 180.0000"/>
                          <joint name="L_Thumb3_y" type="hinge" pos="0 0 0" axis="0 1 0" stiffness="100" damping="10" armature="0.02" range="-180.0000 180.0000"/>
                          <joint name="L_Thumb3_z" type="hinge" pos="0 0 0" axis="0 0 1" stiffness="100" damping="10" armature="0.02" range="-180.0000 180.0000"/>
                          <geom type="capsule" contype="1" conaffinity="1" density="500" fromto="0.0038 0.0047 -0.0005 0.0153 0.0186 -0.0020" size="0.0091" name="L_Thumb3"/>
                        </body>
                      </body>
                    </body>
                  </body>
                </body>
              </body>
            </body>
            <body name="R_Thorax" pos="-0.0068 -0.0398 0.0749">
              <joint name="R_Thorax_x" type="hinge" pos="0 0 0" axis="1 0 0" stiffness="500" damping="50" armature="0.02" range="-180.0000 180.0000"/>
              <joint name="R_Thorax_y" type="hinge" pos="0 0 0" axis="0 1 0" stiffness="500" damping="50" armature="0.02" range="-180.0000 180.0000"/>
              <joint name="R_Thorax_z" type="hinge" pos="0 0 0" axis="0 0 1" stiffness="500" damping="50" armature="0.02" range="-180.0000 180.0000"/>
              <geom type="capsule" contype="1" conaffinity="1" density="500" fromto="-0.0012 -0.0238 0.0112 -0.0047 -0.0951 0.0446" size="0.0541" name="R_Thorax"/>
              <body name="R_Shoulder" pos="-0.0059 -0.1189 0.0558">
                <joint name="R_Shoulder_x" type="hinge" pos="0 0 0" axis="1 0 0" stiffness="500" damping="50" armature="0.02" range="-180.0000 180.0000"/>
                <joint name="R_Shoulder_y" type="hinge" pos="0 0 0" axis="0 1 0" stiffness="500" damping="50" armature="0.02" range="-180.0000 180.0000"/>
                <joint name="R_Shoulder_z" type="hinge" pos="0 0 0" axis="0 0 1" stiffness="500" damping="50" armature="0.02" range="-180.0000 180.0000"/>
                <geom type="capsule" contype="1" conaffinity="1" density="500" fromto="-0.0064 -0.0534 -0.0098 -0.0256 -0.2137 -0.0393" size="0.0513" name="R_Shoulder"/>
                <body name="R_Elbow" pos="-0.032 -0.2671 -0.0491">
                  <joint name="R_Elbow_x" type="hinge" pos="0 0 0" axis="1 0 0" stiffness="500" damping="50" armature="0.02" range="-720.0000 720.0000"/>
                  <joint name="R_Elbow_y" type="hinge" pos="0 0 0" axis="0 1 0" stiffness="500" damping="50" armature="0.02" range="-720.0000 720.0000"/>
                  <joint name="R_Elbow_z" type="hinge" pos="0 0 0" axis="0 0 1" stiffness="500" damping="50" armature="0.02" range="-720.0000 720.0000"/>
                  <geom type="capsule" contype="1" conaffinity="1" density="500" fromto="-0.0023 -0.0519 -0.0004 -0.0093 -0.2077 -0.0014" size="0.0409" name="R_Elbow"/>
                  <body name="R_Wrist" pos="-0.0116 -0.2597 -0.0018">
                    <joint name="R_Wrist_x" type="hinge" pos="0 0 0" axis="1 0 0" stiffness="300" damping="30" armature="0.02" range="-180.0000 180.0000"/>
                    <joint name="R_Wrist_y" type="hinge" pos="0 0 0" axis="0 1 0" stiffness="300" damping="30" armature="0.02" range="-180.0000 180.0000"/>
                    <joint name="R_Wrist_z" type="hinge" pos="0 0 0" axis="0 0 1" stiffness="300" damping="30" armature="0.02" range="-180.0000 180.0000"/>
                    <geom type="box" contype="1" conaffinity="1" density="500" pos="-0.0034 -0.0443 -0.0076" size="0.0424 0.0457 0.0078" quat="0.7339 0.0000 0.0000 0.6793" name="R_Wrist"/>
                    <body name="R_Index1" pos="0.0201 -0.1043 -0.0124">
                      <joint name="R_Index1_x" type="hinge" pos="0 0 0" axis="1 0 0" stiffness="100" damping="10" armature="0.02" range="-180.0000 180.0000"/>
                      <joint name="R_Index1_y" type="hinge" pos="0 0 0" axis="0 1 0" stiffness="100" damping="10" armature="0.02" range="-180.0000 180.0000"/>
                      <joint name="R_Index1_z" type="hinge" pos="0 0 0" axis="0 0 1" stiffness="100" damping="10" armature="0.02" range="-180.0000 180.0000"/>
                      <geom type="capsule" contype="1" conaffinity="1" density="500" fromto="0.0008 -0.0067 0.0003 0.0031 -0.0269 0.0012" size="0.0094" name="R_Index1"/>
                      <body name="R_Index2" pos="0.0039 -0.0336 0.0015">
                        <joint name="R_Index2_x" type="hinge" pos="0 0 0" axis="1 0 0" stiffness="100" damping="10" armature="0.02" range="-180.0000 180.0000"/>
                        <joint name="R_Index2_y" type="hinge" pos="0 0 0" axis="0 1 0" stiffness="100" damping="10" armature="0.02" range="-180.0000 180.0000"/>
                        <joint name="R_Index2_z" type="hinge" pos="0 0 0" axis="0 0 1" stiffness="100" damping="10" armature="0.02" range="-180.0000 180.0000"/>
                        <geom type="capsule" contype="1" conaffinity="1" density="500" fromto="0.0000 -0.0048 -0.0005 0.0001 -0.0190 -0.0022" size="0.0078" name="R_Index2"/>
                        <body name="R_Index3" pos="0.0001 -0.0238 -0.0027">
                          <joint name="R_Index3_x" type="hinge" pos="0 0 0" axis="1 0 0" stiffness="100" damping="10" armature="0.02" range="-180.0000 180.0000"/>
                          <joint name="R_Index3_y" type="hinge" pos="0 0 0" axis="0 1 0" stiffness="100" damping="10" armature="0.02" range="-180.0000 180.0000"/>
                          <joint name="R_Index3_z" type="hinge" pos="0 0 0" axis="0 0 1" stiffness="100" damping="10" armature="0.02" range="-180.0000 180.0000"/>
                          <geom type="capsule" contype="1" conaffinity="1" density="500" fromto="0.0004 -0.0044 -0.0001 0.0017 -0.0174 -0.0006" size="0.007" name="R_Index3"/>
                        </body>
                      </body>
                    </body>
                    <body name="R_Middle1" pos="-0.0044 -0.1122 -0.0098">
                      <joint name="R_Middle1_x" type="hinge" pos="0 0 0" axis="1 0 0" stiffness="100" damping="10" armature="0.02" range="-180.0000 180.0000"/>
                      <joint name="R_Middle1_y" type="hinge" pos="0 0 0" axis="0 1 0" stiffness="100" damping="10" armature="0.02" range="-180.0000 180.0000"/>
                      <joint name="R_Middle1_z" type="hinge" pos="0 0 0" axis="0 0 1" stiffness="100" damping="10" armature="0.02" range="-180.0000 180.0000"/>
                      <geom type="capsule" contype="1" conaffinity="1" density="500" fromto="-0.0009 -0.0064 0.0000 -0.0035 -0.0256 0.0001" size="0.0096" name="R_Middle1"/>
                      <body name="R_Middle2" pos="-0.0043 -0.032 0.0002">
                        <joint name="R_Middle2_x" type="hinge" pos="0 0 0" axis="1 0 0" stiffness="100" damping="10" armature="0.02" range="-180.0000 180.0000"/>
                        <joint name="R_Middle2_y" type="hinge" pos="0 0 0" axis="0 1 0" stiffness="100" damping="10" armature="0.02" range="-180.0000 180.0000"/>
                        <joint name="R_Middle2_z" type="hinge" pos="0 0 0" axis="0 0 1" stiffness="100" damping="10" armature="0.02" range="-180.0000 180.0000"/>
                        <geom type="capsule" contype="1" conaffinity="1" density="500" fromto="-0.0009 -0.0049 -0.0005 -0.0034 -0.0196 -0.0020" size="0.0071" name="R_Middle2"/>
                        <body name="R_Middle3" pos="-0.0043 -0.0245 -0.0025">
                          <joint name="R_Middle3_x" type="hinge" pos="0 0 0" axis="1 0 0" stiffness="100" damping="10" armature="0.02" range="-180.0000 180.0000"/>
                          <joint name="R_Middle3_y" type="hinge" pos="0 0 0" axis="0 1 0" stiffness="100" damping="10" armature="0.02" range="-180.0000 180.0000"/>
                          <joint name="R_Middle3_z" type="hinge" pos="0 0 0" axis="0 0 1" stiffness="100" damping="10" armature="0.02" range="-180.0000 180.0000"/>
                          <geom type="capsule" contype="1" conaffinity="1" density="500" fromto="-0.0005 -0.0045 -0.0001 -0.0018 -0.0180 -0.0004" size="0.0067" name="R_Middle3"/>
                        </body>
                      </body>
                    </body>
                    <body name="R_Pinky1" pos="-0.0469 -0.0859 -0.0179">
                      <joint name="R_Pinky1_x" type="hinge" pos="0 0 0" axis="1 0 0" stiffness="100" damping="10" armature="0.02" range="-180.0000 180.0000"/>
                      <joint name="R_Pinky1_y" type="hinge" pos="0 0 0" axis="0 1 0" stiffness="100" damping="10" armature="0.02" range="-180.0000 180.0000"/>
                      <joint name="R_Pinky1_z" type="hinge" pos="0 0 0" axis="0 0 1" stiffness="100" damping="10" armature="0.02" range="-180.0000 180.0000"/>
                      <geom type="capsule" contype="1" conaffinity="1" density="500" fromto="-0.0024 -0.0034 -0.0004 -0.0096 -0.0134 -0.0015" size="0.0069" name="R_Pinky1"/>
                      <body name="R_Pinky2" pos="-0.012 -0.0168 -0.0019">
                        <joint name="R_Pinky2_x" type="hinge" pos="0 0 0" axis="1 0 0" stiffness="100" damping="10" armature="0.02" range="-180.0000 180.0000"/>
                        <joint name="R_Pinky2_y" type="hinge" pos="0 0 0" axis="0 1 0" stiffness="100" damping="10" armature="0.02" range="-180.0000 180.0000"/>
                        <joint name="R_Pinky2_z" type="hinge" pos="0 0 0" axis="0 0 1" stiffness="100" damping="10" armature="0.02" range="-180.0000 180.0000"/>
                        <geom type="capsule" contype="1" conaffinity="1" density="500" fromto="-0.0023 -0.0033 -0.0004 -0.0091 -0.0133 -0.0016" size="0.0066" name="R_Pinky2"/>
                        <body name="R_Pinky3" pos="-0.0113 -0.0166 -0.002">
                          <joint name="R_Pinky3_x" type="hinge" pos="0 0 0" axis="1 0 0" stiffness="100" damping="10" armature="0.02" range="-180.0000 180.0000"/>
                          <joint name="R_Pinky3_y" type="hinge" pos="0 0 0" axis="0 1 0" stiffness="100" damping="10" armature="0.02" range="-180.0000 180.0000"/>
                          <joint name="R_Pinky3_z" type="hinge" pos="0 0 0" axis="0 0 1" stiffness="100" damping="10" armature="0.02" range="-180.0000 180.0000"/>
                          <geom type="capsule" contype="1" conaffinity="1" density="500" fromto="-0.0019 -0.0029 -0.0000 -0.0075 -0.0117 -0.0000" size="0.0053" name="R_Pinky3"/>
                        </body>
                      </body>
                    </body>
                    <body name="R_Ring1" pos="-0.0292 -0.0997 -0.0124">
                      <joint name="R_Ring1_x" type="hinge" pos="0 0 0" axis="1 0 0" stiffness="100" damping="10" armature="0.02" range="-180.0000 180.0000"/>
                      <joint name="R_Ring1_y" type="hinge" pos="0 0 0" axis="0 1 0" stiffness="100" damping="10" armature="0.02" range="-180.0000 180.0000"/>
                      <joint name="R_Ring1_z" type="hinge" pos="0 0 0" axis="0 0 1" stiffness="100" damping="10" armature="0.02" range="-180.0000 180.0000"/>
                      <geom type="capsule" contype="1" conaffinity="1" density="500" fromto="-0.0010 -0.0059 0.0001 -0.0040 -0.0237 0.0006" size="0.0082" name="R_Ring1"/>
                      <body name="R_Ring2" pos="-0.005 -0.0297 0.0007">
                        <joint name="R_Ring2_x" type="hinge" pos="0 0 0" axis="1 0 0" stiffness="100" damping="10" armature="0.02" range="-180.0000 180.0000"/>
                        <joint name="R_Ring2_y" type="hinge" pos="0 0 0" axis="0 1 0" stiffness="100" damping="10" armature="0.02" range="-180.0000 180.0000"/>
                        <joint name="R_Ring2_z" type="hinge" pos="0 0 0" axis="0 0 1" stiffness="100" damping="10" armature="0.02" range="-180.0000 180.0000"/>
                        <geom type="capsule" contype="1" conaffinity="1" density="500" fromto="-0.0014 -0.0048 -0.0004 -0.0054 -0.0193 -0.0017" size="0.0076" name="R_Ring2"/>
                        <body name="R_Ring3" pos="-0.0068 -0.0241 -0.0022">
                          <joint name="R_Ring3_x" type="hinge" pos="0 0 0" axis="1 0 0" stiffness="100" damping="10" armature="0.02" range="-180.0000 180.0000"/>
                          <joint name="R_Ring3_y" type="hinge" pos="0 0 0" axis="0 1 0" stiffness="100" damping="10" armature="0.02" range="-180.0000 180.0000"/>
                          <joint name="R_Ring3_z" type="hinge" pos="0 0 0" axis="0 0 1" stiffness="100" damping="10" armature="0.02" range="-180.0000 180.0000"/>
                          <geom type="capsule" contype="1" conaffinity="1" density="500" fromto="-0.0010 -0.0044 -0.0000 -0.0038 -0.0177 -0.0001" size="0.0063" name="R_Ring3"/>
                        </body>
                      </body>
                    </body>
                    <body name="R_Thumb1" pos="0.0262 -0.0406 -0.0232">
                      <joint name="R_Thumb1_x" type="hinge" pos="0 0 0" axis="1 0 0" stiffness="100" damping="10" armature="0.02" range="-180.0000 180.0000"/>
                      <joint name="R_Thumb1_y" type="hinge" pos="0 0 0" axis="0 1 0" stiffness="100" damping="10" armature="0.02" range="-180.0000 180.0000"/>
                      <joint name="R_Thumb1_z" type="hinge" pos="0 0 0" axis="0 0 1" stiffness="100" damping="10" armature="0.02" range="-180.0000 180.0000"/>
                      <geom type="capsule" contype="1" conaffinity="1" density="500" fromto="0.0054 -0.0035 0.0003 0.0218 -0.0139 0.0013" size="0.0125" name="R_Thumb1"/>
                      <body name="R_Thumb2" pos="0.0272 -0.0173 0.0016">
                        <joint name="R_Thumb2_x" type="hinge" pos="0 0 0" axis="1 0 0" stiffness="100" damping="10" armature="0.02" range="-180.0000 180.0000"/>
                        <joint name="R_Thumb2_y" type="hinge" pos="0 0 0" axis="0 1 0" stiffness="100" damping="10" armature="0.02" range="-180.0000 180.0000"/>
                        <joint name="R_Thumb2_z" type="hinge" pos="0 0 0" axis="0 0 1" stiffness="100" damping="10" armature="0.02" range="-180.0000 180.0000"/>
                        <geom type="capsule" contype="1" conaffinity="1" density="500" fromto="0.0034 -0.0043 -0.0009 0.0137 -0.0170 -0.0036" size="0.01" name="R_Thumb2"/>
                        <body name="R_Thumb3" pos="0.0171 -0.0213 -0.0045">
                          <joint name="R_Thumb3_x" type="hinge" pos="0 0 0" axis="1 0 0" stiffness="100" damping="10" armature="0.02" range="-180.0000 180.0000"/>
                          <joint name="R_Thumb3_y" type="hinge" pos="0 0 0" axis="0 1 0" stiffness="100" damping="10" armature="0.02" range="-180.0000 180.0000"/>
                          <joint name="R_Thumb3_z" type="hinge" pos="0 0 0" axis="0 0 1" stiffness="100" damping="10" armature="0.02" range="-180.0000 180.0000"/>
                          <geom type="capsule" contype="1" conaffinity="1" density="500" fromto="0.0038 -0.0039 -0.0005 0.0153 -0.0154 -0.0020" size="0.0093" name="R_Thumb3"/>
                        </body>
                      </body>
                    </body>
                  </body>
                </body>
              </body>
            </body>
          </body>
        </body>
      </body>
    </body>
  </worldbody>
  <actuator>
    <motor name="L_Hip_x" joint="L_Hip_x" gear="500"/>
    <motor name="L_Hip_y" joint="L_Hip_y" gear="500"/>
    <motor name="L_Hip_z" joint="L_Hip_z" gear="500"/>
    <motor name="L_Knee_x" joint="L_Knee_x" gear="500"/>
    <motor name="L_Knee_y" joint="L_Knee_y" gear="500"/>
    <motor name="L_Knee_z" joint="L_Knee_z" gear="500"/>
    <motor name="L_Ankle_x" joint="L_Ankle_x" gear="500"/>
    <motor name="L_Ankle_y" joint="L_Ankle_y" gear="500"/>
    <motor name="L_Ankle_z" joint="L_Ankle_z" gear="500"/>
    <motor name="L_Toe_x" joint="L_Toe_x" gear="500"/>
    <motor name="L_Toe_y" joint="L_Toe_y" gear="500"/>
    <motor name="L_Toe_z" joint="L_Toe_z" gear="500"/>
    <motor name="R_Hip_x" joint="R_Hip_x" gear="500"/>
    <motor name="R_Hip_y" joint="R_Hip_y" gear="500"/>
    <motor name="R_Hip_z" joint="R_Hip_z" gear="500"/>
    <motor name="R_Knee_x" joint="R_Knee_x" gear="500"/>
    <motor name="R_Knee_y" joint="R_Knee_y" gear="500"/>
    <motor name="R_Knee_z" joint="R_Knee_z" gear="500"/>
    <motor name="R_Ankle_x" joint="R_Ankle_x" gear="500"/>
    <motor name="R_Ankle_y" joint="R_Ankle_y" gear="500"/>
    <motor name="R_Ankle_z" joint="R_Ankle_z" gear="500"/>
    <motor name="R_Toe_x" joint="R_Toe_x" gear="500"/>
    <motor name="R_Toe_y" joint="R_Toe_y" gear="500"/>
    <motor name="R_Toe_z" joint="R_Toe_z" gear="500"/>
    <motor name="Torso_x" joint="Torso_x" gear="500"/>
    <motor name="Torso_y" joint="Torso_y" gear="500"/>
    <motor name="Torso_z" joint="Torso_z" gear="500"/>
    <motor name="Spine_x" joint="Spine_x" gear="500"/>
    <motor name="Spine_y" joint="Spine_y" gear="500"/>
    <motor name="Spine_z" joint="Spine_z" gear="500"/>
    <motor name="Chest_x" joint="Chest_x" gear="500"/>
    <motor name="Chest_y" joint="Chest_y" gear="500"/>
    <motor name="Chest_z" joint="Chest_z" gear="500"/>
    <motor name="Neck_x" joint="Neck_x" gear="500"/>
    <motor name="Neck_y" joint="Neck_y" gear="500"/>
    <motor name="Neck_z" joint="Neck_z" gear="500"/>
    <motor name="Head_x" joint="Head_x" gear="500"/>
    <motor name="Head_y" joint="Head_y" gear="500"/>
    <motor name="Head_z" joint="Head_z" gear="500"/>
    <motor name="L_Thorax_x" joint="L_Thorax_x" gear="500"/>
    <motor name="L_Thorax_y" joint="L_Thorax_y" gear="500"/>
    <motor name="L_Thorax_z" joint="L_Thorax_z" gear="500"/>
    <motor name="L_Shoulder_x" joint="L_Shoulder_x" gear="500"/>
    <motor name="L_Shoulder_y" joint="L_Shoulder_y" gear="500"/>
    <motor name="L_Shoulder_z" joint="L_Shoulder_z" gear="500"/>
    <motor name="L_Elbow_x" joint="L_Elbow_x" gear="500"/>
    <motor name="L_Elbow_y" joint="L_Elbow_y" gear="500"/>
    <motor name="L_Elbow_z" joint="L_Elbow_z" gear="500"/>
    <motor name="L_Wrist_x" joint="L_Wrist_x" gear="500"/>
    <motor name="L_Wrist_y" joint="L_Wrist_y" gear="500"/>
    <motor name="L_Wrist_z" joint="L_Wrist_z" gear="500"/>
    <motor name="L_Index1_x" joint="L_Index1_x" gear="500"/>
    <motor name="L_Index1_y" joint="L_Index1_y" gear="500"/>
    <motor name="L_Index1_z" joint="L_Index1_z" gear="500"/>
    <motor name="L_Index2_x" joint="L_Index2_x" gear="500"/>
    <motor name="L_Index2_y" joint="L_Index2_y" gear="500"/>
    <motor name="L_Index2_z" joint="L_Index2_z" gear="500"/>
    <motor name="L_Index3_x" joint="L_Index3_x" gear="500"/>
    <motor name="L_Index3_y" joint="L_Index3_y" gear="500"/>
    <motor name="L_Index3_z" joint="L_Index3_z" gear="500"/>
    <motor name="L_Middle1_x" joint="L_Middle1_x" gear="500"/>
    <motor name="L_Middle1_y" joint="L_Middle1_y" gear="500"/>
    <motor name="L_Middle1_z" joint="L_Middle1_z" gear="500"/>
    <motor name="L_Middle2_x" joint="L_Middle2_x" gear="500"/>
    <motor name="L_Middle2_y" joint="L_Middle2_y" gear="500"/>
    <motor name="L_Middle2_z" joint="L_Middle2_z" gear="500"/>
    <motor name="L_Middle3_x" joint="L_Middle3_x" gear="500"/>
    <motor name="L_Middle3_y" joint="L_Middle3_y" gear="500"/>
    <motor name="L_Middle3_z" joint="L_Middle3_z" gear="500"/>
    <motor name="L_Pinky1_x" joint="L_Pinky1_x" gear="500"/>
    <motor name="L_Pinky1_y" joint="L_Pinky1_y" gear="500"/>
    <motor name="L_Pinky1_z" joint="L_Pinky1_z" gear="500"/>
    <motor name="L_Pinky2_x" joint="L_Pinky2_x" gear="500"/>
    <motor name="L_Pinky2_y" joint="L_Pinky2_y" gear="500"/>
    <motor name="L_Pinky2_z" joint="L_Pinky2_z" gear="500"/>
    <motor name="L_Pinky3_x" joint="L_Pinky3_x" gear="500"/>
    <motor name="L_Pinky3_y" joint="L_Pinky3_y" gear="500"/>
    <motor name="L_Pinky3_z" joint="L_Pinky3_z" gear="500"/>
    <motor name="L_Ring1_x" joint="L_Ring1_x" gear="500"/>
    <motor name="L_Ring1_y" joint="L_Ring1_y" gear="500"/>
    <motor name="L_Ring1_z" joint="L_Ring1_z" gear="500"/>
    <motor name="L_Ring2_x" joint="L_Ring2_x" gear="500"/>
    <motor name="L_Ring2_y" joint="L_Ring2_y" gear="500"/>
    <motor name="L_Ring2_z" joint="L_Ring2_z" gear="500"/>
    <motor name="L_Ring3_x" joint="L_Ring3_x" gear="500"/>
    <motor name="L_Ring3_y" joint="L_Ring3_y" gear="500"/>
    <motor name="L_Ring3_z" joint="L_Ring3_z" gear="500"/>
    <motor name="L_Thumb1_x" joint="L_Thumb1_x" gear="500"/>
    <motor name="L_Thumb1_y" joint="L_Thumb1_y" gear="500"/>
    <motor name="L_Thumb1_z" joint="L_Thumb1_z" gear="500"/>
    <motor name="L_Thumb2_x" joint="L_Thumb2_x" gear="500"/>
    <motor name="L_Thumb2_y" joint="L_Thumb2_y" gear="500"/>
    <motor name="L_Thumb2_z" joint="L_Thumb2_z" gear="500"/>
    <motor name="L_Thumb3_x" joint="L_Thumb3_x" gear="500"/>
    <motor name="L_Thumb3_y" joint="L_Thumb3_y" gear="500"/>
    <motor name="L_Thumb3_z" joint="L_Thumb3_z" gear="500"/>
    <motor name="R_Thorax_x" joint="R_Thorax_x" gear="500"/>
    <motor name="R_Thorax_y" joint="R_Thorax_y" gear="500"/>
    <motor name="R_Thorax_z" joint="R_Thorax_z" gear="500"/>
    <motor name="R_Shoulder_x" joint="R_Shoulder_x" gear="500"/>
    <motor name="R_Shoulder_y" joint="R_Shoulder_y" gear="500"/>
    <motor name="R_Shoulder_z" joint="R_Shoulder_z" gear="500"/>
    <motor name="R_Elbow_x" joint="R_Elbow_x" gear="500"/>
    <motor name="R_Elbow_y" joint="R_Elbow_y" gear="500"/>
    <motor name="R_Elbow_z" joint="R_Elbow_z" gear="500"/>
    <motor name="R_Wrist_x" joint="R_Wrist_x" gear="500"/>
    <motor name="R_Wrist_y" joint="R_Wrist_y" gear="500"/>
    <motor name="R_Wrist_z" joint="R_Wrist_z" gear="500"/>
    <motor name="R_Index1_x" joint="R_Index1_x" gear="500"/>
    <motor name="R_Index1_y" joint="R_Index1_y" gear="500"/>
    <motor name="R_Index1_z" joint="R_Index1_z" gear="500"/>
    <motor name="R_Index2_x" joint="R_Index2_x" gear="500"/>
    <motor name="R_Index2_y" joint="R_Index2_y" gear="500"/>
    <motor name="R_Index2_z" joint="R_Index2_z" gear="500"/>
    <motor name="R_Index3_x" joint="R_Index3_x" gear="500"/>
    <motor name="R_Index3_y" joint="R_Index3_y" gear="500"/>
    <motor name="R_Index3_z" joint="R_Index3_z" gear="500"/>
    <motor name="R_Middle1_x" joint="R_Middle1_x" gear="500"/>
    <motor name="R_Middle1_y" joint="R_Middle1_y" gear="500"/>
    <motor name="R_Middle1_z" joint="R_Middle1_z" gear="500"/>
    <motor name="R_Middle2_x" joint="R_Middle2_x" gear="500"/>
    <motor name="R_Middle2_y" joint="R_Middle2_y" gear="500"/>
    <motor name="R_Middle2_z" joint="R_Middle2_z" gear="500"/>
    <motor name="R_Middle3_x" joint="R_Middle3_x" gear="500"/>
    <motor name="R_Middle3_y" joint="R_Middle3_y" gear="500"/>
    <motor name="R_Middle3_z" joint="R_Middle3_z" gear="500"/>
    <motor name="R_Pinky1_x" joint="R_Pinky1_x" gear="500"/>
    <motor name="R_Pinky1_y" joint="R_Pinky1_y" gear="500"/>
    <motor name="R_Pinky1_z" joint="R_Pinky1_z" gear="500"/>
    <motor name="R_Pinky2_x" joint="R_Pinky2_x" gear="500"/>
    <motor name="R_Pinky2_y" joint="R_Pinky2_y" gear="500"/>
    <motor name="R_Pinky2_z" joint="R_Pinky2_z" gear="500"/>
    <motor name="R_Pinky3_x" joint="R_Pinky3_x" gear="500"/>
    <motor name="R_Pinky3_y" joint="R_Pinky3_y" gear="500"/>
    <motor name="R_Pinky3_z" joint="R_Pinky3_z" gear="500"/>
    <motor name="R_Ring1_x" joint="R_Ring1_x" gear="500"/>
    <motor name="R_Ring1_y" joint="R_Ring1_y" gear="500"/>
    <motor name="R_Ring1_z" joint="R_Ring1_z" gear="500"/>
    <motor name="R_Ring2_x" joint="R_Ring2_x" gear="500"/>
    <motor name="R_Ring2_y" joint="R_Ring2_y" gear="500"/>
    <motor name="R_Ring2_z" joint="R_Ring2_z" gear="500"/>
    <motor name="R_Ring3_x" joint="R_Ring3_x" gear="500"/>
    <motor name="R_Ring3_y" joint="R_Ring3_y" gear="500"/>
    <motor name="R_Ring3_z" joint="R_Ring3_z" gear="500"/>
    <motor name="R_Thumb1_x" joint="R_Thumb1_x" gear="500"/>
    <motor name="R_Thumb1_y" joint="R_Thumb1_y" gear="500"/>
    <motor name="R_Thumb1_z" joint="R_Thumb1_z" gear="500"/>
    <motor name="R_Thumb2_x" joint="R_Thumb2_x" gear="500"/>
    <motor name="R_Thumb2_y" joint="R_Thumb2_y" gear="500"/>
    <motor name="R_Thumb2_z" joint="R_Thumb2_z" gear="500"/>
    <motor name="R_Thumb3_x" joint="R_Thumb3_x" gear="500"/>
    <motor name="R_Thumb3_y" joint="R_Thumb3_y" gear="500"/>
    <motor name="R_Thumb3_z" joint="R_Thumb3_z" gear="500"/>
  </actuator>
  <contact>
    <exclude body1="Torso" body2="Chest"/>
    <exclude body1="Head" body2="Chest"/>
    <exclude body1="R_Knee" body2="R_Toe"/>
    <exclude body1="R_Knee" body2="L_Ankle"/>
    <exclude body1="R_Knee" body2="L_Toe"/>
    <exclude body1="L_Knee" body2="L_Toe"/>
    <exclude body1="L_Knee" body2="R_Ankle"/>
    <exclude body1="L_Knee" body2="R_Toe"/>
    <exclude body1="L_Shoulder" body2="Chest"/>
    <exclude body1="R_Shoulder" body2="Chest"/>
  </contact>
  <sensor/>
  <size njmax="700" nconmax="700"/>
</mujoco>
