<mujoco model="humanoid">
  <compiler coordinate="local" angle="radian"/>
  <default>
    <joint damping="0.0" armature="0.01" stiffness="0.0" limited="true"/>
    <geom conaffinity="1" condim="3" contype="7" margin="0.001" rgba="0.8 0.6 .4 1"/>
  </default>
  <asset>
    <texture type="skybox" builtin="gradient" rgb1=".4 .5 .6" rgb2="0 0 0" width="100" height="100"/>
    <texture builtin="flat" height="1278" mark="cross" markrgb="1 1 1" name="texgeom" random="0.01" rgb1="0.8 0.6 0.4" rgb2="0.8 0.6 0.4" type="cube" width="127"/>
    <texture builtin="checker" height="100" name="texplane" rgb1="0 0 0" rgb2="0.8 0.8 0.8" type="2d" width="100"/>
    <material name="MatPlane" reflectance="0.5" shininess="1" specular="1" texrepeat="60 60" texture="texplane"/>
    <material name="geom" texture="texgeom" texuniform="true"/>
  </asset>
  <worldbody>
    <light cutoff="100" diffuse="1 1 1" dir="-0 0 -1.3" directional="true" exponent="1" pos="0 0 1.3" specular=".1 .1 .1"/>
    <geom conaffinity="1" condim="3" name="floor" pos="0 0 0" rgba="0.8 0.9 0.8 1" size="100 100 .2" type="plane" material="MatPlane"/>
    <body name="Pelvis" pos="0.0008 -0.3782 0.0096">
      <freejoint name="Pelvis"/>
      <geom type="sphere" contype="1" conaffinity="1" density="500" size="0.1004" pos="0.0000 0.0000 0.0000" name="Pelvis"/>
      <body name="L_Hip" pos="-0.0293 0.0551 -0.0975">
        <joint name="L_Hip_x" type="hinge" pos="0 0 0" axis="1 0 0" stiffness="800" damping="80" armature="0.02" range="-180.0000 180.0000"/>
        <joint name="L_Hip_y" type="hinge" pos="0 0 0" axis="0 1 0" stiffness="800" damping="80" armature="0.02" range="-180.0000 180.0000"/>
        <joint name="L_Hip_z" type="hinge" pos="0 0 0" axis="0 0 1" stiffness="800" damping="80" armature="0.02" range="-180.0000 180.0000"/>
        <geom type="capsule" contype="1" conaffinity="1" density="500" fromto="-0.0020 0.0139 -0.0796 -0.0080 0.0557 -0.3185" size="0.0603" name="L_Hip"/>
        <body name="L_Knee" pos="-0.01 0.0697 -0.3982">
          <joint name="L_Knee_x" type="hinge" pos="0 0 0" axis="1 0 0" stiffness="800" damping="80" armature="0.02" range="-180.0000 180.0000"/>
          <joint name="L_Knee_y" type="hinge" pos="0 0 0" axis="0 1 0" stiffness="800" damping="80" armature="0.02" range="-180.0000 180.0000"/>
          <joint name="L_Knee_z" type="hinge" pos="0 0 0" axis="0 0 1" stiffness="800" damping="80" armature="0.02" range="-180.0000 180.0000"/>
          <geom type="capsule" contype="1" conaffinity="1" density="500" fromto="-0.0088 -0.0087 -0.0809 -0.0352 -0.0347 -0.3236" size="0.0547" name="L_Knee"/>
          <body name="L_Ankle" pos="-0.0441 -0.0434 -0.4045">
            <joint name="L_Ankle_x" type="hinge" pos="0 0 0" axis="1 0 0" stiffness="800" damping="80" armature="0.02" range="-180.0000 180.0000"/>
            <joint name="L_Ankle_y" type="hinge" pos="0 0 0" axis="0 1 0" stiffness="800" damping="80" armature="0.02" range="-180.0000 180.0000"/>
            <joint name="L_Ankle_z" type="hinge" pos="0 0 0" axis="0 0 1" stiffness="800" damping="80" armature="0.02" range="-180.0000 180.0000"/>
            <geom type="box" contype="1" conaffinity="1" density="500" pos="0.0650 0.0216 -0.0290" size="0.0882 0.0518 0.0208" quat="0.9871 0.0000 0.0000 0.1600" name="L_Ankle"/>
            <body name="L_Toe" pos="0.1299 0.0433 -0.0581">
              <joint name="L_Toe_x" type="hinge" pos="0 0 0" axis="1 0 0" stiffness="500" damping="50" armature="0.02" range="-180.0000 180.0000"/>
              <joint name="L_Toe_y" type="hinge" pos="0 0 0" axis="0 1 0" stiffness="500" damping="50" armature="0.02" range="-180.0000 180.0000"/>
              <joint name="L_Toe_z" type="hinge" pos="0 0 0" axis="0 0 1" stiffness="500" damping="50" armature="0.02" range="-180.0000 180.0000"/>
              <geom type="box" contype="1" conaffinity="1" density="500" pos="0.0000 0.0000 0.0294" size="0.001 0.0025 0.0011" quat="0.9864 0.0000 0.0000 0.1645" name="L_Toe"/>
            </body>
          </body>
        </body>
      </body>
      <body name="R_Hip" pos="-0.0222 -0.0564 -0.108">
        <joint name="R_Hip_x" type="hinge" pos="0 0 0" axis="1 0 0" stiffness="800" damping="80" armature="0.02" range="-180.0000 180.0000"/>
        <joint name="R_Hip_y" type="hinge" pos="0 0 0" axis="0 1 0" stiffness="800" damping="80" armature="0.02" range="-180.0000 180.0000"/>
        <joint name="R_Hip_z" type="hinge" pos="0 0 0" axis="0 0 1" stiffness="800" damping="80" armature="0.02" range="-180.0000 180.0000"/>
        <geom type="capsule" contype="1" conaffinity="1" density="500" fromto="-0.0035 -0.0106 -0.0763 -0.0141 -0.0426 -0.3051" size="0.0602" name="R_Hip"/>
        <body name="R_Knee" pos="-0.0177 -0.0532 -0.3813">
          <joint name="R_Knee_x" type="hinge" pos="0 0 0" axis="1 0 0" stiffness="800" damping="80" armature="0.02" range="-180.0000 180.0000"/>
          <joint name="R_Knee_y" type="hinge" pos="0 0 0" axis="0 1 0" stiffness="800" damping="80" armature="0.02" range="-180.0000 180.0000"/>
          <joint name="R_Knee_z" type="hinge" pos="0 0 0" axis="0 0 1" stiffness="800" damping="80" armature="0.02" range="-180.0000 180.0000"/>
          <geom type="capsule" contype="1" conaffinity="1" density="500" fromto="-0.0086 0.0031 -0.0836 -0.0346 0.0125 -0.3342" size="0.0545" name="R_Knee"/>
          <body name="R_Ankle" pos="-0.0432 0.0156 -0.4178">
            <joint name="R_Ankle_x" type="hinge" pos="0 0 0" axis="1 0 0" stiffness="800" damping="80" armature="0.02" range="-180.0000 180.0000"/>
            <joint name="R_Ankle_y" type="hinge" pos="0 0 0" axis="0 1 0" stiffness="800" damping="80" armature="0.02" range="-180.0000 180.0000"/>
            <joint name="R_Ankle_z" type="hinge" pos="0 0 0" axis="0 0 1" stiffness="800" damping="80" armature="0.02" range="-180.0000 180.0000"/>
            <geom type="box" contype="1" conaffinity="1" density="500" pos="0.0681 -0.0173 -0.0287" size="0.0882 0.0518 0.0252" quat="0.9923 0.0000 0.0000 -0.1242" name="R_Ankle"/>
            <body name="R_Toe" pos="0.1363 -0.0347 -0.0573">
              <joint name="R_Toe_x" type="hinge" pos="0 0 0" axis="1 0 0" stiffness="500" damping="50" armature="0.02" range="-180.0000 180.0000"/>
              <joint name="R_Toe_y" type="hinge" pos="0 0 0" axis="0 1 0" stiffness="500" damping="50" armature="0.02" range="-180.0000 180.0000"/>
              <joint name="R_Toe_z" type="hinge" pos="0 0 0" axis="0 0 1" stiffness="500" damping="50" armature="0.02" range="-180.0000 180.0000"/>
              <geom type="box" contype="1" conaffinity="1" density="500" pos="0.0000 0.0000 0.0246" size="0.001 0.0025 0.0011" quat="0.9933 0.0000 0.0000 -0.1157" name="R_Toe"/>
            </body>
          </body>
        </body>
      </body>
      <body name="Torso" pos="-0.0311 -0.0018 0.1132">
        <joint name="Torso_x" type="hinge" pos="0 0 0" axis="1 0 0" stiffness="1000" damping="100" armature="0.02" range="-180.0000 180.0000"/>
        <joint name="Torso_y" type="hinge" pos="0 0 0" axis="0 1 0" stiffness="1000" damping="100" armature="0.02" range="-180.0000 180.0000"/>
        <joint name="Torso_z" type="hinge" pos="0 0 0" axis="0 0 1" stiffness="1000" damping="100" armature="0.02" range="-180.0000 180.0000"/>
        <geom type="capsule" contype="1" conaffinity="1" density="500" fromto="0.0054 0.0062 0.0970 0.0036 0.0041 0.0647" size="0.0673" name="Torso"/>
        <body name="Spine" pos="0.009 0.0104 0.1617">
          <joint name="Spine_x" type="hinge" pos="0 0 0" axis="1 0 0" stiffness="1000" damping="100" armature="0.02" range="-180.0000 180.0000"/>
          <joint name="Spine_y" type="hinge" pos="0 0 0" axis="0 1 0" stiffness="1000" damping="100" armature="0.02" range="-180.0000 180.0000"/>
          <joint name="Spine_z" type="hinge" pos="0 0 0" axis="0 0 1" stiffness="1000" damping="100" armature="0.02" range="-180.0000 180.0000"/>
          <geom type="capsule" contype="1" conaffinity="1" density="500" fromto="0.0132 -0.0053 0.0360 0.0088 -0.0035 0.0240" size="0.0852" name="Spine"/>
          <body name="Chest" pos="0.0221 -0.0088 0.06">
            <joint name="Chest_x" type="hinge" pos="0 0 0" axis="1 0 0" stiffness="1000" damping="100" armature="0.02" range="-180.0000 180.0000"/>
            <joint name="Chest_y" type="hinge" pos="0 0 0" axis="0 1 0" stiffness="1000" damping="100" armature="0.02" range="-180.0000 180.0000"/>
            <joint name="Chest_z" type="hinge" pos="0 0 0" axis="0 0 1" stiffness="1000" damping="100" armature="0.02" range="-180.0000 180.0000"/>
            <geom type="capsule" contype="1" conaffinity="1" density="500" fromto="-0.0069 -0.0022 0.0640 -0.0046 -0.0015 0.0427" size="0.1015" name="Chest"/>
            <body name="Neck" pos="-0.0254 -0.0087 0.1659">
              <joint name="Neck_x" type="hinge" pos="0 0 0" axis="1 0 0" stiffness="500" damping="50" armature="0.02" range="-180.0000 180.0000"/>
              <joint name="Neck_y" type="hinge" pos="0 0 0" axis="0 1 0" stiffness="500" damping="50" armature="0.02" range="-180.0000 180.0000"/>
              <joint name="Neck_z" type="hinge" pos="0 0 0" axis="0 0 1" stiffness="500" damping="50" armature="0.02" range="-180.0000 180.0000"/>
              <geom type="capsule" contype="1" conaffinity="1" density="500" fromto="0.0018 0.0044 0.0309 0.0073 0.0178 0.1236" size="0.0419" name="Neck"/>
              <body name="Head" pos="0.0091 0.0222 0.1545">
                <joint name="Head_x" type="hinge" pos="0 0 0" axis="1 0 0" stiffness="500" damping="50" armature="0.02" range="-180.0000 180.0000"/>
                <joint name="Head_y" type="hinge" pos="0 0 0" axis="0 1 0" stiffness="500" damping="50" armature="0.02" range="-180.0000 180.0000"/>
                <joint name="Head_z" type="hinge" pos="0 0 0" axis="0 0 1" stiffness="500" damping="50" armature="0.02" range="-180.0000 180.0000"/>
                <geom type="sphere" contype="1" conaffinity="1" density="500" size="0.1019" pos="0.0000 0.0000 0.0000" name="Head"/>
              </body>
            </body>
            <body name="L_Thorax" pos="-0.0029 0.0416 0.0768">
              <joint name="L_Thorax_x" type="hinge" pos="0 0 0" axis="1 0 0" stiffness="500" damping="50" armature="0.02" range="-180.0000 180.0000"/>
              <joint name="L_Thorax_y" type="hinge" pos="0 0 0" axis="0 1 0" stiffness="500" damping="50" armature="0.02" range="-180.0000 180.0000"/>
              <joint name="L_Thorax_z" type="hinge" pos="0 0 0" axis="0 0 1" stiffness="500" damping="50" armature="0.02" range="-180.0000 180.0000"/>
              <geom type="capsule" contype="1" conaffinity="1" density="500" fromto="-0.0024 0.0271 0.0129 -0.0096 0.1085 0.0515" size="0.0487" name="L_Thorax"/>
              <body name="L_Shoulder" pos="-0.012 0.1356 0.0644">
                <joint name="L_Shoulder_x" type="hinge" pos="0 0 0" axis="1 0 0" stiffness="500" damping="50" armature="0.02" range="-180.0000 180.0000"/>
                <joint name="L_Shoulder_y" type="hinge" pos="0 0 0" axis="0 1 0" stiffness="500" damping="50" armature="0.02" range="-180.0000 180.0000"/>
                <joint name="L_Shoulder_z" type="hinge" pos="0 0 0" axis="0 0 1" stiffness="500" damping="50" armature="0.02" range="-180.0000 180.0000"/>
                <geom type="capsule" contype="1" conaffinity="1" density="500" fromto="-0.0082 0.0479 -0.0148 -0.0330 0.1915 -0.0591" size="0.0552" name="L_Shoulder"/>
                <body name="L_Elbow" pos="-0.0412 0.2393 -0.0739">
                  <joint name="L_Elbow_x" type="hinge" pos="0 0 0" axis="1 0 0" stiffness="500" damping="50" armature="0.02" range="-720.0000 720.0000"/>
                  <joint name="L_Elbow_y" type="hinge" pos="0 0 0" axis="0 1 0" stiffness="500" damping="50" armature="0.02" range="-720.0000 720.0000"/>
                  <joint name="L_Elbow_z" type="hinge" pos="0 0 0" axis="0 0 1" stiffness="500" damping="50" armature="0.02" range="-720.0000 720.0000"/>
                  <geom type="capsule" contype="1" conaffinity="1" density="500" fromto="0.0000 0.0503 0.0052 0.0001 0.2012 0.0207" size="0.0411" name="L_Elbow"/>
                  <body name="L_Wrist" pos="0.0002 0.2515 0.0258">
                    <joint name="L_Wrist_x" type="hinge" pos="0 0 0" axis="1 0 0" stiffness="300" damping="30" armature="0.02" range="-180.0000 180.0000"/>
                    <joint name="L_Wrist_y" type="hinge" pos="0 0 0" axis="0 1 0" stiffness="300" damping="30" armature="0.02" range="-180.0000 180.0000"/>
                    <joint name="L_Wrist_z" type="hinge" pos="0 0 0" axis="0 0 1" stiffness="300" damping="30" armature="0.02" range="-180.0000 180.0000"/>
                    <geom type="box" contype="1" conaffinity="1" density="500" pos="-0.0029 0.0408 -0.0059" size="0.0414 0.0411 0.0078" quat="0.7313 0.0000 0.0000 -0.6820" name="L_Wrist"/>
                    <body name="L_Index1" pos="0.0205 0.0964 -0.0089">
                      <joint name="L_Index1_x" type="hinge" pos="0 0 0" axis="1 0 0" stiffness="100" damping="10" armature="0.02" range="-180.0000 180.0000"/>
                      <joint name="L_Index1_y" type="hinge" pos="0 0 0" axis="0 1 0" stiffness="100" damping="10" armature="0.02" range="-180.0000 180.0000"/>
                      <joint name="L_Index1_z" type="hinge" pos="0 0 0" axis="0 0 1" stiffness="100" damping="10" armature="0.02" range="-180.0000 180.0000"/>
                      <geom type="capsule" contype="1" conaffinity="1" density="500" fromto="0.0007 0.0063 0.0003 0.0027 0.0254 0.0012" size="0.0095" name="L_Index1"/>
                      <body name="L_Index2" pos="0.0034 0.0317 0.0015">
                        <joint name="L_Index2_x" type="hinge" pos="0 0 0" axis="1 0 0" stiffness="100" damping="10" armature="0.02" range="-180.0000 180.0000"/>
                        <joint name="L_Index2_y" type="hinge" pos="0 0 0" axis="0 1 0" stiffness="100" damping="10" armature="0.02" range="-180.0000 180.0000"/>
                        <joint name="L_Index2_z" type="hinge" pos="0 0 0" axis="0 0 1" stiffness="100" damping="10" armature="0.02" range="-180.0000 180.0000"/>
                        <geom type="capsule" contype="1" conaffinity="1" density="500" fromto="-0.0001 0.0045 -0.0005 -0.0003 0.0179 -0.0021" size="0.0077" name="L_Index2"/>
                        <body name="L_Index3" pos="-0.0004 0.0224 -0.0026">
                          <joint name="L_Index3_x" type="hinge" pos="0 0 0" axis="1 0 0" stiffness="100" damping="10" armature="0.02" range="-180.0000 180.0000"/>
                          <joint name="L_Index3_y" type="hinge" pos="0 0 0" axis="0 1 0" stiffness="100" damping="10" armature="0.02" range="-180.0000 180.0000"/>
                          <joint name="L_Index3_z" type="hinge" pos="0 0 0" axis="0 0 1" stiffness="100" damping="10" armature="0.02" range="-180.0000 180.0000"/>
                          <geom type="capsule" contype="1" conaffinity="1" density="500" fromto="0.0003 0.0049 -0.0001 0.0013 0.0195 -0.0005" size="0.0065" name="L_Index3"/>
                        </body>
                      </body>
                    </body>
                    <body name="L_Middle1" pos="-0.0036 0.1038 -0.0062">
                      <joint name="L_Middle1_x" type="hinge" pos="0 0 0" axis="1 0 0" stiffness="100" damping="10" armature="0.02" range="-180.0000 180.0000"/>
                      <joint name="L_Middle1_y" type="hinge" pos="0 0 0" axis="0 1 0" stiffness="100" damping="10" armature="0.02" range="-180.0000 180.0000"/>
                      <joint name="L_Middle1_z" type="hinge" pos="0 0 0" axis="0 0 1" stiffness="100" damping="10" armature="0.02" range="-180.0000 180.0000"/>
                      <geom type="capsule" contype="1" conaffinity="1" density="500" fromto="-0.0009 0.0061 0.0001 -0.0034 0.0243 0.0004" size="0.0095" name="L_Middle1"/>
                      <body name="L_Middle2" pos="-0.0043 0.0303 0.0005">
                        <joint name="L_Middle2_x" type="hinge" pos="0 0 0" axis="1 0 0" stiffness="100" damping="10" armature="0.02" range="-180.0000 180.0000"/>
                        <joint name="L_Middle2_y" type="hinge" pos="0 0 0" axis="0 1 0" stiffness="100" damping="10" armature="0.02" range="-180.0000 180.0000"/>
                        <joint name="L_Middle2_z" type="hinge" pos="0 0 0" axis="0 0 1" stiffness="100" damping="10" armature="0.02" range="-180.0000 180.0000"/>
                        <geom type="capsule" contype="1" conaffinity="1" density="500" fromto="-0.0009 0.0046 -0.0005 -0.0034 0.0185 -0.0019" size="0.007" name="L_Middle2"/>
                        <body name="L_Middle3" pos="-0.0043 0.0232 -0.0023">
                          <joint name="L_Middle3_x" type="hinge" pos="0 0 0" axis="1 0 0" stiffness="100" damping="10" armature="0.02" range="-180.0000 180.0000"/>
                          <joint name="L_Middle3_y" type="hinge" pos="0 0 0" axis="0 1 0" stiffness="100" damping="10" armature="0.02" range="-180.0000 180.0000"/>
                          <joint name="L_Middle3_z" type="hinge" pos="0 0 0" axis="0 0 1" stiffness="100" damping="10" armature="0.02" range="-180.0000 180.0000"/>
                          <geom type="capsule" contype="1" conaffinity="1" density="500" fromto="-0.0005 0.0050 -0.0001 -0.0018 0.0201 -0.0003" size="0.0061" name="L_Middle3"/>
                        </body>
                      </body>
                    </body>
                    <body name="L_Pinky1" pos="-0.0446 0.0794 -0.0148">
                      <joint name="L_Pinky1_x" type="hinge" pos="0 0 0" axis="1 0 0" stiffness="100" damping="10" armature="0.02" range="-180.0000 180.0000"/>
                      <joint name="L_Pinky1_y" type="hinge" pos="0 0 0" axis="0 1 0" stiffness="100" damping="10" armature="0.02" range="-180.0000 180.0000"/>
                      <joint name="L_Pinky1_z" type="hinge" pos="0 0 0" axis="0 0 1" stiffness="100" damping="10" armature="0.02" range="-180.0000 180.0000"/>
                      <geom type="capsule" contype="1" conaffinity="1" density="500" fromto="-0.0023 0.0032 -0.0003 -0.0093 0.0130 -0.0013" size="0.0067" name="L_Pinky1"/>
                      <body name="L_Pinky2" pos="-0.0116 0.0162 -0.0016">
                        <joint name="L_Pinky2_x" type="hinge" pos="0 0 0" axis="1 0 0" stiffness="100" damping="10" armature="0.02" range="-180.0000 180.0000"/>
                        <joint name="L_Pinky2_y" type="hinge" pos="0 0 0" axis="0 1 0" stiffness="100" damping="10" armature="0.02" range="-180.0000 180.0000"/>
                        <joint name="L_Pinky2_z" type="hinge" pos="0 0 0" axis="0 0 1" stiffness="100" damping="10" armature="0.02" range="-180.0000 180.0000"/>
                        <geom type="capsule" contype="1" conaffinity="1" density="500" fromto="-0.0022 0.0032 -0.0004 -0.0086 0.0128 -0.0015" size="0.0064" name="L_Pinky2"/>
                        <body name="L_Pinky3" pos="-0.0108 0.0161 -0.0018">
                          <joint name="L_Pinky3_x" type="hinge" pos="0 0 0" axis="1 0 0" stiffness="100" damping="10" armature="0.02" range="-180.0000 180.0000"/>
                          <joint name="L_Pinky3_y" type="hinge" pos="0 0 0" axis="0 1 0" stiffness="100" damping="10" armature="0.02" range="-180.0000 180.0000"/>
                          <joint name="L_Pinky3_z" type="hinge" pos="0 0 0" axis="0 0 1" stiffness="100" damping="10" armature="0.02" range="-180.0000 180.0000"/>
                          <geom type="capsule" contype="1" conaffinity="1" density="500" fromto="-0.0018 0.0036 0.0000 -0.0070 0.0144 0.0001" size="0.0048" name="L_Pinky3"/>
                        </body>
                      </body>
                    </body>
                    <body name="L_Ring1" pos="-0.0276 0.0922 -0.0091">
                      <joint name="L_Ring1_x" type="hinge" pos="0 0 0" axis="1 0 0" stiffness="100" damping="10" armature="0.02" range="-180.0000 180.0000"/>
                      <joint name="L_Ring1_y" type="hinge" pos="0 0 0" axis="0 1 0" stiffness="100" damping="10" armature="0.02" range="-180.0000 180.0000"/>
                      <joint name="L_Ring1_z" type="hinge" pos="0 0 0" axis="0 0 1" stiffness="100" damping="10" armature="0.02" range="-180.0000 180.0000"/>
                      <geom type="capsule" contype="1" conaffinity="1" density="500" fromto="-0.0010 0.0056 0.0001 -0.0038 0.0225 0.0006" size="0.0081" name="L_Ring1"/>
                      <body name="L_Ring2" pos="-0.0048 0.0281 0.0007">
                        <joint name="L_Ring2_x" type="hinge" pos="0 0 0" axis="1 0 0" stiffness="100" damping="10" armature="0.02" range="-180.0000 180.0000"/>
                        <joint name="L_Ring2_y" type="hinge" pos="0 0 0" axis="0 1 0" stiffness="100" damping="10" armature="0.02" range="-180.0000 180.0000"/>
                        <joint name="L_Ring2_z" type="hinge" pos="0 0 0" axis="0 0 1" stiffness="100" damping="10" armature="0.02" range="-180.0000 180.0000"/>
                        <geom type="capsule" contype="1" conaffinity="1" density="500" fromto="-0.0013 0.0046 -0.0005 -0.0052 0.0184 -0.0018" size="0.0075" name="L_Ring2"/>
                        <body name="L_Ring3" pos="-0.0065 0.0229 -0.0023">
                          <joint name="L_Ring3_x" type="hinge" pos="0 0 0" axis="1 0 0" stiffness="100" damping="10" armature="0.02" range="-180.0000 180.0000"/>
                          <joint name="L_Ring3_y" type="hinge" pos="0 0 0" axis="0 1 0" stiffness="100" damping="10" armature="0.02" range="-180.0000 180.0000"/>
                          <joint name="L_Ring3_z" type="hinge" pos="0 0 0" axis="0 0 1" stiffness="100" damping="10" armature="0.02" range="-180.0000 180.0000"/>
                          <geom type="capsule" contype="1" conaffinity="1" density="500" fromto="-0.0009 0.0050 -0.0001 -0.0036 0.0200 -0.0002" size="0.0058" name="L_Ring3"/>
                        </body>
                      </body>
                    </body>
                    <body name="L_Thumb1" pos="0.0268 0.0365 -0.0198">
                      <joint name="L_Thumb1_x" type="hinge" pos="0 0 0" axis="1 0 0" stiffness="100" damping="10" armature="0.02" range="-180.0000 180.0000"/>
                      <joint name="L_Thumb1_y" type="hinge" pos="0 0 0" axis="0 1 0" stiffness="100" damping="10" armature="0.02" range="-180.0000 180.0000"/>
                      <joint name="L_Thumb1_z" type="hinge" pos="0 0 0" axis="0 0 1" stiffness="100" damping="10" armature="0.02" range="-180.0000 180.0000"/>
                      <geom type="capsule" contype="1" conaffinity="1" density="500" fromto="0.0052 0.0032 0.0004 0.0210 0.0128 0.0015" size="0.0123" name="L_Thumb1"/>
                      <body name="L_Thumb2" pos="0.0262 0.016 0.0019">
                        <joint name="L_Thumb2_x" type="hinge" pos="0 0 0" axis="1 0 0" stiffness="100" damping="10" armature="0.02" range="-180.0000 180.0000"/>
                        <joint name="L_Thumb2_y" type="hinge" pos="0 0 0" axis="0 1 0" stiffness="100" damping="10" armature="0.02" range="-180.0000 180.0000"/>
                        <joint name="L_Thumb2_z" type="hinge" pos="0 0 0" axis="0 0 1" stiffness="100" damping="10" armature="0.02" range="-180.0000 180.0000"/>
                        <geom type="capsule" contype="1" conaffinity="1" density="500" fromto="0.0033 0.0040 -0.0009 0.0130 0.0160 -0.0034" size="0.0098" name="L_Thumb2"/>
                        <body name="L_Thumb3" pos="0.0163 0.02 -0.0043">
                          <joint name="L_Thumb3_x" type="hinge" pos="0 0 0" axis="1 0 0" stiffness="100" damping="10" armature="0.02" range="-180.0000 180.0000"/>
                          <joint name="L_Thumb3_y" type="hinge" pos="0 0 0" axis="0 1 0" stiffness="100" damping="10" armature="0.02" range="-180.0000 180.0000"/>
                          <joint name="L_Thumb3_z" type="hinge" pos="0 0 0" axis="0 0 1" stiffness="100" damping="10" armature="0.02" range="-180.0000 180.0000"/>
                          <geom type="capsule" contype="1" conaffinity="1" density="500" fromto="0.0037 0.0044 -0.0005 0.0146 0.0176 -0.0018" size="0.0088" name="L_Thumb3"/>
                        </body>
                      </body>
                    </body>
                  </body>
                </body>
              </body>
            </body>
            <body name="R_Thorax" pos="-0.006 -0.0441 0.0772">
              <joint name="R_Thorax_x" type="hinge" pos="0 0 0" axis="1 0 0" stiffness="500" damping="50" armature="0.02" range="-180.0000 180.0000"/>
              <joint name="R_Thorax_y" type="hinge" pos="0 0 0" axis="0 1 0" stiffness="500" damping="50" armature="0.02" range="-180.0000 180.0000"/>
              <joint name="R_Thorax_z" type="hinge" pos="0 0 0" axis="0 0 1" stiffness="500" damping="50" armature="0.02" range="-180.0000 180.0000"/>
              <geom type="capsule" contype="1" conaffinity="1" density="500" fromto="-0.0020 -0.0251 0.0126 -0.0081 -0.1006 0.0503" size="0.0571" name="R_Thorax"/>
              <body name="R_Shoulder" pos="-0.0102 -0.1257 0.0629">
                <joint name="R_Shoulder_x" type="hinge" pos="0 0 0" axis="1 0 0" stiffness="500" damping="50" armature="0.02" range="-180.0000 180.0000"/>
                <joint name="R_Shoulder_y" type="hinge" pos="0 0 0" axis="0 1 0" stiffness="500" damping="50" armature="0.02" range="-180.0000 180.0000"/>
                <joint name="R_Shoulder_z" type="hinge" pos="0 0 0" axis="0 0 1" stiffness="500" damping="50" armature="0.02" range="-180.0000 180.0000"/>
                <geom type="capsule" contype="1" conaffinity="1" density="500" fromto="-0.0057 -0.0511 -0.0089 -0.0227 -0.2043 -0.0354" size="0.0545" name="R_Shoulder"/>
                <body name="R_Elbow" pos="-0.0284 -0.2554 -0.0443">
                  <joint name="R_Elbow_x" type="hinge" pos="0 0 0" axis="1 0 0" stiffness="500" damping="50" armature="0.02" range="-720.0000 720.0000"/>
                  <joint name="R_Elbow_y" type="hinge" pos="0 0 0" axis="0 1 0" stiffness="500" damping="50" armature="0.02" range="-720.0000 720.0000"/>
                  <joint name="R_Elbow_z" type="hinge" pos="0 0 0" axis="0 0 1" stiffness="500" damping="50" armature="0.02" range="-720.0000 720.0000"/>
                  <geom type="capsule" contype="1" conaffinity="1" density="500" fromto="-0.0021 -0.0488 0.0002 -0.0085 -0.1954 0.0008" size="0.042" name="R_Elbow"/>
                  <body name="R_Wrist" pos="-0.0106 -0.2442 0.001">
                    <joint name="R_Wrist_x" type="hinge" pos="0 0 0" axis="1 0 0" stiffness="300" damping="30" armature="0.02" range="-180.0000 180.0000"/>
                    <joint name="R_Wrist_y" type="hinge" pos="0 0 0" axis="0 1 0" stiffness="300" damping="30" armature="0.02" range="-180.0000 180.0000"/>
                    <joint name="R_Wrist_z" type="hinge" pos="0 0 0" axis="0 0 1" stiffness="300" damping="30" armature="0.02" range="-180.0000 180.0000"/>
                    <geom type="box" contype="1" conaffinity="1" density="500" pos="-0.0033 -0.0406 -0.0077" size="0.0414 0.0421 0.008" quat="0.7351 0.0000 0.0000 0.6780" name="R_Wrist"/>
                    <body name="R_Index1" pos="0.0197 -0.096 -0.0125">
                      <joint name="R_Index1_x" type="hinge" pos="0 0 0" axis="1 0 0" stiffness="100" damping="10" armature="0.02" range="-180.0000 180.0000"/>
                      <joint name="R_Index1_y" type="hinge" pos="0 0 0" axis="0 1 0" stiffness="100" damping="10" armature="0.02" range="-180.0000 180.0000"/>
                      <joint name="R_Index1_z" type="hinge" pos="0 0 0" axis="0 0 1" stiffness="100" damping="10" armature="0.02" range="-180.0000 180.0000"/>
                      <geom type="capsule" contype="1" conaffinity="1" density="500" fromto="0.0007 -0.0063 0.0003 0.0027 -0.0254 0.0012" size="0.0095" name="R_Index1"/>
                      <body name="R_Index2" pos="0.0034 -0.0317 0.0015">
                        <joint name="R_Index2_x" type="hinge" pos="0 0 0" axis="1 0 0" stiffness="100" damping="10" armature="0.02" range="-180.0000 180.0000"/>
                        <joint name="R_Index2_y" type="hinge" pos="0 0 0" axis="0 1 0" stiffness="100" damping="10" armature="0.02" range="-180.0000 180.0000"/>
                        <joint name="R_Index2_z" type="hinge" pos="0 0 0" axis="0 0 1" stiffness="100" damping="10" armature="0.02" range="-180.0000 180.0000"/>
                        <geom type="capsule" contype="1" conaffinity="1" density="500" fromto="-0.0001 -0.0045 -0.0005 -0.0003 -0.0179 -0.0021" size="0.0077" name="R_Index2"/>
                        <body name="R_Index3" pos="-0.0004 -0.0224 -0.0026">
                          <joint name="R_Index3_x" type="hinge" pos="0 0 0" axis="1 0 0" stiffness="100" damping="10" armature="0.02" range="-180.0000 180.0000"/>
                          <joint name="R_Index3_y" type="hinge" pos="0 0 0" axis="0 1 0" stiffness="100" damping="10" armature="0.02" range="-180.0000 180.0000"/>
                          <joint name="R_Index3_z" type="hinge" pos="0 0 0" axis="0 0 1" stiffness="100" damping="10" armature="0.02" range="-180.0000 180.0000"/>
                          <geom type="capsule" contype="1" conaffinity="1" density="500" fromto="0.0003 -0.0041 -0.0001 0.0013 -0.0163 -0.0005" size="0.0068" name="R_Index3"/>
                        </body>
                      </body>
                    </body>
                    <body name="R_Middle1" pos="-0.0045 -0.1034 -0.0098">
                      <joint name="R_Middle1_x" type="hinge" pos="0 0 0" axis="1 0 0" stiffness="100" damping="10" armature="0.02" range="-180.0000 180.0000"/>
                      <joint name="R_Middle1_y" type="hinge" pos="0 0 0" axis="0 1 0" stiffness="100" damping="10" armature="0.02" range="-180.0000 180.0000"/>
                      <joint name="R_Middle1_z" type="hinge" pos="0 0 0" axis="0 0 1" stiffness="100" damping="10" armature="0.02" range="-180.0000 180.0000"/>
                      <geom type="capsule" contype="1" conaffinity="1" density="500" fromto="-0.0009 -0.0061 0.0001 -0.0034 -0.0243 0.0004" size="0.0095" name="R_Middle1"/>
                      <body name="R_Middle2" pos="-0.0043 -0.0303 0.0005">
                        <joint name="R_Middle2_x" type="hinge" pos="0 0 0" axis="1 0 0" stiffness="100" damping="10" armature="0.02" range="-180.0000 180.0000"/>
                        <joint name="R_Middle2_y" type="hinge" pos="0 0 0" axis="0 1 0" stiffness="100" damping="10" armature="0.02" range="-180.0000 180.0000"/>
                        <joint name="R_Middle2_z" type="hinge" pos="0 0 0" axis="0 0 1" stiffness="100" damping="10" armature="0.02" range="-180.0000 180.0000"/>
                        <geom type="capsule" contype="1" conaffinity="1" density="500" fromto="-0.0009 -0.0046 -0.0005 -0.0034 -0.0185 -0.0019" size="0.007" name="R_Middle2"/>
                        <body name="R_Middle3" pos="-0.0043 -0.0232 -0.0023">
                          <joint name="R_Middle3_x" type="hinge" pos="0 0 0" axis="1 0 0" stiffness="100" damping="10" armature="0.02" range="-180.0000 180.0000"/>
                          <joint name="R_Middle3_y" type="hinge" pos="0 0 0" axis="0 1 0" stiffness="100" damping="10" armature="0.02" range="-180.0000 180.0000"/>
                          <joint name="R_Middle3_z" type="hinge" pos="0 0 0" axis="0 0 1" stiffness="100" damping="10" armature="0.02" range="-180.0000 180.0000"/>
                          <geom type="capsule" contype="1" conaffinity="1" density="500" fromto="-0.0005 -0.0042 -0.0001 -0.0018 -0.0169 -0.0003" size="0.0064" name="R_Middle3"/>
                        </body>
                      </body>
                    </body>
                    <body name="R_Pinky1" pos="-0.0455 -0.079 -0.0184">
                      <joint name="R_Pinky1_x" type="hinge" pos="0 0 0" axis="1 0 0" stiffness="100" damping="10" armature="0.02" range="-180.0000 180.0000"/>
                      <joint name="R_Pinky1_y" type="hinge" pos="0 0 0" axis="0 1 0" stiffness="100" damping="10" armature="0.02" range="-180.0000 180.0000"/>
                      <joint name="R_Pinky1_z" type="hinge" pos="0 0 0" axis="0 0 1" stiffness="100" damping="10" armature="0.02" range="-180.0000 180.0000"/>
                      <geom type="capsule" contype="1" conaffinity="1" density="500" fromto="-0.0023 -0.0032 -0.0003 -0.0093 -0.0130 -0.0013" size="0.0067" name="R_Pinky1"/>
                      <body name="R_Pinky2" pos="-0.0116 -0.0162 -0.0016">
                        <joint name="R_Pinky2_x" type="hinge" pos="0 0 0" axis="1 0 0" stiffness="100" damping="10" armature="0.02" range="-180.0000 180.0000"/>
                        <joint name="R_Pinky2_y" type="hinge" pos="0 0 0" axis="0 1 0" stiffness="100" damping="10" armature="0.02" range="-180.0000 180.0000"/>
                        <joint name="R_Pinky2_z" type="hinge" pos="0 0 0" axis="0 0 1" stiffness="100" damping="10" armature="0.02" range="-180.0000 180.0000"/>
                        <geom type="capsule" contype="1" conaffinity="1" density="500" fromto="-0.0022 -0.0032 -0.0004 -0.0086 -0.0128 -0.0015" size="0.0064" name="R_Pinky2"/>
                        <body name="R_Pinky3" pos="-0.0108 -0.0161 -0.0018">
                          <joint name="R_Pinky3_x" type="hinge" pos="0 0 0" axis="1 0 0" stiffness="100" damping="10" armature="0.02" range="-180.0000 180.0000"/>
                          <joint name="R_Pinky3_y" type="hinge" pos="0 0 0" axis="0 1 0" stiffness="100" damping="10" armature="0.02" range="-180.0000 180.0000"/>
                          <joint name="R_Pinky3_z" type="hinge" pos="0 0 0" axis="0 0 1" stiffness="100" damping="10" armature="0.02" range="-180.0000 180.0000"/>
                          <geom type="capsule" contype="1" conaffinity="1" density="500" fromto="-0.0018 -0.0028 0.0000 -0.0070 -0.0112 0.0001" size="0.0051" name="R_Pinky3"/>
                        </body>
                      </body>
                    </body>
                    <body name="R_Ring1" pos="-0.0285 -0.0918 -0.0127">
                      <joint name="R_Ring1_x" type="hinge" pos="0 0 0" axis="1 0 0" stiffness="100" damping="10" armature="0.02" range="-180.0000 180.0000"/>
                      <joint name="R_Ring1_y" type="hinge" pos="0 0 0" axis="0 1 0" stiffness="100" damping="10" armature="0.02" range="-180.0000 180.0000"/>
                      <joint name="R_Ring1_z" type="hinge" pos="0 0 0" axis="0 0 1" stiffness="100" damping="10" armature="0.02" range="-180.0000 180.0000"/>
                      <geom type="capsule" contype="1" conaffinity="1" density="500" fromto="-0.0010 -0.0056 0.0001 -0.0038 -0.0225 0.0006" size="0.0081" name="R_Ring1"/>
                      <body name="R_Ring2" pos="-0.0048 -0.0281 0.0007">
                        <joint name="R_Ring2_x" type="hinge" pos="0 0 0" axis="1 0 0" stiffness="100" damping="10" armature="0.02" range="-180.0000 180.0000"/>
                        <joint name="R_Ring2_y" type="hinge" pos="0 0 0" axis="0 1 0" stiffness="100" damping="10" armature="0.02" range="-180.0000 180.0000"/>
                        <joint name="R_Ring2_z" type="hinge" pos="0 0 0" axis="0 0 1" stiffness="100" damping="10" armature="0.02" range="-180.0000 180.0000"/>
                        <geom type="capsule" contype="1" conaffinity="1" density="500" fromto="-0.0013 -0.0046 -0.0005 -0.0052 -0.0184 -0.0018" size="0.0075" name="R_Ring2"/>
                        <body name="R_Ring3" pos="-0.0065 -0.0229 -0.0023">
                          <joint name="R_Ring3_x" type="hinge" pos="0 0 0" axis="1 0 0" stiffness="100" damping="10" armature="0.02" range="-180.0000 180.0000"/>
                          <joint name="R_Ring3_y" type="hinge" pos="0 0 0" axis="0 1 0" stiffness="100" damping="10" armature="0.02" range="-180.0000 180.0000"/>
                          <joint name="R_Ring3_z" type="hinge" pos="0 0 0" axis="0 0 1" stiffness="100" damping="10" armature="0.02" range="-180.0000 180.0000"/>
                          <geom type="capsule" contype="1" conaffinity="1" density="500" fromto="-0.0009 -0.0042 -0.0001 -0.0036 -0.0168 -0.0002" size="0.006" name="R_Ring3"/>
                        </body>
                      </body>
                    </body>
                    <body name="R_Thumb1" pos="0.0259 -0.0361 -0.0234">
                      <joint name="R_Thumb1_x" type="hinge" pos="0 0 0" axis="1 0 0" stiffness="100" damping="10" armature="0.02" range="-180.0000 180.0000"/>
                      <joint name="R_Thumb1_y" type="hinge" pos="0 0 0" axis="0 1 0" stiffness="100" damping="10" armature="0.02" range="-180.0000 180.0000"/>
                      <joint name="R_Thumb1_z" type="hinge" pos="0 0 0" axis="0 0 1" stiffness="100" damping="10" armature="0.02" range="-180.0000 180.0000"/>
                      <geom type="capsule" contype="1" conaffinity="1" density="500" fromto="0.0052 -0.0032 0.0004 0.0210 -0.0128 0.0015" size="0.0123" name="R_Thumb1"/>
                      <body name="R_Thumb2" pos="0.0262 -0.016 0.0019">
                        <joint name="R_Thumb2_x" type="hinge" pos="0 0 0" axis="1 0 0" stiffness="100" damping="10" armature="0.02" range="-180.0000 180.0000"/>
                        <joint name="R_Thumb2_y" type="hinge" pos="0 0 0" axis="0 1 0" stiffness="100" damping="10" armature="0.02" range="-180.0000 180.0000"/>
                        <joint name="R_Thumb2_z" type="hinge" pos="0 0 0" axis="0 0 1" stiffness="100" damping="10" armature="0.02" range="-180.0000 180.0000"/>
                        <geom type="capsule" contype="1" conaffinity="1" density="500" fromto="0.0033 -0.0040 -0.0009 0.0130 -0.0160 -0.0034" size="0.0098" name="R_Thumb2"/>
                        <body name="R_Thumb3" pos="0.0163 -0.02 -0.0043">
                          <joint name="R_Thumb3_x" type="hinge" pos="0 0 0" axis="1 0 0" stiffness="100" damping="10" armature="0.02" range="-180.0000 180.0000"/>
                          <joint name="R_Thumb3_y" type="hinge" pos="0 0 0" axis="0 1 0" stiffness="100" damping="10" armature="0.02" range="-180.0000 180.0000"/>
                          <joint name="R_Thumb3_z" type="hinge" pos="0 0 0" axis="0 0 1" stiffness="100" damping="10" armature="0.02" range="-180.0000 180.0000"/>
                          <geom type="capsule" contype="1" conaffinity="1" density="500" fromto="0.0037 -0.0036 -0.0005 0.0146 -0.0144 -0.0018" size="0.009" name="R_Thumb3"/>
                        </body>
                      </body>
                    </body>
                  </body>
                </body>
              </body>
            </body>
          </body>
        </body>
      </body>
    </body>
  </worldbody>
  <actuator>
    <motor name="L_Hip_x" joint="L_Hip_x" gear="500"/>
    <motor name="L_Hip_y" joint="L_Hip_y" gear="500"/>
    <motor name="L_Hip_z" joint="L_Hip_z" gear="500"/>
    <motor name="L_Knee_x" joint="L_Knee_x" gear="500"/>
    <motor name="L_Knee_y" joint="L_Knee_y" gear="500"/>
    <motor name="L_Knee_z" joint="L_Knee_z" gear="500"/>
    <motor name="L_Ankle_x" joint="L_Ankle_x" gear="500"/>
    <motor name="L_Ankle_y" joint="L_Ankle_y" gear="500"/>
    <motor name="L_Ankle_z" joint="L_Ankle_z" gear="500"/>
    <motor name="L_Toe_x" joint="L_Toe_x" gear="500"/>
    <motor name="L_Toe_y" joint="L_Toe_y" gear="500"/>
    <motor name="L_Toe_z" joint="L_Toe_z" gear="500"/>
    <motor name="R_Hip_x" joint="R_Hip_x" gear="500"/>
    <motor name="R_Hip_y" joint="R_Hip_y" gear="500"/>
    <motor name="R_Hip_z" joint="R_Hip_z" gear="500"/>
    <motor name="R_Knee_x" joint="R_Knee_x" gear="500"/>
    <motor name="R_Knee_y" joint="R_Knee_y" gear="500"/>
    <motor name="R_Knee_z" joint="R_Knee_z" gear="500"/>
    <motor name="R_Ankle_x" joint="R_Ankle_x" gear="500"/>
    <motor name="R_Ankle_y" joint="R_Ankle_y" gear="500"/>
    <motor name="R_Ankle_z" joint="R_Ankle_z" gear="500"/>
    <motor name="R_Toe_x" joint="R_Toe_x" gear="500"/>
    <motor name="R_Toe_y" joint="R_Toe_y" gear="500"/>
    <motor name="R_Toe_z" joint="R_Toe_z" gear="500"/>
    <motor name="Torso_x" joint="Torso_x" gear="500"/>
    <motor name="Torso_y" joint="Torso_y" gear="500"/>
    <motor name="Torso_z" joint="Torso_z" gear="500"/>
    <motor name="Spine_x" joint="Spine_x" gear="500"/>
    <motor name="Spine_y" joint="Spine_y" gear="500"/>
    <motor name="Spine_z" joint="Spine_z" gear="500"/>
    <motor name="Chest_x" joint="Chest_x" gear="500"/>
    <motor name="Chest_y" joint="Chest_y" gear="500"/>
    <motor name="Chest_z" joint="Chest_z" gear="500"/>
    <motor name="Neck_x" joint="Neck_x" gear="500"/>
    <motor name="Neck_y" joint="Neck_y" gear="500"/>
    <motor name="Neck_z" joint="Neck_z" gear="500"/>
    <motor name="Head_x" joint="Head_x" gear="500"/>
    <motor name="Head_y" joint="Head_y" gear="500"/>
    <motor name="Head_z" joint="Head_z" gear="500"/>
    <motor name="L_Thorax_x" joint="L_Thorax_x" gear="500"/>
    <motor name="L_Thorax_y" joint="L_Thorax_y" gear="500"/>
    <motor name="L_Thorax_z" joint="L_Thorax_z" gear="500"/>
    <motor name="L_Shoulder_x" joint="L_Shoulder_x" gear="500"/>
    <motor name="L_Shoulder_y" joint="L_Shoulder_y" gear="500"/>
    <motor name="L_Shoulder_z" joint="L_Shoulder_z" gear="500"/>
    <motor name="L_Elbow_x" joint="L_Elbow_x" gear="500"/>
    <motor name="L_Elbow_y" joint="L_Elbow_y" gear="500"/>
    <motor name="L_Elbow_z" joint="L_Elbow_z" gear="500"/>
    <motor name="L_Wrist_x" joint="L_Wrist_x" gear="500"/>
    <motor name="L_Wrist_y" joint="L_Wrist_y" gear="500"/>
    <motor name="L_Wrist_z" joint="L_Wrist_z" gear="500"/>
    <motor name="L_Index1_x" joint="L_Index1_x" gear="500"/>
    <motor name="L_Index1_y" joint="L_Index1_y" gear="500"/>
    <motor name="L_Index1_z" joint="L_Index1_z" gear="500"/>
    <motor name="L_Index2_x" joint="L_Index2_x" gear="500"/>
    <motor name="L_Index2_y" joint="L_Index2_y" gear="500"/>
    <motor name="L_Index2_z" joint="L_Index2_z" gear="500"/>
    <motor name="L_Index3_x" joint="L_Index3_x" gear="500"/>
    <motor name="L_Index3_y" joint="L_Index3_y" gear="500"/>
    <motor name="L_Index3_z" joint="L_Index3_z" gear="500"/>
    <motor name="L_Middle1_x" joint="L_Middle1_x" gear="500"/>
    <motor name="L_Middle1_y" joint="L_Middle1_y" gear="500"/>
    <motor name="L_Middle1_z" joint="L_Middle1_z" gear="500"/>
    <motor name="L_Middle2_x" joint="L_Middle2_x" gear="500"/>
    <motor name="L_Middle2_y" joint="L_Middle2_y" gear="500"/>
    <motor name="L_Middle2_z" joint="L_Middle2_z" gear="500"/>
    <motor name="L_Middle3_x" joint="L_Middle3_x" gear="500"/>
    <motor name="L_Middle3_y" joint="L_Middle3_y" gear="500"/>
    <motor name="L_Middle3_z" joint="L_Middle3_z" gear="500"/>
    <motor name="L_Pinky1_x" joint="L_Pinky1_x" gear="500"/>
    <motor name="L_Pinky1_y" joint="L_Pinky1_y" gear="500"/>
    <motor name="L_Pinky1_z" joint="L_Pinky1_z" gear="500"/>
    <motor name="L_Pinky2_x" joint="L_Pinky2_x" gear="500"/>
    <motor name="L_Pinky2_y" joint="L_Pinky2_y" gear="500"/>
    <motor name="L_Pinky2_z" joint="L_Pinky2_z" gear="500"/>
    <motor name="L_Pinky3_x" joint="L_Pinky3_x" gear="500"/>
    <motor name="L_Pinky3_y" joint="L_Pinky3_y" gear="500"/>
    <motor name="L_Pinky3_z" joint="L_Pinky3_z" gear="500"/>
    <motor name="L_Ring1_x" joint="L_Ring1_x" gear="500"/>
    <motor name="L_Ring1_y" joint="L_Ring1_y" gear="500"/>
    <motor name="L_Ring1_z" joint="L_Ring1_z" gear="500"/>
    <motor name="L_Ring2_x" joint="L_Ring2_x" gear="500"/>
    <motor name="L_Ring2_y" joint="L_Ring2_y" gear="500"/>
    <motor name="L_Ring2_z" joint="L_Ring2_z" gear="500"/>
    <motor name="L_Ring3_x" joint="L_Ring3_x" gear="500"/>
    <motor name="L_Ring3_y" joint="L_Ring3_y" gear="500"/>
    <motor name="L_Ring3_z" joint="L_Ring3_z" gear="500"/>
    <motor name="L_Thumb1_x" joint="L_Thumb1_x" gear="500"/>
    <motor name="L_Thumb1_y" joint="L_Thumb1_y" gear="500"/>
    <motor name="L_Thumb1_z" joint="L_Thumb1_z" gear="500"/>
    <motor name="L_Thumb2_x" joint="L_Thumb2_x" gear="500"/>
    <motor name="L_Thumb2_y" joint="L_Thumb2_y" gear="500"/>
    <motor name="L_Thumb2_z" joint="L_Thumb2_z" gear="500"/>
    <motor name="L_Thumb3_x" joint="L_Thumb3_x" gear="500"/>
    <motor name="L_Thumb3_y" joint="L_Thumb3_y" gear="500"/>
    <motor name="L_Thumb3_z" joint="L_Thumb3_z" gear="500"/>
    <motor name="R_Thorax_x" joint="R_Thorax_x" gear="500"/>
    <motor name="R_Thorax_y" joint="R_Thorax_y" gear="500"/>
    <motor name="R_Thorax_z" joint="R_Thorax_z" gear="500"/>
    <motor name="R_Shoulder_x" joint="R_Shoulder_x" gear="500"/>
    <motor name="R_Shoulder_y" joint="R_Shoulder_y" gear="500"/>
    <motor name="R_Shoulder_z" joint="R_Shoulder_z" gear="500"/>
    <motor name="R_Elbow_x" joint="R_Elbow_x" gear="500"/>
    <motor name="R_Elbow_y" joint="R_Elbow_y" gear="500"/>
    <motor name="R_Elbow_z" joint="R_Elbow_z" gear="500"/>
    <motor name="R_Wrist_x" joint="R_Wrist_x" gear="500"/>
    <motor name="R_Wrist_y" joint="R_Wrist_y" gear="500"/>
    <motor name="R_Wrist_z" joint="R_Wrist_z" gear="500"/>
    <motor name="R_Index1_x" joint="R_Index1_x" gear="500"/>
    <motor name="R_Index1_y" joint="R_Index1_y" gear="500"/>
    <motor name="R_Index1_z" joint="R_Index1_z" gear="500"/>
    <motor name="R_Index2_x" joint="R_Index2_x" gear="500"/>
    <motor name="R_Index2_y" joint="R_Index2_y" gear="500"/>
    <motor name="R_Index2_z" joint="R_Index2_z" gear="500"/>
    <motor name="R_Index3_x" joint="R_Index3_x" gear="500"/>
    <motor name="R_Index3_y" joint="R_Index3_y" gear="500"/>
    <motor name="R_Index3_z" joint="R_Index3_z" gear="500"/>
    <motor name="R_Middle1_x" joint="R_Middle1_x" gear="500"/>
    <motor name="R_Middle1_y" joint="R_Middle1_y" gear="500"/>
    <motor name="R_Middle1_z" joint="R_Middle1_z" gear="500"/>
    <motor name="R_Middle2_x" joint="R_Middle2_x" gear="500"/>
    <motor name="R_Middle2_y" joint="R_Middle2_y" gear="500"/>
    <motor name="R_Middle2_z" joint="R_Middle2_z" gear="500"/>
    <motor name="R_Middle3_x" joint="R_Middle3_x" gear="500"/>
    <motor name="R_Middle3_y" joint="R_Middle3_y" gear="500"/>
    <motor name="R_Middle3_z" joint="R_Middle3_z" gear="500"/>
    <motor name="R_Pinky1_x" joint="R_Pinky1_x" gear="500"/>
    <motor name="R_Pinky1_y" joint="R_Pinky1_y" gear="500"/>
    <motor name="R_Pinky1_z" joint="R_Pinky1_z" gear="500"/>
    <motor name="R_Pinky2_x" joint="R_Pinky2_x" gear="500"/>
    <motor name="R_Pinky2_y" joint="R_Pinky2_y" gear="500"/>
    <motor name="R_Pinky2_z" joint="R_Pinky2_z" gear="500"/>
    <motor name="R_Pinky3_x" joint="R_Pinky3_x" gear="500"/>
    <motor name="R_Pinky3_y" joint="R_Pinky3_y" gear="500"/>
    <motor name="R_Pinky3_z" joint="R_Pinky3_z" gear="500"/>
    <motor name="R_Ring1_x" joint="R_Ring1_x" gear="500"/>
    <motor name="R_Ring1_y" joint="R_Ring1_y" gear="500"/>
    <motor name="R_Ring1_z" joint="R_Ring1_z" gear="500"/>
    <motor name="R_Ring2_x" joint="R_Ring2_x" gear="500"/>
    <motor name="R_Ring2_y" joint="R_Ring2_y" gear="500"/>
    <motor name="R_Ring2_z" joint="R_Ring2_z" gear="500"/>
    <motor name="R_Ring3_x" joint="R_Ring3_x" gear="500"/>
    <motor name="R_Ring3_y" joint="R_Ring3_y" gear="500"/>
    <motor name="R_Ring3_z" joint="R_Ring3_z" gear="500"/>
    <motor name="R_Thumb1_x" joint="R_Thumb1_x" gear="500"/>
    <motor name="R_Thumb1_y" joint="R_Thumb1_y" gear="500"/>
    <motor name="R_Thumb1_z" joint="R_Thumb1_z" gear="500"/>
    <motor name="R_Thumb2_x" joint="R_Thumb2_x" gear="500"/>
    <motor name="R_Thumb2_y" joint="R_Thumb2_y" gear="500"/>
    <motor name="R_Thumb2_z" joint="R_Thumb2_z" gear="500"/>
    <motor name="R_Thumb3_x" joint="R_Thumb3_x" gear="500"/>
    <motor name="R_Thumb3_y" joint="R_Thumb3_y" gear="500"/>
    <motor name="R_Thumb3_z" joint="R_Thumb3_z" gear="500"/>
  </actuator>
  <contact>
    <exclude body1="Torso" body2="Chest"/>
    <exclude body1="Head" body2="Chest"/>
    <exclude body1="R_Knee" body2="R_Toe"/>
    <exclude body1="R_Knee" body2="L_Ankle"/>
    <exclude body1="R_Knee" body2="L_Toe"/>
    <exclude body1="L_Knee" body2="L_Toe"/>
    <exclude body1="L_Knee" body2="R_Ankle"/>
    <exclude body1="L_Knee" body2="R_Toe"/>
    <exclude body1="L_Shoulder" body2="Chest"/>
    <exclude body1="R_Shoulder" body2="Chest"/>
  </contact>
  <sensor/>
  <size njmax="700" nconmax="700"/>
</mujoco>
