<mujoco model="humanoid">
  <compiler coordinate="local" angle="radian"/>
  <default>
    <joint damping="0.0" armature="0.01" stiffness="0.0" limited="true"/>
    <geom conaffinity="1" condim="3" contype="7" margin="0.001" rgba="0.8 0.6 .4 1"/>
  </default>
  <asset>
    <texture type="skybox" builtin="gradient" rgb1=".4 .5 .6" rgb2="0 0 0" width="100" height="100"/>
    <texture builtin="flat" height="1278" mark="cross" markrgb="1 1 1" name="texgeom" random="0.01" rgb1="0.8 0.6 0.4" rgb2="0.8 0.6 0.4" type="cube" width="127"/>
    <texture builtin="checker" height="100" name="texplane" rgb1="0 0 0" rgb2="0.8 0.8 0.8" type="2d" width="100"/>
    <material name="MatPlane" reflectance="0.5" shininess="1" specular="1" texrepeat="60 60" texture="texplane"/>
    <material name="geom" texture="texgeom" texuniform="true"/>
  </asset>
  <worldbody>
    <light cutoff="100" diffuse="1 1 1" dir="-0 0 -1.3" directional="true" exponent="1" pos="0 0 1.3" specular=".1 .1 .1"/>
    <geom conaffinity="1" condim="3" name="floor" pos="0 0 0" rgba="0.8 0.9 0.8 1" size="100 100 .2" type="plane" material="MatPlane"/>
    <body name="Pelvis" pos="0.0015 -0.3378 0.0243">
      <freejoint name="Pelvis"/>
      <geom type="sphere" contype="1" conaffinity="1" density="500" size="0.1011" pos="0.0000 0.0000 0.0000" name="Pelvis"/>
      <body name="L_Hip" pos="-0.0144 0.0536 -0.0897">
        <joint name="L_Hip_x" type="hinge" pos="0 0 0" axis="1 0 0" stiffness="800" damping="80" armature="0.02" range="-180.0000 180.0000"/>
        <joint name="L_Hip_y" type="hinge" pos="0 0 0" axis="0 1 0" stiffness="800" damping="80" armature="0.02" range="-180.0000 180.0000"/>
        <joint name="L_Hip_z" type="hinge" pos="0 0 0" axis="0 0 1" stiffness="800" damping="80" armature="0.02" range="-180.0000 180.0000"/>
        <geom type="capsule" contype="1" conaffinity="1" density="500" fromto="0.0001 0.0130 -0.0798 0.0005 0.0519 -0.3190" size="0.0566" name="L_Hip"/>
        <body name="L_Knee" pos="0.0006 0.0648 -0.3988">
          <joint name="L_Knee_x" type="hinge" pos="0 0 0" axis="1 0 0" stiffness="800" damping="80" armature="0.02" range="-180.0000 180.0000"/>
          <joint name="L_Knee_y" type="hinge" pos="0 0 0" axis="0 1 0" stiffness="800" damping="80" armature="0.02" range="-180.0000 180.0000"/>
          <joint name="L_Knee_z" type="hinge" pos="0 0 0" axis="0 0 1" stiffness="800" damping="80" armature="0.02" range="-180.0000 180.0000"/>
          <geom type="capsule" contype="1" conaffinity="1" density="500" fromto="-0.0072 -0.0083 -0.0864 -0.0289 -0.0333 -0.3458" size="0.0515" name="L_Knee"/>
          <body name="L_Ankle" pos="-0.0361 -0.0416 -0.4322">
            <joint name="L_Ankle_x" type="hinge" pos="0 0 0" axis="1 0 0" stiffness="800" damping="80" armature="0.02" range="-180.0000 180.0000"/>
            <joint name="L_Ankle_y" type="hinge" pos="0 0 0" axis="0 1 0" stiffness="800" damping="80" armature="0.02" range="-180.0000 180.0000"/>
            <joint name="L_Ankle_z" type="hinge" pos="0 0 0" axis="0 0 1" stiffness="800" damping="80" armature="0.02" range="-180.0000 180.0000"/>
            <geom type="box" contype="1" conaffinity="1" density="500" pos="0.0665 0.0203 -0.0310" size="0.0917 0.0499 0.021" quat="0.9891 0.0000 0.0000 0.1473" name="L_Ankle"/>
            <body name="L_Toe" pos="0.1331 0.0406 -0.062">
              <joint name="L_Toe_x" type="hinge" pos="0 0 0" axis="1 0 0" stiffness="500" damping="50" armature="0.02" range="-180.0000 180.0000"/>
              <joint name="L_Toe_y" type="hinge" pos="0 0 0" axis="0 1 0" stiffness="500" damping="50" armature="0.02" range="-180.0000 180.0000"/>
              <joint name="L_Toe_z" type="hinge" pos="0 0 0" axis="0 0 1" stiffness="500" damping="50" armature="0.02" range="-180.0000 180.0000"/>
              <geom type="box" contype="1" conaffinity="1" density="500" pos="0.0000 0.0000 0.0313" size="0.001 0.0024 0.0011" quat="0.9884 0.0000 0.0000 0.1520" name="L_Toe"/>
            </body>
          </body>
        </body>
      </body>
      <body name="R_Hip" pos="-0.0085 -0.0555 -0.1008">
        <joint name="R_Hip_x" type="hinge" pos="0 0 0" axis="1 0 0" stiffness="800" damping="80" armature="0.02" range="-180.0000 180.0000"/>
        <joint name="R_Hip_y" type="hinge" pos="0 0 0" axis="0 1 0" stiffness="800" damping="80" armature="0.02" range="-180.0000 180.0000"/>
        <joint name="R_Hip_z" type="hinge" pos="0 0 0" axis="0 0 1" stiffness="800" damping="80" armature="0.02" range="-180.0000 180.0000"/>
        <geom type="capsule" contype="1" conaffinity="1" density="500" fromto="-0.0014 -0.0100 -0.0762 -0.0056 -0.0398 -0.3048" size="0.0562" name="R_Hip"/>
        <body name="R_Knee" pos="-0.007 -0.0498 -0.381">
          <joint name="R_Knee_x" type="hinge" pos="0 0 0" axis="1 0 0" stiffness="800" damping="80" armature="0.02" range="-180.0000 180.0000"/>
          <joint name="R_Knee_y" type="hinge" pos="0 0 0" axis="0 1 0" stiffness="800" damping="80" armature="0.02" range="-180.0000 180.0000"/>
          <joint name="R_Knee_z" type="hinge" pos="0 0 0" axis="0 0 1" stiffness="800" damping="80" armature="0.02" range="-180.0000 180.0000"/>
          <geom type="capsule" contype="1" conaffinity="1" density="500" fromto="-0.0069 0.0031 -0.0892 -0.0275 0.0123 -0.3570" size="0.051" name="R_Knee"/>
          <body name="R_Ankle" pos="-0.0343 0.0154 -0.4462">
            <joint name="R_Ankle_x" type="hinge" pos="0 0 0" axis="1 0 0" stiffness="800" damping="80" armature="0.02" range="-180.0000 180.0000"/>
            <joint name="R_Ankle_y" type="hinge" pos="0 0 0" axis="0 1 0" stiffness="800" damping="80" armature="0.02" range="-180.0000 180.0000"/>
            <joint name="R_Ankle_z" type="hinge" pos="0 0 0" axis="0 0 1" stiffness="800" damping="80" armature="0.02" range="-180.0000 180.0000"/>
            <geom type="box" contype="1" conaffinity="1" density="500" pos="0.0699 -0.0166 -0.0303" size="0.0917 0.0499 0.0252" quat="0.9932 0.0000 0.0000 -0.1162" name="R_Ankle"/>
            <body name="R_Toe" pos="0.1399 -0.0332 -0.0606">
              <joint name="R_Toe_x" type="hinge" pos="0 0 0" axis="1 0 0" stiffness="500" damping="50" armature="0.02" range="-180.0000 180.0000"/>
              <joint name="R_Toe_y" type="hinge" pos="0 0 0" axis="0 1 0" stiffness="500" damping="50" armature="0.02" range="-180.0000 180.0000"/>
              <joint name="R_Toe_z" type="hinge" pos="0 0 0" axis="0 0 1" stiffness="500" damping="50" armature="0.02" range="-180.0000 180.0000"/>
              <geom type="box" contype="1" conaffinity="1" density="500" pos="0.0000 0.0000 0.0264" size="0.001 0.0024 0.0011" quat="0.9942 0.0000 0.0000 -0.1079" name="R_Toe"/>
            </body>
          </body>
        </body>
      </body>
      <body name="Torso" pos="-0.0441 -0.0004 0.1087">
        <joint name="Torso_x" type="hinge" pos="0 0 0" axis="1 0 0" stiffness="1000" damping="100" armature="0.02" range="-180.0000 180.0000"/>
        <joint name="Torso_y" type="hinge" pos="0 0 0" axis="0 1 0" stiffness="1000" damping="100" armature="0.02" range="-180.0000 180.0000"/>
        <joint name="Torso_z" type="hinge" pos="0 0 0" axis="0 0 1" stiffness="1000" damping="100" armature="0.02" range="-180.0000 180.0000"/>
        <geom type="capsule" contype="1" conaffinity="1" density="500" fromto="-0.0003 0.0061 0.0838 -0.0002 0.0040 0.0558" size="0.0737" name="Torso"/>
        <body name="Spine" pos="-0.0005 0.0101 0.1396">
          <joint name="Spine_x" type="hinge" pos="0 0 0" axis="1 0 0" stiffness="1000" damping="100" armature="0.02" range="-180.0000 180.0000"/>
          <joint name="Spine_y" type="hinge" pos="0 0 0" axis="0 1 0" stiffness="1000" damping="100" armature="0.02" range="-180.0000 180.0000"/>
          <joint name="Spine_z" type="hinge" pos="0 0 0" axis="0 0 1" stiffness="1000" damping="100" armature="0.02" range="-180.0000 180.0000"/>
          <geom type="capsule" contype="1" conaffinity="1" density="500" fromto="0.0116 -0.0059 0.0320 0.0077 -0.0039 0.0213" size="0.0898" name="Spine"/>
          <body name="Chest" pos="0.0193 -0.0098 0.0533">
            <joint name="Chest_x" type="hinge" pos="0 0 0" axis="1 0 0" stiffness="1000" damping="100" armature="0.02" range="-180.0000 180.0000"/>
            <joint name="Chest_y" type="hinge" pos="0 0 0" axis="0 1 0" stiffness="1000" damping="100" armature="0.02" range="-180.0000 180.0000"/>
            <joint name="Chest_z" type="hinge" pos="0 0 0" axis="0 0 1" stiffness="1000" damping="100" armature="0.02" range="-180.0000 180.0000"/>
            <geom type="capsule" contype="1" conaffinity="1" density="500" fromto="-0.0105 -0.0029 0.0607 -0.0070 -0.0019 0.0405" size="0.1066" name="Chest"/>
            <body name="Neck" pos="-0.0311 -0.0102 0.1579">
              <joint name="Neck_x" type="hinge" pos="0 0 0" axis="1 0 0" stiffness="500" damping="50" armature="0.02" range="-180.0000 180.0000"/>
              <joint name="Neck_y" type="hinge" pos="0 0 0" axis="0 1 0" stiffness="500" damping="50" armature="0.02" range="-180.0000 180.0000"/>
              <joint name="Neck_z" type="hinge" pos="0 0 0" axis="0 0 1" stiffness="500" damping="50" armature="0.02" range="-180.0000 180.0000"/>
              <geom type="capsule" contype="1" conaffinity="1" density="500" fromto="0.0050 0.0046 0.0277 0.0199 0.0184 0.1108" size="0.0428" name="Neck"/>
              <body name="Head" pos="0.0248 0.023 0.1385">
                <joint name="Head_x" type="hinge" pos="0 0 0" axis="1 0 0" stiffness="500" damping="50" armature="0.02" range="-180.0000 180.0000"/>
                <joint name="Head_y" type="hinge" pos="0 0 0" axis="0 1 0" stiffness="500" damping="50" armature="0.02" range="-180.0000 180.0000"/>
                <joint name="Head_z" type="hinge" pos="0 0 0" axis="0 0 1" stiffness="500" damping="50" armature="0.02" range="-180.0000 180.0000"/>
                <geom type="sphere" contype="1" conaffinity="1" density="500" size="0.1017" pos="0.0000 0.0000 0.0000" name="Head"/>
              </body>
            </body>
            <body name="L_Thorax" pos="-0.0089 0.0438 0.0725">
              <joint name="L_Thorax_x" type="hinge" pos="0 0 0" axis="1 0 0" stiffness="500" damping="50" armature="0.02" range="-180.0000 180.0000"/>
              <joint name="L_Thorax_y" type="hinge" pos="0 0 0" axis="0 1 0" stiffness="500" damping="50" armature="0.02" range="-180.0000 180.0000"/>
              <joint name="L_Thorax_z" type="hinge" pos="0 0 0" axis="0 0 1" stiffness="500" damping="50" armature="0.02" range="-180.0000 180.0000"/>
              <geom type="capsule" contype="1" conaffinity="1" density="500" fromto="-0.0029 0.0294 0.0125 -0.0118 0.1175 0.0500" size="0.0498" name="L_Thorax"/>
              <body name="L_Shoulder" pos="-0.0147 0.1468 0.0626">
                <joint name="L_Shoulder_x" type="hinge" pos="0 0 0" axis="1 0 0" stiffness="500" damping="50" armature="0.02" range="-180.0000 180.0000"/>
                <joint name="L_Shoulder_y" type="hinge" pos="0 0 0" axis="0 1 0" stiffness="500" damping="50" armature="0.02" range="-180.0000 180.0000"/>
                <joint name="L_Shoulder_z" type="hinge" pos="0 0 0" axis="0 0 1" stiffness="500" damping="50" armature="0.02" range="-180.0000 180.0000"/>
                <geom type="capsule" contype="1" conaffinity="1" density="500" fromto="-0.0091 0.0519 -0.0147 -0.0365 0.2075 -0.0590" size="0.0548" name="L_Shoulder"/>
                <body name="L_Elbow" pos="-0.0456 0.2594 -0.0737">
                  <joint name="L_Elbow_x" type="hinge" pos="0 0 0" axis="1 0 0" stiffness="500" damping="50" armature="0.02" range="-720.0000 720.0000"/>
                  <joint name="L_Elbow_y" type="hinge" pos="0 0 0" axis="0 1 0" stiffness="500" damping="50" armature="0.02" range="-720.0000 720.0000"/>
                  <joint name="L_Elbow_z" type="hinge" pos="0 0 0" axis="0 0 1" stiffness="500" damping="50" armature="0.02" range="-720.0000 720.0000"/>
                  <geom type="capsule" contype="1" conaffinity="1" density="500" fromto="-0.0003 0.0553 0.0050 -0.0011 0.2214 0.0199" size="0.0409" name="L_Elbow"/>
                  <body name="L_Wrist" pos="-0.0014 0.2767 0.0249">
                    <joint name="L_Wrist_x" type="hinge" pos="0 0 0" axis="1 0 0" stiffness="300" damping="30" armature="0.02" range="-180.0000 180.0000"/>
                    <joint name="L_Wrist_y" type="hinge" pos="0 0 0" axis="0 1 0" stiffness="300" damping="30" armature="0.02" range="-180.0000 180.0000"/>
                    <joint name="L_Wrist_z" type="hinge" pos="0 0 0" axis="0 0 1" stiffness="300" damping="30" armature="0.02" range="-180.0000 180.0000"/>
                    <geom type="box" contype="1" conaffinity="1" density="500" pos="-0.0027 0.0456 -0.0052" size="0.0415 0.0455 0.0078" quat="0.7275 0.0000 0.0000 -0.6861" name="L_Wrist"/>
                    <body name="L_Index1" pos="0.0212 0.1069 -0.0072">
                      <joint name="L_Index1_x" type="hinge" pos="0 0 0" axis="1 0 0" stiffness="100" damping="10" armature="0.02" range="-180.0000 180.0000"/>
                      <joint name="L_Index1_y" type="hinge" pos="0 0 0" axis="0 1 0" stiffness="100" damping="10" armature="0.02" range="-180.0000 180.0000"/>
                      <joint name="L_Index1_z" type="hinge" pos="0 0 0" axis="0 0 1" stiffness="100" damping="10" armature="0.02" range="-180.0000 180.0000"/>
                      <geom type="capsule" contype="1" conaffinity="1" density="500" fromto="0.0007 0.0066 0.0003 0.0029 0.0266 0.0012" size="0.0095" name="L_Index1"/>
                      <body name="L_Index2" pos="0.0036 0.0332 0.0015">
                        <joint name="L_Index2_x" type="hinge" pos="0 0 0" axis="1 0 0" stiffness="100" damping="10" armature="0.02" range="-180.0000 180.0000"/>
                        <joint name="L_Index2_y" type="hinge" pos="0 0 0" axis="0 1 0" stiffness="100" damping="10" armature="0.02" range="-180.0000 180.0000"/>
                        <joint name="L_Index2_z" type="hinge" pos="0 0 0" axis="0 0 1" stiffness="100" damping="10" armature="0.02" range="-180.0000 180.0000"/>
                        <geom type="capsule" contype="1" conaffinity="1" density="500" fromto="-0.0001 0.0047 -0.0005 -0.0002 0.0188 -0.0022" size="0.0078" name="L_Index2"/>
                        <body name="L_Index3" pos="-0.0003 0.0234 -0.0027">
                          <joint name="L_Index3_x" type="hinge" pos="0 0 0" axis="1 0 0" stiffness="100" damping="10" armature="0.02" range="-180.0000 180.0000"/>
                          <joint name="L_Index3_y" type="hinge" pos="0 0 0" axis="0 1 0" stiffness="100" damping="10" armature="0.02" range="-180.0000 180.0000"/>
                          <joint name="L_Index3_z" type="hinge" pos="0 0 0" axis="0 0 1" stiffness="100" damping="10" armature="0.02" range="-180.0000 180.0000"/>
                          <geom type="capsule" contype="1" conaffinity="1" density="500" fromto="0.0003 0.0051 -0.0001 0.0014 0.0204 -0.0006" size="0.0067" name="L_Index3"/>
                        </body>
                      </body>
                    </body>
                    <body name="L_Middle1" pos="-0.0032 0.115 -0.0049">
                      <joint name="L_Middle1_x" type="hinge" pos="0 0 0" axis="1 0 0" stiffness="100" damping="10" armature="0.02" range="-180.0000 180.0000"/>
                      <joint name="L_Middle1_y" type="hinge" pos="0 0 0" axis="0 1 0" stiffness="100" damping="10" armature="0.02" range="-180.0000 180.0000"/>
                      <joint name="L_Middle1_z" type="hinge" pos="0 0 0" axis="0 0 1" stiffness="100" damping="10" armature="0.02" range="-180.0000 180.0000"/>
                      <geom type="capsule" contype="1" conaffinity="1" density="500" fromto="-0.0009 0.0064 0.0001 -0.0035 0.0255 0.0002" size="0.0097" name="L_Middle1"/>
                      <body name="L_Middle2" pos="-0.0044 0.0319 0.0003">
                        <joint name="L_Middle2_x" type="hinge" pos="0 0 0" axis="1 0 0" stiffness="100" damping="10" armature="0.02" range="-180.0000 180.0000"/>
                        <joint name="L_Middle2_y" type="hinge" pos="0 0 0" axis="0 1 0" stiffness="100" damping="10" armature="0.02" range="-180.0000 180.0000"/>
                        <joint name="L_Middle2_z" type="hinge" pos="0 0 0" axis="0 0 1" stiffness="100" damping="10" armature="0.02" range="-180.0000 180.0000"/>
                        <geom type="capsule" contype="1" conaffinity="1" density="500" fromto="-0.0009 0.0049 -0.0005 -0.0036 0.0195 -0.0021" size="0.0072" name="L_Middle2"/>
                        <body name="L_Middle3" pos="-0.0045 0.0244 -0.0027">
                          <joint name="L_Middle3_x" type="hinge" pos="0 0 0" axis="1 0 0" stiffness="100" damping="10" armature="0.02" range="-180.0000 180.0000"/>
                          <joint name="L_Middle3_y" type="hinge" pos="0 0 0" axis="0 1 0" stiffness="100" damping="10" armature="0.02" range="-180.0000 180.0000"/>
                          <joint name="L_Middle3_z" type="hinge" pos="0 0 0" axis="0 0 1" stiffness="100" damping="10" armature="0.02" range="-180.0000 180.0000"/>
                          <geom type="capsule" contype="1" conaffinity="1" density="500" fromto="-0.0005 0.0053 -0.0001 -0.0020 0.0211 -0.0005" size="0.0064" name="L_Middle3"/>
                        </body>
                      </body>
                    </body>
                    <body name="L_Pinky1" pos="-0.0446 0.0889 -0.0136">
                      <joint name="L_Pinky1_x" type="hinge" pos="0 0 0" axis="1 0 0" stiffness="100" damping="10" armature="0.02" range="-180.0000 180.0000"/>
                      <joint name="L_Pinky1_y" type="hinge" pos="0 0 0" axis="0 1 0" stiffness="100" damping="10" armature="0.02" range="-180.0000 180.0000"/>
                      <joint name="L_Pinky1_z" type="hinge" pos="0 0 0" axis="0 0 1" stiffness="100" damping="10" armature="0.02" range="-180.0000 180.0000"/>
                      <geom type="capsule" contype="1" conaffinity="1" density="500" fromto="-0.0025 0.0034 -0.0003 -0.0098 0.0136 -0.0013" size="0.007" name="L_Pinky1"/>
                      <body name="L_Pinky2" pos="-0.0123 0.017 -0.0016">
                        <joint name="L_Pinky2_x" type="hinge" pos="0 0 0" axis="1 0 0" stiffness="100" damping="10" armature="0.02" range="-180.0000 180.0000"/>
                        <joint name="L_Pinky2_y" type="hinge" pos="0 0 0" axis="0 1 0" stiffness="100" damping="10" armature="0.02" range="-180.0000 180.0000"/>
                        <joint name="L_Pinky2_z" type="hinge" pos="0 0 0" axis="0 0 1" stiffness="100" damping="10" armature="0.02" range="-180.0000 180.0000"/>
                        <geom type="capsule" contype="1" conaffinity="1" density="500" fromto="-0.0023 0.0033 -0.0004 -0.0091 0.0132 -0.0016" size="0.0067" name="L_Pinky2"/>
                        <body name="L_Pinky3" pos="-0.0114 0.0165 -0.002">
                          <joint name="L_Pinky3_x" type="hinge" pos="0 0 0" axis="1 0 0" stiffness="100" damping="10" armature="0.02" range="-180.0000 180.0000"/>
                          <joint name="L_Pinky3_y" type="hinge" pos="0 0 0" axis="0 1 0" stiffness="100" damping="10" armature="0.02" range="-180.0000 180.0000"/>
                          <joint name="L_Pinky3_z" type="hinge" pos="0 0 0" axis="0 0 1" stiffness="100" damping="10" armature="0.02" range="-180.0000 180.0000"/>
                          <geom type="capsule" contype="1" conaffinity="1" density="500" fromto="-0.0019 0.0037 -0.0000 -0.0075 0.0148 -0.0000" size="0.0051" name="L_Pinky3"/>
                        </body>
                      </body>
                    </body>
                    <body name="L_Ring1" pos="-0.0274 0.1027 -0.0081">
                      <joint name="L_Ring1_x" type="hinge" pos="0 0 0" axis="1 0 0" stiffness="100" damping="10" armature="0.02" range="-180.0000 180.0000"/>
                      <joint name="L_Ring1_y" type="hinge" pos="0 0 0" axis="0 1 0" stiffness="100" damping="10" armature="0.02" range="-180.0000 180.0000"/>
                      <joint name="L_Ring1_z" type="hinge" pos="0 0 0" axis="0 0 1" stiffness="100" damping="10" armature="0.02" range="-180.0000 180.0000"/>
                      <geom type="capsule" contype="1" conaffinity="1" density="500" fromto="-0.0010 0.0059 0.0001 -0.0042 0.0236 0.0003" size="0.0082" name="L_Ring1"/>
                      <body name="L_Ring2" pos="-0.0052 0.0295 0.0003">
                        <joint name="L_Ring2_x" type="hinge" pos="0 0 0" axis="1 0 0" stiffness="100" damping="10" armature="0.02" range="-180.0000 180.0000"/>
                        <joint name="L_Ring2_y" type="hinge" pos="0 0 0" axis="0 1 0" stiffness="100" damping="10" armature="0.02" range="-180.0000 180.0000"/>
                        <joint name="L_Ring2_z" type="hinge" pos="0 0 0" axis="0 0 1" stiffness="100" damping="10" armature="0.02" range="-180.0000 180.0000"/>
                        <geom type="capsule" contype="1" conaffinity="1" density="500" fromto="-0.0014 0.0048 -0.0005 -0.0055 0.0191 -0.0020" size="0.0077" name="L_Ring2"/>
                        <body name="L_Ring3" pos="-0.0069 0.0239 -0.0025">
                          <joint name="L_Ring3_x" type="hinge" pos="0 0 0" axis="1 0 0" stiffness="100" damping="10" armature="0.02" range="-180.0000 180.0000"/>
                          <joint name="L_Ring3_y" type="hinge" pos="0 0 0" axis="0 1 0" stiffness="100" damping="10" armature="0.02" range="-180.0000 180.0000"/>
                          <joint name="L_Ring3_z" type="hinge" pos="0 0 0" axis="0 0 1" stiffness="100" damping="10" armature="0.02" range="-180.0000 180.0000"/>
                          <geom type="capsule" contype="1" conaffinity="1" density="500" fromto="-0.0010 0.0052 -0.0001 -0.0039 0.0207 -0.0004" size="0.006" name="L_Ring3"/>
                        </body>
                      </body>
                    </body>
                    <body name="L_Thumb1" pos="0.0273 0.0429 -0.0185">
                      <joint name="L_Thumb1_x" type="hinge" pos="0 0 0" axis="1 0 0" stiffness="100" damping="10" armature="0.02" range="-180.0000 180.0000"/>
                      <joint name="L_Thumb1_y" type="hinge" pos="0 0 0" axis="0 1 0" stiffness="100" damping="10" armature="0.02" range="-180.0000 180.0000"/>
                      <joint name="L_Thumb1_z" type="hinge" pos="0 0 0" axis="0 0 1" stiffness="100" damping="10" armature="0.02" range="-180.0000 180.0000"/>
                      <geom type="capsule" contype="1" conaffinity="1" density="500" fromto="0.0054 0.0034 0.0003 0.0215 0.0138 0.0013" size="0.0124" name="L_Thumb1"/>
                      <body name="L_Thumb2" pos="0.0269 0.0172 0.0016">
                        <joint name="L_Thumb2_x" type="hinge" pos="0 0 0" axis="1 0 0" stiffness="100" damping="10" armature="0.02" range="-180.0000 180.0000"/>
                        <joint name="L_Thumb2_y" type="hinge" pos="0 0 0" axis="0 1 0" stiffness="100" damping="10" armature="0.02" range="-180.0000 180.0000"/>
                        <joint name="L_Thumb2_z" type="hinge" pos="0 0 0" axis="0 0 1" stiffness="100" damping="10" armature="0.02" range="-180.0000 180.0000"/>
                        <geom type="capsule" contype="1" conaffinity="1" density="500" fromto="0.0034 0.0041 -0.0010 0.0137 0.0164 -0.0041" size="0.01" name="L_Thumb2"/>
                        <body name="L_Thumb3" pos="0.0171 0.0205 -0.0051">
                          <joint name="L_Thumb3_x" type="hinge" pos="0 0 0" axis="1 0 0" stiffness="100" damping="10" armature="0.02" range="-180.0000 180.0000"/>
                          <joint name="L_Thumb3_y" type="hinge" pos="0 0 0" axis="0 1 0" stiffness="100" damping="10" armature="0.02" range="-180.0000 180.0000"/>
                          <joint name="L_Thumb3_z" type="hinge" pos="0 0 0" axis="0 0 1" stiffness="100" damping="10" armature="0.02" range="-180.0000 180.0000"/>
                          <geom type="capsule" contype="1" conaffinity="1" density="500" fromto="0.0038 0.0045 -0.0006 0.0153 0.0180 -0.0025" size="0.0093" name="L_Thumb3"/>
                        </body>
                      </body>
                    </body>
                  </body>
                </body>
              </body>
            </body>
            <body name="R_Thorax" pos="-0.0125 -0.0481 0.0731">
              <joint name="R_Thorax_x" type="hinge" pos="0 0 0" axis="1 0 0" stiffness="500" damping="50" armature="0.02" range="-180.0000 180.0000"/>
              <joint name="R_Thorax_y" type="hinge" pos="0 0 0" axis="0 1 0" stiffness="500" damping="50" armature="0.02" range="-180.0000 180.0000"/>
              <joint name="R_Thorax_z" type="hinge" pos="0 0 0" axis="0 0 1" stiffness="500" damping="50" armature="0.02" range="-180.0000 180.0000"/>
              <geom type="capsule" contype="1" conaffinity="1" density="500" fromto="-0.0024 -0.0271 0.0120 -0.0096 -0.1083 0.0480" size="0.0587" name="R_Thorax"/>
              <body name="R_Shoulder" pos="-0.012 -0.1354 0.06">
                <joint name="R_Shoulder_x" type="hinge" pos="0 0 0" axis="1 0 0" stiffness="500" damping="50" armature="0.02" range="-180.0000 180.0000"/>
                <joint name="R_Shoulder_y" type="hinge" pos="0 0 0" axis="0 1 0" stiffness="500" damping="50" armature="0.02" range="-180.0000 180.0000"/>
                <joint name="R_Shoulder_z" type="hinge" pos="0 0 0" axis="0 0 1" stiffness="500" damping="50" armature="0.02" range="-180.0000 180.0000"/>
                <geom type="capsule" contype="1" conaffinity="1" density="500" fromto="-0.0066 -0.0557 -0.0088 -0.0264 -0.2227 -0.0351" size="0.0539" name="R_Shoulder"/>
                <body name="R_Elbow" pos="-0.0329 -0.2783 -0.0439">
                  <joint name="R_Elbow_x" type="hinge" pos="0 0 0" axis="1 0 0" stiffness="500" damping="50" armature="0.02" range="-720.0000 720.0000"/>
                  <joint name="R_Elbow_y" type="hinge" pos="0 0 0" axis="0 1 0" stiffness="500" damping="50" armature="0.02" range="-720.0000 720.0000"/>
                  <joint name="R_Elbow_z" type="hinge" pos="0 0 0" axis="0 0 1" stiffness="500" damping="50" armature="0.02" range="-720.0000 720.0000"/>
                  <geom type="capsule" contype="1" conaffinity="1" density="500" fromto="-0.0024 -0.0536 0.0001 -0.0097 -0.2145 0.0005" size="0.0419" name="R_Elbow"/>
                  <body name="R_Wrist" pos="-0.0121 -0.2681 0.0007">
                    <joint name="R_Wrist_x" type="hinge" pos="0 0 0" axis="1 0 0" stiffness="300" damping="30" armature="0.02" range="-180.0000 180.0000"/>
                    <joint name="R_Wrist_y" type="hinge" pos="0 0 0" axis="0 1 0" stiffness="300" damping="30" armature="0.02" range="-180.0000 180.0000"/>
                    <joint name="R_Wrist_z" type="hinge" pos="0 0 0" axis="0 0 1" stiffness="300" damping="30" armature="0.02" range="-180.0000 180.0000"/>
                    <geom type="box" contype="1" conaffinity="1" density="500" pos="-0.0032 -0.0454 -0.0070" size="0.0415 0.0468 0.0079" quat="0.7315 0.0000 0.0000 0.6818" name="R_Wrist"/>
                    <body name="R_Index1" pos="0.0202 -0.1064 -0.0108">
                      <joint name="R_Index1_x" type="hinge" pos="0 0 0" axis="1 0 0" stiffness="100" damping="10" armature="0.02" range="-180.0000 180.0000"/>
                      <joint name="R_Index1_y" type="hinge" pos="0 0 0" axis="0 1 0" stiffness="100" damping="10" armature="0.02" range="-180.0000 180.0000"/>
                      <joint name="R_Index1_z" type="hinge" pos="0 0 0" axis="0 0 1" stiffness="100" damping="10" armature="0.02" range="-180.0000 180.0000"/>
                      <geom type="capsule" contype="1" conaffinity="1" density="500" fromto="0.0007 -0.0066 0.0003 0.0029 -0.0266 0.0012" size="0.0095" name="R_Index1"/>
                      <body name="R_Index2" pos="0.0036 -0.0332 0.0015">
                        <joint name="R_Index2_x" type="hinge" pos="0 0 0" axis="1 0 0" stiffness="100" damping="10" armature="0.02" range="-180.0000 180.0000"/>
                        <joint name="R_Index2_y" type="hinge" pos="0 0 0" axis="0 1 0" stiffness="100" damping="10" armature="0.02" range="-180.0000 180.0000"/>
                        <joint name="R_Index2_z" type="hinge" pos="0 0 0" axis="0 0 1" stiffness="100" damping="10" armature="0.02" range="-180.0000 180.0000"/>
                        <geom type="capsule" contype="1" conaffinity="1" density="500" fromto="-0.0001 -0.0047 -0.0005 -0.0002 -0.0188 -0.0022" size="0.0078" name="R_Index2"/>
                        <body name="R_Index3" pos="-0.0003 -0.0234 -0.0027">
                          <joint name="R_Index3_x" type="hinge" pos="0 0 0" axis="1 0 0" stiffness="100" damping="10" armature="0.02" range="-180.0000 180.0000"/>
                          <joint name="R_Index3_y" type="hinge" pos="0 0 0" axis="0 1 0" stiffness="100" damping="10" armature="0.02" range="-180.0000 180.0000"/>
                          <joint name="R_Index3_z" type="hinge" pos="0 0 0" axis="0 0 1" stiffness="100" damping="10" armature="0.02" range="-180.0000 180.0000"/>
                          <geom type="capsule" contype="1" conaffinity="1" density="500" fromto="0.0003 -0.0043 -0.0001 0.0014 -0.0172 -0.0006" size="0.007" name="R_Index3"/>
                        </body>
                      </body>
                    </body>
                    <body name="R_Middle1" pos="-0.0042 -0.1145 -0.0085">
                      <joint name="R_Middle1_x" type="hinge" pos="0 0 0" axis="1 0 0" stiffness="100" damping="10" armature="0.02" range="-180.0000 180.0000"/>
                      <joint name="R_Middle1_y" type="hinge" pos="0 0 0" axis="0 1 0" stiffness="100" damping="10" armature="0.02" range="-180.0000 180.0000"/>
                      <joint name="R_Middle1_z" type="hinge" pos="0 0 0" axis="0 0 1" stiffness="100" damping="10" armature="0.02" range="-180.0000 180.0000"/>
                      <geom type="capsule" contype="1" conaffinity="1" density="500" fromto="-0.0009 -0.0064 0.0001 -0.0035 -0.0255 0.0002" size="0.0097" name="R_Middle1"/>
                      <body name="R_Middle2" pos="-0.0044 -0.0319 0.0003">
                        <joint name="R_Middle2_x" type="hinge" pos="0 0 0" axis="1 0 0" stiffness="100" damping="10" armature="0.02" range="-180.0000 180.0000"/>
                        <joint name="R_Middle2_y" type="hinge" pos="0 0 0" axis="0 1 0" stiffness="100" damping="10" armature="0.02" range="-180.0000 180.0000"/>
                        <joint name="R_Middle2_z" type="hinge" pos="0 0 0" axis="0 0 1" stiffness="100" damping="10" armature="0.02" range="-180.0000 180.0000"/>
                        <geom type="capsule" contype="1" conaffinity="1" density="500" fromto="-0.0009 -0.0049 -0.0005 -0.0036 -0.0195 -0.0021" size="0.0072" name="R_Middle2"/>
                        <body name="R_Middle3" pos="-0.0045 -0.0244 -0.0027">
                          <joint name="R_Middle3_x" type="hinge" pos="0 0 0" axis="1 0 0" stiffness="100" damping="10" armature="0.02" range="-180.0000 180.0000"/>
                          <joint name="R_Middle3_y" type="hinge" pos="0 0 0" axis="0 1 0" stiffness="100" damping="10" armature="0.02" range="-180.0000 180.0000"/>
                          <joint name="R_Middle3_z" type="hinge" pos="0 0 0" axis="0 0 1" stiffness="100" damping="10" armature="0.02" range="-180.0000 180.0000"/>
                          <geom type="capsule" contype="1" conaffinity="1" density="500" fromto="-0.0005 -0.0045 -0.0001 -0.0020 -0.0179 -0.0005" size="0.0067" name="R_Middle3"/>
                        </body>
                      </body>
                    </body>
                    <body name="R_Pinky1" pos="-0.0457 -0.0885 -0.0172">
                      <joint name="R_Pinky1_x" type="hinge" pos="0 0 0" axis="1 0 0" stiffness="100" damping="10" armature="0.02" range="-180.0000 180.0000"/>
                      <joint name="R_Pinky1_y" type="hinge" pos="0 0 0" axis="0 1 0" stiffness="100" damping="10" armature="0.02" range="-180.0000 180.0000"/>
                      <joint name="R_Pinky1_z" type="hinge" pos="0 0 0" axis="0 0 1" stiffness="100" damping="10" armature="0.02" range="-180.0000 180.0000"/>
                      <geom type="capsule" contype="1" conaffinity="1" density="500" fromto="-0.0025 -0.0034 -0.0003 -0.0098 -0.0136 -0.0013" size="0.007" name="R_Pinky1"/>
                      <body name="R_Pinky2" pos="-0.0123 -0.017 -0.0016">
                        <joint name="R_Pinky2_x" type="hinge" pos="0 0 0" axis="1 0 0" stiffness="100" damping="10" armature="0.02" range="-180.0000 180.0000"/>
                        <joint name="R_Pinky2_y" type="hinge" pos="0 0 0" axis="0 1 0" stiffness="100" damping="10" armature="0.02" range="-180.0000 180.0000"/>
                        <joint name="R_Pinky2_z" type="hinge" pos="0 0 0" axis="0 0 1" stiffness="100" damping="10" armature="0.02" range="-180.0000 180.0000"/>
                        <geom type="capsule" contype="1" conaffinity="1" density="500" fromto="-0.0023 -0.0033 -0.0004 -0.0091 -0.0132 -0.0016" size="0.0067" name="R_Pinky2"/>
                        <body name="R_Pinky3" pos="-0.0114 -0.0165 -0.002">
                          <joint name="R_Pinky3_x" type="hinge" pos="0 0 0" axis="1 0 0" stiffness="100" damping="10" armature="0.02" range="-180.0000 180.0000"/>
                          <joint name="R_Pinky3_y" type="hinge" pos="0 0 0" axis="0 1 0" stiffness="100" damping="10" armature="0.02" range="-180.0000 180.0000"/>
                          <joint name="R_Pinky3_z" type="hinge" pos="0 0 0" axis="0 0 1" stiffness="100" damping="10" armature="0.02" range="-180.0000 180.0000"/>
                          <geom type="capsule" contype="1" conaffinity="1" density="500" fromto="-0.0019 -0.0029 -0.0000 -0.0075 -0.0116 -0.0000" size="0.0053" name="R_Pinky3"/>
                        </body>
                      </body>
                    </body>
                    <body name="R_Ring1" pos="-0.0285 -0.1022 -0.0117">
                      <joint name="R_Ring1_x" type="hinge" pos="0 0 0" axis="1 0 0" stiffness="100" damping="10" armature="0.02" range="-180.0000 180.0000"/>
                      <joint name="R_Ring1_y" type="hinge" pos="0 0 0" axis="0 1 0" stiffness="100" damping="10" armature="0.02" range="-180.0000 180.0000"/>
                      <joint name="R_Ring1_z" type="hinge" pos="0 0 0" axis="0 0 1" stiffness="100" damping="10" armature="0.02" range="-180.0000 180.0000"/>
                      <geom type="capsule" contype="1" conaffinity="1" density="500" fromto="-0.0010 -0.0059 0.0001 -0.0042 -0.0236 0.0003" size="0.0082" name="R_Ring1"/>
                      <body name="R_Ring2" pos="-0.0052 -0.0295 0.0003">
                        <joint name="R_Ring2_x" type="hinge" pos="0 0 0" axis="1 0 0" stiffness="100" damping="10" armature="0.02" range="-180.0000 180.0000"/>
                        <joint name="R_Ring2_y" type="hinge" pos="0 0 0" axis="0 1 0" stiffness="100" damping="10" armature="0.02" range="-180.0000 180.0000"/>
                        <joint name="R_Ring2_z" type="hinge" pos="0 0 0" axis="0 0 1" stiffness="100" damping="10" armature="0.02" range="-180.0000 180.0000"/>
                        <geom type="capsule" contype="1" conaffinity="1" density="500" fromto="-0.0014 -0.0048 -0.0005 -0.0055 -0.0191 -0.0020" size="0.0077" name="R_Ring2"/>
                        <body name="R_Ring3" pos="-0.0069 -0.0239 -0.0025">
                          <joint name="R_Ring3_x" type="hinge" pos="0 0 0" axis="1 0 0" stiffness="100" damping="10" armature="0.02" range="-180.0000 180.0000"/>
                          <joint name="R_Ring3_y" type="hinge" pos="0 0 0" axis="0 1 0" stiffness="100" damping="10" armature="0.02" range="-180.0000 180.0000"/>
                          <joint name="R_Ring3_z" type="hinge" pos="0 0 0" axis="0 0 1" stiffness="100" damping="10" armature="0.02" range="-180.0000 180.0000"/>
                          <geom type="capsule" contype="1" conaffinity="1" density="500" fromto="-0.0010 -0.0044 -0.0001 -0.0039 -0.0175 -0.0004" size="0.0063" name="R_Ring3"/>
                        </body>
                      </body>
                    </body>
                    <body name="R_Thumb1" pos="0.0263 -0.0424 -0.0221">
                      <joint name="R_Thumb1_x" type="hinge" pos="0 0 0" axis="1 0 0" stiffness="100" damping="10" armature="0.02" range="-180.0000 180.0000"/>
                      <joint name="R_Thumb1_y" type="hinge" pos="0 0 0" axis="0 1 0" stiffness="100" damping="10" armature="0.02" range="-180.0000 180.0000"/>
                      <joint name="R_Thumb1_z" type="hinge" pos="0 0 0" axis="0 0 1" stiffness="100" damping="10" armature="0.02" range="-180.0000 180.0000"/>
                      <geom type="capsule" contype="1" conaffinity="1" density="500" fromto="0.0054 -0.0034 0.0003 0.0215 -0.0138 0.0013" size="0.0124" name="R_Thumb1"/>
                      <body name="R_Thumb2" pos="0.0269 -0.0172 0.0016">
                        <joint name="R_Thumb2_x" type="hinge" pos="0 0 0" axis="1 0 0" stiffness="100" damping="10" armature="0.02" range="-180.0000 180.0000"/>
                        <joint name="R_Thumb2_y" type="hinge" pos="0 0 0" axis="0 1 0" stiffness="100" damping="10" armature="0.02" range="-180.0000 180.0000"/>
                        <joint name="R_Thumb2_z" type="hinge" pos="0 0 0" axis="0 0 1" stiffness="100" damping="10" armature="0.02" range="-180.0000 180.0000"/>
                        <geom type="capsule" contype="1" conaffinity="1" density="500" fromto="0.0034 -0.0041 -0.0010 0.0137 -0.0164 -0.0041" size="0.01" name="R_Thumb2"/>
                        <body name="R_Thumb3" pos="0.0171 -0.0205 -0.0051">
                          <joint name="R_Thumb3_x" type="hinge" pos="0 0 0" axis="1 0 0" stiffness="100" damping="10" armature="0.02" range="-180.0000 180.0000"/>
                          <joint name="R_Thumb3_y" type="hinge" pos="0 0 0" axis="0 1 0" stiffness="100" damping="10" armature="0.02" range="-180.0000 180.0000"/>
                          <joint name="R_Thumb3_z" type="hinge" pos="0 0 0" axis="0 0 1" stiffness="100" damping="10" armature="0.02" range="-180.0000 180.0000"/>
                          <geom type="capsule" contype="1" conaffinity="1" density="500" fromto="0.0038 -0.0037 -0.0006 0.0153 -0.0148 -0.0025" size="0.0095" name="R_Thumb3"/>
                        </body>
                      </body>
                    </body>
                  </body>
                </body>
              </body>
            </body>
          </body>
        </body>
      </body>
    </body>
  </worldbody>
  <actuator>
    <motor name="L_Hip_x" joint="L_Hip_x" gear="500"/>
    <motor name="L_Hip_y" joint="L_Hip_y" gear="500"/>
    <motor name="L_Hip_z" joint="L_Hip_z" gear="500"/>
    <motor name="L_Knee_x" joint="L_Knee_x" gear="500"/>
    <motor name="L_Knee_y" joint="L_Knee_y" gear="500"/>
    <motor name="L_Knee_z" joint="L_Knee_z" gear="500"/>
    <motor name="L_Ankle_x" joint="L_Ankle_x" gear="500"/>
    <motor name="L_Ankle_y" joint="L_Ankle_y" gear="500"/>
    <motor name="L_Ankle_z" joint="L_Ankle_z" gear="500"/>
    <motor name="L_Toe_x" joint="L_Toe_x" gear="500"/>
    <motor name="L_Toe_y" joint="L_Toe_y" gear="500"/>
    <motor name="L_Toe_z" joint="L_Toe_z" gear="500"/>
    <motor name="R_Hip_x" joint="R_Hip_x" gear="500"/>
    <motor name="R_Hip_y" joint="R_Hip_y" gear="500"/>
    <motor name="R_Hip_z" joint="R_Hip_z" gear="500"/>
    <motor name="R_Knee_x" joint="R_Knee_x" gear="500"/>
    <motor name="R_Knee_y" joint="R_Knee_y" gear="500"/>
    <motor name="R_Knee_z" joint="R_Knee_z" gear="500"/>
    <motor name="R_Ankle_x" joint="R_Ankle_x" gear="500"/>
    <motor name="R_Ankle_y" joint="R_Ankle_y" gear="500"/>
    <motor name="R_Ankle_z" joint="R_Ankle_z" gear="500"/>
    <motor name="R_Toe_x" joint="R_Toe_x" gear="500"/>
    <motor name="R_Toe_y" joint="R_Toe_y" gear="500"/>
    <motor name="R_Toe_z" joint="R_Toe_z" gear="500"/>
    <motor name="Torso_x" joint="Torso_x" gear="500"/>
    <motor name="Torso_y" joint="Torso_y" gear="500"/>
    <motor name="Torso_z" joint="Torso_z" gear="500"/>
    <motor name="Spine_x" joint="Spine_x" gear="500"/>
    <motor name="Spine_y" joint="Spine_y" gear="500"/>
    <motor name="Spine_z" joint="Spine_z" gear="500"/>
    <motor name="Chest_x" joint="Chest_x" gear="500"/>
    <motor name="Chest_y" joint="Chest_y" gear="500"/>
    <motor name="Chest_z" joint="Chest_z" gear="500"/>
    <motor name="Neck_x" joint="Neck_x" gear="500"/>
    <motor name="Neck_y" joint="Neck_y" gear="500"/>
    <motor name="Neck_z" joint="Neck_z" gear="500"/>
    <motor name="Head_x" joint="Head_x" gear="500"/>
    <motor name="Head_y" joint="Head_y" gear="500"/>
    <motor name="Head_z" joint="Head_z" gear="500"/>
    <motor name="L_Thorax_x" joint="L_Thorax_x" gear="500"/>
    <motor name="L_Thorax_y" joint="L_Thorax_y" gear="500"/>
    <motor name="L_Thorax_z" joint="L_Thorax_z" gear="500"/>
    <motor name="L_Shoulder_x" joint="L_Shoulder_x" gear="500"/>
    <motor name="L_Shoulder_y" joint="L_Shoulder_y" gear="500"/>
    <motor name="L_Shoulder_z" joint="L_Shoulder_z" gear="500"/>
    <motor name="L_Elbow_x" joint="L_Elbow_x" gear="500"/>
    <motor name="L_Elbow_y" joint="L_Elbow_y" gear="500"/>
    <motor name="L_Elbow_z" joint="L_Elbow_z" gear="500"/>
    <motor name="L_Wrist_x" joint="L_Wrist_x" gear="500"/>
    <motor name="L_Wrist_y" joint="L_Wrist_y" gear="500"/>
    <motor name="L_Wrist_z" joint="L_Wrist_z" gear="500"/>
    <motor name="L_Index1_x" joint="L_Index1_x" gear="500"/>
    <motor name="L_Index1_y" joint="L_Index1_y" gear="500"/>
    <motor name="L_Index1_z" joint="L_Index1_z" gear="500"/>
    <motor name="L_Index2_x" joint="L_Index2_x" gear="500"/>
    <motor name="L_Index2_y" joint="L_Index2_y" gear="500"/>
    <motor name="L_Index2_z" joint="L_Index2_z" gear="500"/>
    <motor name="L_Index3_x" joint="L_Index3_x" gear="500"/>
    <motor name="L_Index3_y" joint="L_Index3_y" gear="500"/>
    <motor name="L_Index3_z" joint="L_Index3_z" gear="500"/>
    <motor name="L_Middle1_x" joint="L_Middle1_x" gear="500"/>
    <motor name="L_Middle1_y" joint="L_Middle1_y" gear="500"/>
    <motor name="L_Middle1_z" joint="L_Middle1_z" gear="500"/>
    <motor name="L_Middle2_x" joint="L_Middle2_x" gear="500"/>
    <motor name="L_Middle2_y" joint="L_Middle2_y" gear="500"/>
    <motor name="L_Middle2_z" joint="L_Middle2_z" gear="500"/>
    <motor name="L_Middle3_x" joint="L_Middle3_x" gear="500"/>
    <motor name="L_Middle3_y" joint="L_Middle3_y" gear="500"/>
    <motor name="L_Middle3_z" joint="L_Middle3_z" gear="500"/>
    <motor name="L_Pinky1_x" joint="L_Pinky1_x" gear="500"/>
    <motor name="L_Pinky1_y" joint="L_Pinky1_y" gear="500"/>
    <motor name="L_Pinky1_z" joint="L_Pinky1_z" gear="500"/>
    <motor name="L_Pinky2_x" joint="L_Pinky2_x" gear="500"/>
    <motor name="L_Pinky2_y" joint="L_Pinky2_y" gear="500"/>
    <motor name="L_Pinky2_z" joint="L_Pinky2_z" gear="500"/>
    <motor name="L_Pinky3_x" joint="L_Pinky3_x" gear="500"/>
    <motor name="L_Pinky3_y" joint="L_Pinky3_y" gear="500"/>
    <motor name="L_Pinky3_z" joint="L_Pinky3_z" gear="500"/>
    <motor name="L_Ring1_x" joint="L_Ring1_x" gear="500"/>
    <motor name="L_Ring1_y" joint="L_Ring1_y" gear="500"/>
    <motor name="L_Ring1_z" joint="L_Ring1_z" gear="500"/>
    <motor name="L_Ring2_x" joint="L_Ring2_x" gear="500"/>
    <motor name="L_Ring2_y" joint="L_Ring2_y" gear="500"/>
    <motor name="L_Ring2_z" joint="L_Ring2_z" gear="500"/>
    <motor name="L_Ring3_x" joint="L_Ring3_x" gear="500"/>
    <motor name="L_Ring3_y" joint="L_Ring3_y" gear="500"/>
    <motor name="L_Ring3_z" joint="L_Ring3_z" gear="500"/>
    <motor name="L_Thumb1_x" joint="L_Thumb1_x" gear="500"/>
    <motor name="L_Thumb1_y" joint="L_Thumb1_y" gear="500"/>
    <motor name="L_Thumb1_z" joint="L_Thumb1_z" gear="500"/>
    <motor name="L_Thumb2_x" joint="L_Thumb2_x" gear="500"/>
    <motor name="L_Thumb2_y" joint="L_Thumb2_y" gear="500"/>
    <motor name="L_Thumb2_z" joint="L_Thumb2_z" gear="500"/>
    <motor name="L_Thumb3_x" joint="L_Thumb3_x" gear="500"/>
    <motor name="L_Thumb3_y" joint="L_Thumb3_y" gear="500"/>
    <motor name="L_Thumb3_z" joint="L_Thumb3_z" gear="500"/>
    <motor name="R_Thorax_x" joint="R_Thorax_x" gear="500"/>
    <motor name="R_Thorax_y" joint="R_Thorax_y" gear="500"/>
    <motor name="R_Thorax_z" joint="R_Thorax_z" gear="500"/>
    <motor name="R_Shoulder_x" joint="R_Shoulder_x" gear="500"/>
    <motor name="R_Shoulder_y" joint="R_Shoulder_y" gear="500"/>
    <motor name="R_Shoulder_z" joint="R_Shoulder_z" gear="500"/>
    <motor name="R_Elbow_x" joint="R_Elbow_x" gear="500"/>
    <motor name="R_Elbow_y" joint="R_Elbow_y" gear="500"/>
    <motor name="R_Elbow_z" joint="R_Elbow_z" gear="500"/>
    <motor name="R_Wrist_x" joint="R_Wrist_x" gear="500"/>
    <motor name="R_Wrist_y" joint="R_Wrist_y" gear="500"/>
    <motor name="R_Wrist_z" joint="R_Wrist_z" gear="500"/>
    <motor name="R_Index1_x" joint="R_Index1_x" gear="500"/>
    <motor name="R_Index1_y" joint="R_Index1_y" gear="500"/>
    <motor name="R_Index1_z" joint="R_Index1_z" gear="500"/>
    <motor name="R_Index2_x" joint="R_Index2_x" gear="500"/>
    <motor name="R_Index2_y" joint="R_Index2_y" gear="500"/>
    <motor name="R_Index2_z" joint="R_Index2_z" gear="500"/>
    <motor name="R_Index3_x" joint="R_Index3_x" gear="500"/>
    <motor name="R_Index3_y" joint="R_Index3_y" gear="500"/>
    <motor name="R_Index3_z" joint="R_Index3_z" gear="500"/>
    <motor name="R_Middle1_x" joint="R_Middle1_x" gear="500"/>
    <motor name="R_Middle1_y" joint="R_Middle1_y" gear="500"/>
    <motor name="R_Middle1_z" joint="R_Middle1_z" gear="500"/>
    <motor name="R_Middle2_x" joint="R_Middle2_x" gear="500"/>
    <motor name="R_Middle2_y" joint="R_Middle2_y" gear="500"/>
    <motor name="R_Middle2_z" joint="R_Middle2_z" gear="500"/>
    <motor name="R_Middle3_x" joint="R_Middle3_x" gear="500"/>
    <motor name="R_Middle3_y" joint="R_Middle3_y" gear="500"/>
    <motor name="R_Middle3_z" joint="R_Middle3_z" gear="500"/>
    <motor name="R_Pinky1_x" joint="R_Pinky1_x" gear="500"/>
    <motor name="R_Pinky1_y" joint="R_Pinky1_y" gear="500"/>
    <motor name="R_Pinky1_z" joint="R_Pinky1_z" gear="500"/>
    <motor name="R_Pinky2_x" joint="R_Pinky2_x" gear="500"/>
    <motor name="R_Pinky2_y" joint="R_Pinky2_y" gear="500"/>
    <motor name="R_Pinky2_z" joint="R_Pinky2_z" gear="500"/>
    <motor name="R_Pinky3_x" joint="R_Pinky3_x" gear="500"/>
    <motor name="R_Pinky3_y" joint="R_Pinky3_y" gear="500"/>
    <motor name="R_Pinky3_z" joint="R_Pinky3_z" gear="500"/>
    <motor name="R_Ring1_x" joint="R_Ring1_x" gear="500"/>
    <motor name="R_Ring1_y" joint="R_Ring1_y" gear="500"/>
    <motor name="R_Ring1_z" joint="R_Ring1_z" gear="500"/>
    <motor name="R_Ring2_x" joint="R_Ring2_x" gear="500"/>
    <motor name="R_Ring2_y" joint="R_Ring2_y" gear="500"/>
    <motor name="R_Ring2_z" joint="R_Ring2_z" gear="500"/>
    <motor name="R_Ring3_x" joint="R_Ring3_x" gear="500"/>
    <motor name="R_Ring3_y" joint="R_Ring3_y" gear="500"/>
    <motor name="R_Ring3_z" joint="R_Ring3_z" gear="500"/>
    <motor name="R_Thumb1_x" joint="R_Thumb1_x" gear="500"/>
    <motor name="R_Thumb1_y" joint="R_Thumb1_y" gear="500"/>
    <motor name="R_Thumb1_z" joint="R_Thumb1_z" gear="500"/>
    <motor name="R_Thumb2_x" joint="R_Thumb2_x" gear="500"/>
    <motor name="R_Thumb2_y" joint="R_Thumb2_y" gear="500"/>
    <motor name="R_Thumb2_z" joint="R_Thumb2_z" gear="500"/>
    <motor name="R_Thumb3_x" joint="R_Thumb3_x" gear="500"/>
    <motor name="R_Thumb3_y" joint="R_Thumb3_y" gear="500"/>
    <motor name="R_Thumb3_z" joint="R_Thumb3_z" gear="500"/>
  </actuator>
  <contact>
    <exclude body1="Torso" body2="Chest"/>
    <exclude body1="Head" body2="Chest"/>
    <exclude body1="R_Knee" body2="R_Toe"/>
    <exclude body1="R_Knee" body2="L_Ankle"/>
    <exclude body1="R_Knee" body2="L_Toe"/>
    <exclude body1="L_Knee" body2="L_Toe"/>
    <exclude body1="L_Knee" body2="R_Ankle"/>
    <exclude body1="L_Knee" body2="R_Toe"/>
    <exclude body1="L_Shoulder" body2="Chest"/>
    <exclude body1="R_Shoulder" body2="Chest"/>
  </contact>
  <sensor/>
  <size njmax="700" nconmax="700"/>
</mujoco>
