<mujoco model="humanoid">
  <compiler coordinate="local" angle="radian"/>
  <default>
    <joint damping="0.0" armature="0.01" stiffness="0.0" limited="true"/>
    <geom conaffinity="1" condim="3" contype="7" margin="0.001" rgba="0.8 0.6 .4 1"/>
  </default>
  <asset>
    <texture type="skybox" builtin="gradient" rgb1=".4 .5 .6" rgb2="0 0 0" width="100" height="100"/>
    <texture builtin="flat" height="1278" mark="cross" markrgb="1 1 1" name="texgeom" random="0.01" rgb1="0.8 0.6 0.4" rgb2="0.8 0.6 0.4" type="cube" width="127"/>
    <texture builtin="checker" height="100" name="texplane" rgb1="0 0 0" rgb2="0.8 0.8 0.8" type="2d" width="100"/>
    <material name="MatPlane" reflectance="0.5" shininess="1" specular="1" texrepeat="60 60" texture="texplane"/>
    <material name="geom" texture="texgeom" texuniform="true"/>
  </asset>
  <worldbody>
    <light cutoff="100" diffuse="1 1 1" dir="-0 0 -1.3" directional="true" exponent="1" pos="0 0 1.3" specular=".1 .1 .1"/>
    <geom conaffinity="1" condim="3" name="floor" pos="0 0 0" rgba="0.8 0.9 0.8 1" size="100 100 .2" type="plane" material="MatPlane"/>
    <body name="Pelvis" pos="-0.006 -0.2084 0.0054">
      <freejoint name="Pelvis"/>
      <geom type="box" contype="1" conaffinity="1" density="500" pos="-0.0121 0.0006 -0.0082" size="0.0608 0.0857 0.0354" quat="0.9997 0.0000 0.0000 -0.0248" name="Pelvis"/>
      <body name="L_Hip" pos="-0.0261 0.0449 -0.0728">
        <joint name="L_Hip_x" type="hinge" pos="0 0 0" axis="1 0 0" stiffness="800" damping="80" armature="0.02" range="-180.0000 180.0000"/>
        <joint name="L_Hip_y" type="hinge" pos="0 0 0" axis="0 1 0" stiffness="800" damping="80" armature="0.02" range="-180.0000 180.0000"/>
        <joint name="L_Hip_z" type="hinge" pos="0 0 0" axis="0 0 1" stiffness="800" damping="80" armature="0.02" range="-180.0000 180.0000"/>
        <geom type="capsule" contype="1" conaffinity="1" density="500" fromto="0.0039 0.0099 -0.0762 0.0157 0.0395 -0.3047" size="0.0526" name="L_Hip"/>
        <body name="L_Knee" pos="0.0197 0.0494 -0.3808">
          <joint name="L_Knee_x" type="hinge" pos="0 0 0" axis="1 0 0" stiffness="800" damping="80" armature="0.02" range="-180.0000 180.0000"/>
          <joint name="L_Knee_y" type="hinge" pos="0 0 0" axis="0 1 0" stiffness="800" damping="80" armature="0.02" range="-180.0000 180.0000"/>
          <joint name="L_Knee_z" type="hinge" pos="0 0 0" axis="0 0 1" stiffness="800" damping="80" armature="0.02" range="-180.0000 180.0000"/>
          <geom type="capsule" contype="1" conaffinity="1" density="500" fromto="-0.0053 -0.0020 -0.0793 -0.0211 -0.0078 -0.3174" size="0.0457" name="L_Knee"/>
          <body name="L_Ankle" pos="-0.0264 -0.0098 -0.3967">
            <joint name="L_Ankle_x" type="hinge" pos="0 0 0" axis="1 0 0" stiffness="800" damping="80" armature="0.02" range="-180.0000 180.0000"/>
            <joint name="L_Ankle_y" type="hinge" pos="0 0 0" axis="0 1 0" stiffness="800" damping="80" armature="0.02" range="-180.0000 180.0000"/>
            <joint name="L_Ankle_z" type="hinge" pos="0 0 0" axis="0 0 1" stiffness="800" damping="80" armature="0.02" range="-180.0000 180.0000"/>
            <geom type="box" contype="1" conaffinity="1" density="500" pos="0.0553 0.0281 -0.0294" size="0.0811 0.0557 0.0165" quat="0.9726 0.0000 0.0000 0.2326" name="L_Ankle"/>
            <body name="L_Toe" pos="0.1106 0.0561 -0.0589">
              <joint name="L_Toe_x" type="hinge" pos="0 0 0" axis="1 0 0" stiffness="500" damping="50" armature="0.02" range="-180.0000 180.0000"/>
              <joint name="L_Toe_y" type="hinge" pos="0 0 0" axis="0 1 0" stiffness="500" damping="50" armature="0.02" range="-180.0000 180.0000"/>
              <joint name="L_Toe_z" type="hinge" pos="0 0 0" axis="0 0 1" stiffness="500" damping="50" armature="0.02" range="-180.0000 180.0000"/>
              <geom type="box" contype="1" conaffinity="1" density="500" pos="0.0000 0.0000 0.0321" size="0.0009 0.0026 0.001" quat="0.9718 0.0000 0.0000 0.2360" name="L_Toe"/>
            </body>
          </body>
        </body>
      </body>
      <body name="R_Hip" pos="-0.0233 -0.0453 -0.0802">
        <joint name="R_Hip_x" type="hinge" pos="0 0 0" axis="1 0 0" stiffness="800" damping="80" armature="0.02" range="-180.0000 180.0000"/>
        <joint name="R_Hip_y" type="hinge" pos="0 0 0" axis="0 1 0" stiffness="800" damping="80" armature="0.02" range="-180.0000 180.0000"/>
        <joint name="R_Hip_z" type="hinge" pos="0 0 0" axis="0 0 1" stiffness="800" damping="80" armature="0.02" range="-180.0000 180.0000"/>
        <geom type="capsule" contype="1" conaffinity="1" density="500" fromto="0.0007 -0.0092 -0.0733 0.0028 -0.0366 -0.2931" size="0.0513" name="R_Hip"/>
        <body name="R_Knee" pos="0.0035 -0.0458 -0.3664">
          <joint name="R_Knee_x" type="hinge" pos="0 0 0" axis="1 0 0" stiffness="800" damping="80" armature="0.02" range="-180.0000 180.0000"/>
          <joint name="R_Knee_y" type="hinge" pos="0 0 0" axis="0 1 0" stiffness="800" damping="80" armature="0.02" range="-180.0000 180.0000"/>
          <joint name="R_Knee_z" type="hinge" pos="0 0 0" axis="0 0 1" stiffness="800" damping="80" armature="0.02" range="-180.0000 180.0000"/>
          <geom type="capsule" contype="1" conaffinity="1" density="500" fromto="-0.0054 0.0029 -0.0770 -0.0214 0.0117 -0.3081" size="0.047" name="R_Knee"/>
          <body name="R_Ankle" pos="-0.0268 0.0146 -0.3852">
            <joint name="R_Ankle_x" type="hinge" pos="0 0 0" axis="1 0 0" stiffness="800" damping="80" armature="0.02" range="-180.0000 180.0000"/>
            <joint name="R_Ankle_y" type="hinge" pos="0 0 0" axis="0 1 0" stiffness="800" damping="80" armature="0.02" range="-180.0000 180.0000"/>
            <joint name="R_Ankle_z" type="hinge" pos="0 0 0" axis="0 0 1" stiffness="800" damping="80" armature="0.02" range="-180.0000 180.0000"/>
            <geom type="box" contype="1" conaffinity="1" density="500" pos="0.0615 -0.0148 -0.0283" size="0.0888 0.0472 0.0185" quat="0.9930 0.0000 0.0000 -0.1179" name="R_Ankle"/>
            <body name="R_Toe" pos="0.123 -0.0296 -0.0566">
              <joint name="R_Toe_x" type="hinge" pos="0 0 0" axis="1 0 0" stiffness="500" damping="50" armature="0.02" range="-180.0000 180.0000"/>
              <joint name="R_Toe_y" type="hinge" pos="0 0 0" axis="0 1 0" stiffness="500" damping="50" armature="0.02" range="-180.0000 180.0000"/>
              <joint name="R_Toe_z" type="hinge" pos="0 0 0" axis="0 0 1" stiffness="500" damping="50" armature="0.02" range="-180.0000 180.0000"/>
              <geom type="box" contype="1" conaffinity="1" density="500" pos="0.0000 0.0000 0.0323" size="0.0008 0.0023 0.0011" quat="0.9941 0.0000 0.0000 -0.1085" name="R_Toe"/>
            </body>
          </body>
        </body>
      </body>
      <body name="Torso" pos="-0.0229 0.004 0.1039">
        <joint name="Torso_x" type="hinge" pos="0 0 0" axis="1 0 0" stiffness="1000" damping="100" armature="0.02" range="-180.0000 180.0000"/>
        <joint name="Torso_y" type="hinge" pos="0 0 0" axis="0 1 0" stiffness="1000" damping="100" armature="0.02" range="-180.0000 180.0000"/>
        <joint name="Torso_z" type="hinge" pos="0 0 0" axis="0 0 1" stiffness="1000" damping="100" armature="0.02" range="-180.0000 180.0000"/>
        <geom type="capsule" contype="1" conaffinity="1" density="500" fromto="0.0160 0.0029 0.0786 0.0106 0.0019 0.0524" size="0.0562" name="Torso"/>
        <body name="Spine" pos="0.0266 0.0048 0.1311">
          <joint name="Spine_x" type="hinge" pos="0 0 0" axis="1 0 0" stiffness="1000" damping="100" armature="0.02" range="-180.0000 180.0000"/>
          <joint name="Spine_y" type="hinge" pos="0 0 0" axis="0 1 0" stiffness="1000" damping="100" armature="0.02" range="-180.0000 180.0000"/>
          <joint name="Spine_z" type="hinge" pos="0 0 0" axis="0 0 1" stiffness="1000" damping="100" armature="0.02" range="-180.0000 180.0000"/>
          <geom type="capsule" contype="1" conaffinity="1" density="500" fromto="-0.0010 -0.0001 0.0315 -0.0007 -0.0001 0.0210" size="0.057" name="Spine"/>
          <body name="Chest" pos="-0.0017 -0.0001 0.0525">
            <joint name="Chest_x" type="hinge" pos="0 0 0" axis="1 0 0" stiffness="1000" damping="100" armature="0.02" range="-180.0000 180.0000"/>
            <joint name="Chest_y" type="hinge" pos="0 0 0" axis="0 1 0" stiffness="1000" damping="100" armature="0.02" range="-180.0000 180.0000"/>
            <joint name="Chest_z" type="hinge" pos="0 0 0" axis="0 0 1" stiffness="1000" damping="100" armature="0.02" range="-180.0000 180.0000"/>
            <geom type="capsule" contype="1" conaffinity="1" density="500" fromto="-0.0070 -0.0041 0.0731 -0.0047 -0.0027 0.0488" size="0.0796" name="Chest"/>
            <body name="Neck" pos="-0.0022 -0.0108 0.1773">
              <joint name="Neck_x" type="hinge" pos="0 0 0" axis="1 0 0" stiffness="500" damping="50" armature="0.02" range="-180.0000 180.0000"/>
              <joint name="Neck_y" type="hinge" pos="0 0 0" axis="0 1 0" stiffness="500" damping="50" armature="0.02" range="-180.0000 180.0000"/>
              <joint name="Neck_z" type="hinge" pos="0 0 0" axis="0 0 1" stiffness="500" damping="50" armature="0.02" range="-180.0000 180.0000"/>
              <geom type="capsule" contype="1" conaffinity="1" density="500" fromto="0.0107 0.0022 0.0197 0.0429 0.0088 0.0787" size="0.0379" name="Neck"/>
              <body name="Head" pos="0.0536 0.0109 0.0984">
                <joint name="Head_x" type="hinge" pos="0 0 0" axis="1 0 0" stiffness="500" damping="50" armature="0.02" range="-180.0000 180.0000"/>
                <joint name="Head_y" type="hinge" pos="0 0 0" axis="0 1 0" stiffness="500" damping="50" armature="0.02" range="-180.0000 180.0000"/>
                <joint name="Head_z" type="hinge" pos="0 0 0" axis="0 0 1" stiffness="500" damping="50" armature="0.02" range="-180.0000 180.0000"/>
                <geom type="box" contype="1" conaffinity="1" density="500" pos="0.0278 0.0065 0.0502" size="0.0744 0.0554 0.0479" quat="0.9935 0.0000 0.0000 0.1140" name="Head"/>
              </body>
            </body>
            <body name="L_Thorax" pos="-0.0142 0.056 0.0956">
              <joint name="L_Thorax_x" type="hinge" pos="0 0 0" axis="1 0 0" stiffness="500" damping="50" armature="0.02" range="-180.0000 180.0000"/>
              <joint name="L_Thorax_y" type="hinge" pos="0 0 0" axis="0 1 0" stiffness="500" damping="50" armature="0.02" range="-180.0000 180.0000"/>
              <joint name="L_Thorax_z" type="hinge" pos="0 0 0" axis="0 0 1" stiffness="500" damping="50" armature="0.02" range="-180.0000 180.0000"/>
              <geom type="capsule" contype="1" conaffinity="1" density="500" fromto="-0.0016 0.0200 0.0089 -0.0064 0.0799 0.0357" size="0.0421" name="L_Thorax"/>
              <body name="L_Shoulder" pos="-0.008 0.0998 0.0446">
                <joint name="L_Shoulder_x" type="hinge" pos="0 0 0" axis="1 0 0" stiffness="500" damping="50" armature="0.02" range="-720.0000 720.0000"/>
                <joint name="L_Shoulder_y" type="hinge" pos="0 0 0" axis="0 1 0" stiffness="500" damping="50" armature="0.02" range="-720.0000 720.0000"/>
                <joint name="L_Shoulder_z" type="hinge" pos="0 0 0" axis="0 0 1" stiffness="500" damping="50" armature="0.02" range="-720.0000 720.0000"/>
                <geom type="capsule" contype="1" conaffinity="1" density="500" fromto="-0.0032 0.0499 -0.0036 -0.0128 0.1997 -0.0145" size="0.0422" name="L_Shoulder"/>
                <body name="L_Elbow" pos="-0.016 0.2497 -0.0181">
                  <joint name="L_Elbow_x" type="hinge" pos="0 0 0" axis="1 0 0" stiffness="500" damping="50" armature="0.02" range="-720.0000 720.0000"/>
                  <joint name="L_Elbow_y" type="hinge" pos="0 0 0" axis="0 1 0" stiffness="500" damping="50" armature="0.02" range="-720.0000 720.0000"/>
                  <joint name="L_Elbow_z" type="hinge" pos="0 0 0" axis="0 0 1" stiffness="500" damping="50" armature="0.02" range="-720.0000 720.0000"/>
                  <geom type="capsule" contype="1" conaffinity="1" density="500" fromto="-0.0022 0.0515 0.0023 -0.0090 0.2061 0.0091" size="0.0342" name="L_Elbow"/>
                  <body name="L_Wrist" pos="-0.0112 0.2576 0.0114">
                    <joint name="L_Wrist_x" type="hinge" pos="0 0 0" axis="1 0 0" stiffness="300" damping="30" armature="0.02" range="-180.0000 180.0000"/>
                    <joint name="L_Wrist_y" type="hinge" pos="0 0 0" axis="0 1 0" stiffness="300" damping="30" armature="0.02" range="-180.0000 180.0000"/>
                    <joint name="L_Wrist_z" type="hinge" pos="0 0 0" axis="0 0 1" stiffness="300" damping="30" armature="0.02" range="-180.0000 180.0000"/>
                    <geom type="capsule" contype="1" conaffinity="1" density="500" fromto="-0.0032 0.0169 -0.0021 -0.0127 0.0676 -0.0083" size="0.0321" name="L_Wrist"/>
                    <body name="L_Hand" pos="-0.0158 0.0845 -0.0104">
                      <joint name="L_Hand_x" type="hinge" pos="0 0 0" axis="1 0 0" stiffness="300" damping="30" armature="0.02" range="-180.0000 180.0000"/>
                      <joint name="L_Hand_y" type="hinge" pos="0 0 0" axis="0 1 0" stiffness="300" damping="30" armature="0.02" range="-180.0000 180.0000"/>
                      <joint name="L_Hand_z" type="hinge" pos="0 0 0" axis="0 0 1" stiffness="300" damping="30" armature="0.02" range="-180.0000 180.0000"/>
                      <geom type="sphere" contype="1" conaffinity="1" density="500" size="0.0343" pos="0.0000 0.0000 0.0000" name="L_Hand"/>
                    </body>
                  </body>
                </body>
              </body>
            </body>
            <body name="R_Thorax" pos="-0.0185 -0.0658 0.0929">
              <joint name="R_Thorax_x" type="hinge" pos="0 0 0" axis="1 0 0" stiffness="500" damping="50" armature="0.02" range="-180.0000 180.0000"/>
              <joint name="R_Thorax_y" type="hinge" pos="0 0 0" axis="0 1 0" stiffness="500" damping="50" armature="0.02" range="-180.0000 180.0000"/>
              <joint name="R_Thorax_z" type="hinge" pos="0 0 0" axis="0 0 1" stiffness="500" damping="50" armature="0.02" range="-180.0000 180.0000"/>
              <geom type="capsule" contype="1" conaffinity="1" density="500" fromto="-0.0001 -0.0184 0.0086 -0.0004 -0.0735 0.0345" size="0.0428" name="R_Thorax"/>
              <body name="R_Shoulder" pos="-0.0006 -0.0919 0.0432">
                <joint name="R_Shoulder_x" type="hinge" pos="0 0 0" axis="1 0 0" stiffness="500" damping="50" armature="0.02" range="-720.0000 720.0000"/>
                <joint name="R_Shoulder_y" type="hinge" pos="0 0 0" axis="0 1 0" stiffness="500" damping="50" armature="0.02" range="-720.0000 720.0000"/>
                <joint name="R_Shoulder_z" type="hinge" pos="0 0 0" axis="0 0 1" stiffness="500" damping="50" armature="0.02" range="-720.0000 720.0000"/>
                <geom type="capsule" contype="1" conaffinity="1" density="500" fromto="-0.0044 -0.0497 -0.0044 -0.0176 -0.1990 -0.0176" size="0.0434" name="R_Shoulder"/>
                <body name="R_Elbow" pos="-0.0219 -0.2487 -0.022">
                  <joint name="R_Elbow_x" type="hinge" pos="0 0 0" axis="1 0 0" stiffness="500" damping="50" armature="0.02" range="-720.0000 720.0000"/>
                  <joint name="R_Elbow_y" type="hinge" pos="0 0 0" axis="0 1 0" stiffness="500" damping="50" armature="0.02" range="-720.0000 720.0000"/>
                  <joint name="R_Elbow_z" type="hinge" pos="0 0 0" axis="0 0 1" stiffness="500" damping="50" armature="0.02" range="-720.0000 720.0000"/>
                  <geom type="capsule" contype="1" conaffinity="1" density="500" fromto="-0.0011 -0.0530 0.0026 -0.0045 -0.2121 0.0104" size="0.0345" name="R_Elbow"/>
                  <body name="R_Wrist" pos="-0.0056 -0.2651 0.0129">
                    <joint name="R_Wrist_x" type="hinge" pos="0 0 0" axis="1 0 0" stiffness="300" damping="30" armature="0.02" range="-180.0000 180.0000"/>
                    <joint name="R_Wrist_y" type="hinge" pos="0 0 0" axis="0 1 0" stiffness="300" damping="30" armature="0.02" range="-180.0000 180.0000"/>
                    <joint name="R_Wrist_z" type="hinge" pos="0 0 0" axis="0 0 1" stiffness="300" damping="30" armature="0.02" range="-180.0000 180.0000"/>
                    <geom type="capsule" contype="1" conaffinity="1" density="500" fromto="-0.0021 -0.0169 -0.0016 -0.0086 -0.0676 -0.0066" size="0.032" name="R_Wrist"/>
                    <body name="R_Hand" pos="-0.0107 -0.0846 -0.0082">
                      <joint name="R_Hand_x" type="hinge" pos="0 0 0" axis="1 0 0" stiffness="300" damping="30" armature="0.02" range="-180.0000 180.0000"/>
                      <joint name="R_Hand_y" type="hinge" pos="0 0 0" axis="0 1 0" stiffness="300" damping="30" armature="0.02" range="-180.0000 180.0000"/>
                      <joint name="R_Hand_z" type="hinge" pos="0 0 0" axis="0 0 1" stiffness="300" damping="30" armature="0.02" range="-180.0000 180.0000"/>
                      <geom type="sphere" contype="1" conaffinity="1" density="500" size="0.0341" pos="0.0000 0.0000 0.0000" name="R_Hand"/>
                    </body>
                  </body>
                </body>
              </body>
            </body>
          </body>
        </body>
      </body>
    </body>
  </worldbody>
  <actuator>
    <motor name="L_Hip_x" joint="L_Hip_x" gear="500"/>
    <motor name="L_Hip_y" joint="L_Hip_y" gear="500"/>
    <motor name="L_Hip_z" joint="L_Hip_z" gear="500"/>
    <motor name="L_Knee_x" joint="L_Knee_x" gear="500"/>
    <motor name="L_Knee_y" joint="L_Knee_y" gear="500"/>
    <motor name="L_Knee_z" joint="L_Knee_z" gear="500"/>
    <motor name="L_Ankle_x" joint="L_Ankle_x" gear="500"/>
    <motor name="L_Ankle_y" joint="L_Ankle_y" gear="500"/>
    <motor name="L_Ankle_z" joint="L_Ankle_z" gear="500"/>
    <motor name="L_Toe_x" joint="L_Toe_x" gear="500"/>
    <motor name="L_Toe_y" joint="L_Toe_y" gear="500"/>
    <motor name="L_Toe_z" joint="L_Toe_z" gear="500"/>
    <motor name="R_Hip_x" joint="R_Hip_x" gear="500"/>
    <motor name="R_Hip_y" joint="R_Hip_y" gear="500"/>
    <motor name="R_Hip_z" joint="R_Hip_z" gear="500"/>
    <motor name="R_Knee_x" joint="R_Knee_x" gear="500"/>
    <motor name="R_Knee_y" joint="R_Knee_y" gear="500"/>
    <motor name="R_Knee_z" joint="R_Knee_z" gear="500"/>
    <motor name="R_Ankle_x" joint="R_Ankle_x" gear="500"/>
    <motor name="R_Ankle_y" joint="R_Ankle_y" gear="500"/>
    <motor name="R_Ankle_z" joint="R_Ankle_z" gear="500"/>
    <motor name="R_Toe_x" joint="R_Toe_x" gear="500"/>
    <motor name="R_Toe_y" joint="R_Toe_y" gear="500"/>
    <motor name="R_Toe_z" joint="R_Toe_z" gear="500"/>
    <motor name="Torso_x" joint="Torso_x" gear="500"/>
    <motor name="Torso_y" joint="Torso_y" gear="500"/>
    <motor name="Torso_z" joint="Torso_z" gear="500"/>
    <motor name="Spine_x" joint="Spine_x" gear="500"/>
    <motor name="Spine_y" joint="Spine_y" gear="500"/>
    <motor name="Spine_z" joint="Spine_z" gear="500"/>
    <motor name="Chest_x" joint="Chest_x" gear="500"/>
    <motor name="Chest_y" joint="Chest_y" gear="500"/>
    <motor name="Chest_z" joint="Chest_z" gear="500"/>
    <motor name="Neck_x" joint="Neck_x" gear="500"/>
    <motor name="Neck_y" joint="Neck_y" gear="500"/>
    <motor name="Neck_z" joint="Neck_z" gear="500"/>
    <motor name="Head_x" joint="Head_x" gear="500"/>
    <motor name="Head_y" joint="Head_y" gear="500"/>
    <motor name="Head_z" joint="Head_z" gear="500"/>
    <motor name="L_Thorax_x" joint="L_Thorax_x" gear="500"/>
    <motor name="L_Thorax_y" joint="L_Thorax_y" gear="500"/>
    <motor name="L_Thorax_z" joint="L_Thorax_z" gear="500"/>
    <motor name="L_Shoulder_x" joint="L_Shoulder_x" gear="500"/>
    <motor name="L_Shoulder_y" joint="L_Shoulder_y" gear="500"/>
    <motor name="L_Shoulder_z" joint="L_Shoulder_z" gear="500"/>
    <motor name="L_Elbow_x" joint="L_Elbow_x" gear="500"/>
    <motor name="L_Elbow_y" joint="L_Elbow_y" gear="500"/>
    <motor name="L_Elbow_z" joint="L_Elbow_z" gear="500"/>
    <motor name="L_Wrist_x" joint="L_Wrist_x" gear="500"/>
    <motor name="L_Wrist_y" joint="L_Wrist_y" gear="500"/>
    <motor name="L_Wrist_z" joint="L_Wrist_z" gear="500"/>
    <motor name="L_Hand_x" joint="L_Hand_x" gear="500"/>
    <motor name="L_Hand_y" joint="L_Hand_y" gear="500"/>
    <motor name="L_Hand_z" joint="L_Hand_z" gear="500"/>
    <motor name="R_Thorax_x" joint="R_Thorax_x" gear="500"/>
    <motor name="R_Thorax_y" joint="R_Thorax_y" gear="500"/>
    <motor name="R_Thorax_z" joint="R_Thorax_z" gear="500"/>
    <motor name="R_Shoulder_x" joint="R_Shoulder_x" gear="500"/>
    <motor name="R_Shoulder_y" joint="R_Shoulder_y" gear="500"/>
    <motor name="R_Shoulder_z" joint="R_Shoulder_z" gear="500"/>
    <motor name="R_Elbow_x" joint="R_Elbow_x" gear="500"/>
    <motor name="R_Elbow_y" joint="R_Elbow_y" gear="500"/>
    <motor name="R_Elbow_z" joint="R_Elbow_z" gear="500"/>
    <motor name="R_Wrist_x" joint="R_Wrist_x" gear="500"/>
    <motor name="R_Wrist_y" joint="R_Wrist_y" gear="500"/>
    <motor name="R_Wrist_z" joint="R_Wrist_z" gear="500"/>
    <motor name="R_Hand_x" joint="R_Hand_x" gear="500"/>
    <motor name="R_Hand_y" joint="R_Hand_y" gear="500"/>
    <motor name="R_Hand_z" joint="R_Hand_z" gear="500"/>
  </actuator>
  <contact>
    <exclude body1="Torso" body2="Chest"/>
    <exclude body1="Head" body2="Chest"/>
    <exclude body1="R_Knee" body2="R_Toe"/>
    <exclude body1="R_Knee" body2="L_Ankle"/>
    <exclude body1="R_Knee" body2="L_Toe"/>
    <exclude body1="L_Knee" body2="L_Toe"/>
    <exclude body1="L_Knee" body2="R_Ankle"/>
    <exclude body1="L_Knee" body2="R_Toe"/>
    <exclude body1="L_Shoulder" body2="Chest"/>
    <exclude body1="R_Shoulder" body2="Chest"/>
  </contact>
  <sensor/>
  <size njmax="700" nconmax="700"/>
</mujoco>
