<mujoco model="humanoid">
  <compiler coordinate="local" angle="radian"/>
  <default>
    <joint damping="0.0" armature="0.01" stiffness="0.0" limited="true"/>
    <geom conaffinity="1" condim="3" contype="7" margin="0.001" rgba="0.8 0.6 .4 1"/>
  </default>
  <asset>
    <texture type="skybox" builtin="gradient" rgb1=".4 .5 .6" rgb2="0 0 0" width="100" height="100"/>
    <texture builtin="flat" height="1278" mark="cross" markrgb="1 1 1" name="texgeom" random="0.01" rgb1="0.8 0.6 0.4" rgb2="0.8 0.6 0.4" type="cube" width="127"/>
    <texture builtin="checker" height="100" name="texplane" rgb1="0 0 0" rgb2="0.8 0.8 0.8" type="2d" width="100"/>
    <material name="MatPlane" reflectance="0.5" shininess="1" specular="1" texrepeat="60 60" texture="texplane"/>
    <material name="geom" texture="texgeom" texuniform="true"/>
  </asset>
  <worldbody>
    <light cutoff="100" diffuse="1 1 1" dir="-0 0 -1.3" directional="true" exponent="1" pos="0 0 1.3" specular=".1 .1 .1"/>
    <geom conaffinity="1" condim="3" name="floor" pos="0 0 0" rgba="0.8 0.9 0.8 1" size="100 100 .2" type="plane" material="MatPlane"/>
    <body name="Pelvis" pos="-0.0037 -0.2757 0.0285">
      <freejoint name="Pelvis"/>
      <geom type="sphere" contype="1" conaffinity="1" density="500" size="0.1103" pos="0.0000 0.0000 0.0000" name="Pelvis"/>
      <body name="L_Hip" pos="-0.0171 0.0618 -0.0917">
        <joint name="L_Hip_x" type="hinge" pos="0 0 0" axis="1 0 0" stiffness="800" damping="80" armature="0.02" range="-180.0000 180.0000"/>
        <joint name="L_Hip_y" type="hinge" pos="0 0 0" axis="0 1 0" stiffness="800" damping="80" armature="0.02" range="-180.0000 180.0000"/>
        <joint name="L_Hip_z" type="hinge" pos="0 0 0" axis="0 0 1" stiffness="800" damping="80" armature="0.02" range="-180.0000 180.0000"/>
        <geom type="capsule" contype="1" conaffinity="1" density="500" fromto="0.0007 0.0073 -0.0778 0.0027 0.0293 -0.3113" size="0.0657" name="L_Hip"/>
        <body name="L_Knee" pos="0.0034 0.0366 -0.3891">
          <joint name="L_Knee_x" type="hinge" pos="0 0 0" axis="1 0 0" stiffness="800" damping="80" armature="0.02" range="-180.0000 180.0000"/>
          <joint name="L_Knee_y" type="hinge" pos="0 0 0" axis="0 1 0" stiffness="800" damping="80" armature="0.02" range="-180.0000 180.0000"/>
          <joint name="L_Knee_z" type="hinge" pos="0 0 0" axis="0 0 1" stiffness="800" damping="80" armature="0.02" range="-180.0000 180.0000"/>
          <geom type="capsule" contype="1" conaffinity="1" density="500" fromto="-0.0089 -0.0036 -0.0884 -0.0355 -0.0145 -0.3536" size="0.06" name="L_Knee"/>
          <body name="L_Ankle" pos="-0.0444 -0.0181 -0.442">
            <joint name="L_Ankle_x" type="hinge" pos="0 0 0" axis="1 0 0" stiffness="800" damping="80" armature="0.02" range="-180.0000 180.0000"/>
            <joint name="L_Ankle_y" type="hinge" pos="0 0 0" axis="0 1 0" stiffness="800" damping="80" armature="0.02" range="-180.0000 180.0000"/>
            <joint name="L_Ankle_z" type="hinge" pos="0 0 0" axis="0 0 1" stiffness="800" damping="80" armature="0.02" range="-180.0000 180.0000"/>
            <geom type="box" contype="1" conaffinity="1" density="500" pos="0.0649 0.0165 -0.0311" size="0.0937 0.0529 0.0253" quat="0.9923 0.0000 0.0000 0.1239" name="L_Ankle"/>
            <body name="L_Toe" pos="0.1298 0.0329 -0.0621">
              <joint name="L_Toe_x" type="hinge" pos="0 0 0" axis="1 0 0" stiffness="500" damping="50" armature="0.02" range="-180.0000 180.0000"/>
              <joint name="L_Toe_y" type="hinge" pos="0 0 0" axis="0 1 0" stiffness="500" damping="50" armature="0.02" range="-180.0000 180.0000"/>
              <joint name="L_Toe_z" type="hinge" pos="0 0 0" axis="0 0 1" stiffness="500" damping="50" armature="0.02" range="-180.0000 180.0000"/>
              <geom type="box" contype="1" conaffinity="1" density="500" pos="0.0000 0.0000 0.0313" size="0.0011 0.0026 0.0013" quat="0.9916 0.0000 0.0000 0.1291" name="L_Toe"/>
            </body>
          </body>
        </body>
      </body>
      <body name="R_Hip" pos="-0.0106 -0.0652 -0.1019">
        <joint name="R_Hip_x" type="hinge" pos="0 0 0" axis="1 0 0" stiffness="800" damping="80" armature="0.02" range="-180.0000 180.0000"/>
        <joint name="R_Hip_y" type="hinge" pos="0 0 0" axis="0 1 0" stiffness="800" damping="80" armature="0.02" range="-180.0000 180.0000"/>
        <joint name="R_Hip_z" type="hinge" pos="0 0 0" axis="0 0 1" stiffness="800" damping="80" armature="0.02" range="-180.0000 180.0000"/>
        <geom type="capsule" contype="1" conaffinity="1" density="500" fromto="-0.0019 -0.0080 -0.0786 -0.0076 -0.0319 -0.3145" size="0.0656" name="R_Hip"/>
        <body name="R_Knee" pos="-0.0095 -0.0398 -0.3932">
          <joint name="R_Knee_x" type="hinge" pos="0 0 0" axis="1 0 0" stiffness="800" damping="80" armature="0.02" range="-180.0000 180.0000"/>
          <joint name="R_Knee_y" type="hinge" pos="0 0 0" axis="0 1 0" stiffness="800" damping="80" armature="0.02" range="-180.0000 180.0000"/>
          <joint name="R_Knee_z" type="hinge" pos="0 0 0" axis="0 0 1" stiffness="800" damping="80" armature="0.02" range="-180.0000 180.0000"/>
          <geom type="capsule" contype="1" conaffinity="1" density="500" fromto="-0.0080 0.0045 -0.0876 -0.0319 0.0179 -0.3503" size="0.0595" name="R_Knee"/>
          <body name="R_Ankle" pos="-0.0399 0.0224 -0.4379">
            <joint name="R_Ankle_x" type="hinge" pos="0 0 0" axis="1 0 0" stiffness="800" damping="80" armature="0.02" range="-180.0000 180.0000"/>
            <joint name="R_Ankle_y" type="hinge" pos="0 0 0" axis="0 1 0" stiffness="800" damping="80" armature="0.02" range="-180.0000 180.0000"/>
            <joint name="R_Ankle_z" type="hinge" pos="0 0 0" axis="0 0 1" stiffness="800" damping="80" armature="0.02" range="-180.0000 180.0000"/>
            <geom type="box" contype="1" conaffinity="1" density="500" pos="0.0692 -0.0184 -0.0322" size="0.0949 0.055 0.0244" quat="0.9915 0.0000 0.0000 -0.1298" name="R_Ankle"/>
            <body name="R_Toe" pos="0.1385 -0.0369 -0.0645">
              <joint name="R_Toe_x" type="hinge" pos="0 0 0" axis="1 0 0" stiffness="500" damping="50" armature="0.02" range="-180.0000 180.0000"/>
              <joint name="R_Toe_y" type="hinge" pos="0 0 0" axis="0 1 0" stiffness="500" damping="50" armature="0.02" range="-180.0000 180.0000"/>
              <joint name="R_Toe_z" type="hinge" pos="0 0 0" axis="0 0 1" stiffness="500" damping="50" armature="0.02" range="-180.0000 180.0000"/>
              <geom type="box" contype="1" conaffinity="1" density="500" pos="0.0000 0.0000 0.0341" size="0.0012 0.0027 0.0013" quat="0.9926 0.0000 0.0000 -0.1214" name="R_Toe"/>
            </body>
          </body>
        </body>
      </body>
      <body name="Torso" pos="-0.0394 0.0051 0.1422">
        <joint name="Torso_x" type="hinge" pos="0 0 0" axis="1 0 0" stiffness="1000" damping="100" armature="0.02" range="-180.0000 180.0000"/>
        <joint name="Torso_y" type="hinge" pos="0 0 0" axis="0 1 0" stiffness="1000" damping="100" armature="0.02" range="-180.0000 180.0000"/>
        <joint name="Torso_z" type="hinge" pos="0 0 0" axis="0 0 1" stiffness="1000" damping="100" armature="0.02" range="-180.0000 180.0000"/>
        <geom type="capsule" contype="1" conaffinity="1" density="500" fromto="0.0196 0.0038 0.0942 0.0131 0.0025 0.0628" size="0.0953" name="Torso"/>
        <body name="Spine" pos="0.0327 0.0063 0.1569">
          <joint name="Spine_x" type="hinge" pos="0 0 0" axis="1 0 0" stiffness="1000" damping="100" armature="0.02" range="-180.0000 180.0000"/>
          <joint name="Spine_y" type="hinge" pos="0 0 0" axis="0 1 0" stiffness="1000" damping="100" armature="0.02" range="-180.0000 180.0000"/>
          <joint name="Spine_z" type="hinge" pos="0 0 0" axis="0 0 1" stiffness="1000" damping="100" armature="0.02" range="-180.0000 180.0000"/>
          <geom type="capsule" contype="1" conaffinity="1" density="500" fromto="0.0039 -0.0018 0.0381 0.0026 -0.0012 0.0254" size="0.0932" name="Spine"/>
          <body name="Chest" pos="0.0065 -0.003 0.0634">
            <joint name="Chest_x" type="hinge" pos="0 0 0" axis="1 0 0" stiffness="1000" damping="100" armature="0.02" range="-180.0000 180.0000"/>
            <joint name="Chest_y" type="hinge" pos="0 0 0" axis="0 1 0" stiffness="1000" damping="100" armature="0.02" range="-180.0000 180.0000"/>
            <joint name="Chest_z" type="hinge" pos="0 0 0" axis="0 0 1" stiffness="1000" damping="100" armature="0.02" range="-180.0000 180.0000"/>
            <geom type="capsule" contype="1" conaffinity="1" density="500" fromto="-0.0176 -0.0052 0.0944 -0.0117 -0.0035 0.0629" size="0.1141" name="Chest"/>
            <body name="Neck" pos="-0.0403 -0.0156 0.2275">
              <joint name="Neck_x" type="hinge" pos="0 0 0" axis="1 0 0" stiffness="500" damping="50" armature="0.02" range="-180.0000 180.0000"/>
              <joint name="Neck_y" type="hinge" pos="0 0 0" axis="0 1 0" stiffness="500" damping="50" armature="0.02" range="-180.0000 180.0000"/>
              <joint name="Neck_z" type="hinge" pos="0 0 0" axis="0 0 1" stiffness="500" damping="50" armature="0.02" range="-180.0000 180.0000"/>
              <geom type="capsule" contype="1" conaffinity="1" density="500" fromto="0.0107 0.0016 0.0179 0.0427 0.0065 0.0717" size="0.0493" name="Neck"/>
              <body name="Head" pos="0.0533 0.0081 0.0896">
                <joint name="Head_x" type="hinge" pos="0 0 0" axis="1 0 0" stiffness="500" damping="50" armature="0.02" range="-180.0000 180.0000"/>
                <joint name="Head_y" type="hinge" pos="0 0 0" axis="0 1 0" stiffness="500" damping="50" armature="0.02" range="-180.0000 180.0000"/>
                <joint name="Head_z" type="hinge" pos="0 0 0" axis="0 0 1" stiffness="500" damping="50" armature="0.02" range="-180.0000 180.0000"/>
                <geom type="sphere" contype="1" conaffinity="1" density="500" size="0.1117" pos="0.0000 0.0000 0.0000" name="Head"/>
              </body>
            </body>
            <body name="L_Thorax" pos="-0.022 0.0783 0.123">
              <joint name="L_Thorax_x" type="hinge" pos="0 0 0" axis="1 0 0" stiffness="500" damping="50" armature="0.02" range="-180.0000 180.0000"/>
              <joint name="L_Thorax_y" type="hinge" pos="0 0 0" axis="0 1 0" stiffness="500" damping="50" armature="0.02" range="-180.0000 180.0000"/>
              <joint name="L_Thorax_z" type="hinge" pos="0 0 0" axis="0 0 1" stiffness="500" damping="50" armature="0.02" range="-180.0000 180.0000"/>
              <geom type="capsule" contype="1" conaffinity="1" density="500" fromto="-0.0051 0.0263 0.0087 -0.0203 0.1053 0.0349" size="0.0577" name="L_Thorax"/>
              <body name="L_Shoulder" pos="-0.0254 0.1317 0.0436">
                <joint name="L_Shoulder_x" type="hinge" pos="0 0 0" axis="1 0 0" stiffness="500" damping="50" armature="0.02" range="-720.0000 720.0000"/>
                <joint name="L_Shoulder_y" type="hinge" pos="0 0 0" axis="0 1 0" stiffness="500" damping="50" armature="0.02" range="-720.0000 720.0000"/>
                <joint name="L_Shoulder_z" type="hinge" pos="0 0 0" axis="0 0 1" stiffness="500" damping="50" armature="0.02" range="-720.0000 720.0000"/>
                <geom type="capsule" contype="1" conaffinity="1" density="500" fromto="-0.0051 0.0541 -0.0032 -0.0206 0.2164 -0.0129" size="0.0607" name="L_Shoulder"/>
                <body name="L_Elbow" pos="-0.0257 0.2705 -0.0161">
                  <joint name="L_Elbow_x" type="hinge" pos="0 0 0" axis="1 0 0" stiffness="500" damping="50" armature="0.02" range="-720.0000 720.0000"/>
                  <joint name="L_Elbow_y" type="hinge" pos="0 0 0" axis="0 1 0" stiffness="500" damping="50" armature="0.02" range="-720.0000 720.0000"/>
                  <joint name="L_Elbow_z" type="hinge" pos="0 0 0" axis="0 0 1" stiffness="500" damping="50" armature="0.02" range="-720.0000 720.0000"/>
                  <geom type="capsule" contype="1" conaffinity="1" density="500" fromto="-0.0015 0.0551 0.0025 -0.0059 0.2206 0.0102" size="0.047" name="L_Elbow"/>
                  <body name="L_Wrist" pos="-0.0074 0.2757 0.0127">
                    <joint name="L_Wrist_x" type="hinge" pos="0 0 0" axis="1 0 0" stiffness="300" damping="30" armature="0.02" range="-180.0000 180.0000"/>
                    <joint name="L_Wrist_y" type="hinge" pos="0 0 0" axis="0 1 0" stiffness="300" damping="30" armature="0.02" range="-180.0000 180.0000"/>
                    <joint name="L_Wrist_z" type="hinge" pos="0 0 0" axis="0 0 1" stiffness="300" damping="30" armature="0.02" range="-180.0000 180.0000"/>
                    <geom type="capsule" contype="1" conaffinity="1" density="500" fromto="-0.0032 0.0180 -0.0022 -0.0129 0.0721 -0.0087" size="0.0362" name="L_Wrist"/>
                    <body name="L_Hand" pos="-0.0161 0.0901 -0.0109">
                      <joint name="L_Hand_x" type="hinge" pos="0 0 0" axis="1 0 0" stiffness="300" damping="30" armature="0.02" range="-180.0000 180.0000"/>
                      <joint name="L_Hand_y" type="hinge" pos="0 0 0" axis="0 1 0" stiffness="300" damping="30" armature="0.02" range="-180.0000 180.0000"/>
                      <joint name="L_Hand_z" type="hinge" pos="0 0 0" axis="0 0 1" stiffness="300" damping="30" armature="0.02" range="-180.0000 180.0000"/>
                      <geom type="sphere" contype="1" conaffinity="1" density="500" size="0.0373" pos="0.0000 0.0000 0.0000" name="L_Hand"/>
                    </body>
                  </body>
                </body>
              </body>
            </body>
            <body name="R_Thorax" pos="-0.0258 -0.0887 0.1213">
              <joint name="R_Thorax_x" type="hinge" pos="0 0 0" axis="1 0 0" stiffness="500" damping="50" armature="0.02" range="-180.0000 180.0000"/>
              <joint name="R_Thorax_y" type="hinge" pos="0 0 0" axis="0 1 0" stiffness="500" damping="50" armature="0.02" range="-180.0000 180.0000"/>
              <joint name="R_Thorax_z" type="hinge" pos="0 0 0" axis="0 0 1" stiffness="500" damping="50" armature="0.02" range="-180.0000 180.0000"/>
              <geom type="capsule" contype="1" conaffinity="1" density="500" fromto="-0.0023 -0.0239 0.0089 -0.0092 -0.0954 0.0355" size="0.0569" name="R_Thorax"/>
              <body name="R_Shoulder" pos="-0.0115 -0.1193 0.0443">
                <joint name="R_Shoulder_x" type="hinge" pos="0 0 0" axis="1 0 0" stiffness="500" damping="50" armature="0.02" range="-720.0000 720.0000"/>
                <joint name="R_Shoulder_y" type="hinge" pos="0 0 0" axis="0 1 0" stiffness="500" damping="50" armature="0.02" range="-720.0000 720.0000"/>
                <joint name="R_Shoulder_z" type="hinge" pos="0 0 0" axis="0 0 1" stiffness="500" damping="50" armature="0.02" range="-720.0000 720.0000"/>
                <geom type="capsule" contype="1" conaffinity="1" density="500" fromto="-0.0074 -0.0540 -0.0020 -0.0297 -0.2160 -0.0079" size="0.0607" name="R_Shoulder"/>
                <body name="R_Elbow" pos="-0.0372 -0.27 -0.0099">
                  <joint name="R_Elbow_x" type="hinge" pos="0 0 0" axis="1 0 0" stiffness="500" damping="50" armature="0.02" range="-720.0000 720.0000"/>
                  <joint name="R_Elbow_y" type="hinge" pos="0 0 0" axis="0 1 0" stiffness="500" damping="50" armature="0.02" range="-720.0000 720.0000"/>
                  <joint name="R_Elbow_z" type="hinge" pos="0 0 0" axis="0 0 1" stiffness="500" damping="50" armature="0.02" range="-720.0000 720.0000"/>
                  <geom type="capsule" contype="1" conaffinity="1" density="500" fromto="-0.0016 -0.0553 0.0011 -0.0065 -0.2213 0.0045" size="0.0477" name="R_Elbow"/>
                  <body name="R_Wrist" pos="-0.0081 -0.2766 0.0057">
                    <joint name="R_Wrist_x" type="hinge" pos="0 0 0" axis="1 0 0" stiffness="300" damping="30" armature="0.02" range="-180.0000 180.0000"/>
                    <joint name="R_Wrist_y" type="hinge" pos="0 0 0" axis="0 1 0" stiffness="300" damping="30" armature="0.02" range="-180.0000 180.0000"/>
                    <joint name="R_Wrist_z" type="hinge" pos="0 0 0" axis="0 0 1" stiffness="300" damping="30" armature="0.02" range="-180.0000 180.0000"/>
                    <geom type="capsule" contype="1" conaffinity="1" density="500" fromto="-0.0020 -0.0183 -0.0018 -0.0080 -0.0732 -0.0072" size="0.0366" name="R_Wrist"/>
                    <body name="R_Hand" pos="-0.01 -0.0915 -0.0089">
                      <joint name="R_Hand_x" type="hinge" pos="0 0 0" axis="1 0 0" stiffness="300" damping="30" armature="0.02" range="-180.0000 180.0000"/>
                      <joint name="R_Hand_y" type="hinge" pos="0 0 0" axis="0 1 0" stiffness="300" damping="30" armature="0.02" range="-180.0000 180.0000"/>
                      <joint name="R_Hand_z" type="hinge" pos="0 0 0" axis="0 0 1" stiffness="300" damping="30" armature="0.02" range="-180.0000 180.0000"/>
                      <geom type="sphere" contype="1" conaffinity="1" density="500" size="0.0374" pos="0.0000 0.0000 0.0000" name="R_Hand"/>
                    </body>
                  </body>
                </body>
              </body>
            </body>
          </body>
        </body>
      </body>
    </body>
  </worldbody>
  <actuator>
    <motor name="L_Hip_x" joint="L_Hip_x" gear="500"/>
    <motor name="L_Hip_y" joint="L_Hip_y" gear="500"/>
    <motor name="L_Hip_z" joint="L_Hip_z" gear="500"/>
    <motor name="L_Knee_x" joint="L_Knee_x" gear="500"/>
    <motor name="L_Knee_y" joint="L_Knee_y" gear="500"/>
    <motor name="L_Knee_z" joint="L_Knee_z" gear="500"/>
    <motor name="L_Ankle_x" joint="L_Ankle_x" gear="500"/>
    <motor name="L_Ankle_y" joint="L_Ankle_y" gear="500"/>
    <motor name="L_Ankle_z" joint="L_Ankle_z" gear="500"/>
    <motor name="L_Toe_x" joint="L_Toe_x" gear="500"/>
    <motor name="L_Toe_y" joint="L_Toe_y" gear="500"/>
    <motor name="L_Toe_z" joint="L_Toe_z" gear="500"/>
    <motor name="R_Hip_x" joint="R_Hip_x" gear="500"/>
    <motor name="R_Hip_y" joint="R_Hip_y" gear="500"/>
    <motor name="R_Hip_z" joint="R_Hip_z" gear="500"/>
    <motor name="R_Knee_x" joint="R_Knee_x" gear="500"/>
    <motor name="R_Knee_y" joint="R_Knee_y" gear="500"/>
    <motor name="R_Knee_z" joint="R_Knee_z" gear="500"/>
    <motor name="R_Ankle_x" joint="R_Ankle_x" gear="500"/>
    <motor name="R_Ankle_y" joint="R_Ankle_y" gear="500"/>
    <motor name="R_Ankle_z" joint="R_Ankle_z" gear="500"/>
    <motor name="R_Toe_x" joint="R_Toe_x" gear="500"/>
    <motor name="R_Toe_y" joint="R_Toe_y" gear="500"/>
    <motor name="R_Toe_z" joint="R_Toe_z" gear="500"/>
    <motor name="Torso_x" joint="Torso_x" gear="500"/>
    <motor name="Torso_y" joint="Torso_y" gear="500"/>
    <motor name="Torso_z" joint="Torso_z" gear="500"/>
    <motor name="Spine_x" joint="Spine_x" gear="500"/>
    <motor name="Spine_y" joint="Spine_y" gear="500"/>
    <motor name="Spine_z" joint="Spine_z" gear="500"/>
    <motor name="Chest_x" joint="Chest_x" gear="500"/>
    <motor name="Chest_y" joint="Chest_y" gear="500"/>
    <motor name="Chest_z" joint="Chest_z" gear="500"/>
    <motor name="Neck_x" joint="Neck_x" gear="500"/>
    <motor name="Neck_y" joint="Neck_y" gear="500"/>
    <motor name="Neck_z" joint="Neck_z" gear="500"/>
    <motor name="Head_x" joint="Head_x" gear="500"/>
    <motor name="Head_y" joint="Head_y" gear="500"/>
    <motor name="Head_z" joint="Head_z" gear="500"/>
    <motor name="L_Thorax_x" joint="L_Thorax_x" gear="500"/>
    <motor name="L_Thorax_y" joint="L_Thorax_y" gear="500"/>
    <motor name="L_Thorax_z" joint="L_Thorax_z" gear="500"/>
    <motor name="L_Shoulder_x" joint="L_Shoulder_x" gear="500"/>
    <motor name="L_Shoulder_y" joint="L_Shoulder_y" gear="500"/>
    <motor name="L_Shoulder_z" joint="L_Shoulder_z" gear="500"/>
    <motor name="L_Elbow_x" joint="L_Elbow_x" gear="500"/>
    <motor name="L_Elbow_y" joint="L_Elbow_y" gear="500"/>
    <motor name="L_Elbow_z" joint="L_Elbow_z" gear="500"/>
    <motor name="L_Wrist_x" joint="L_Wrist_x" gear="500"/>
    <motor name="L_Wrist_y" joint="L_Wrist_y" gear="500"/>
    <motor name="L_Wrist_z" joint="L_Wrist_z" gear="500"/>
    <motor name="L_Hand_x" joint="L_Hand_x" gear="500"/>
    <motor name="L_Hand_y" joint="L_Hand_y" gear="500"/>
    <motor name="L_Hand_z" joint="L_Hand_z" gear="500"/>
    <motor name="R_Thorax_x" joint="R_Thorax_x" gear="500"/>
    <motor name="R_Thorax_y" joint="R_Thorax_y" gear="500"/>
    <motor name="R_Thorax_z" joint="R_Thorax_z" gear="500"/>
    <motor name="R_Shoulder_x" joint="R_Shoulder_x" gear="500"/>
    <motor name="R_Shoulder_y" joint="R_Shoulder_y" gear="500"/>
    <motor name="R_Shoulder_z" joint="R_Shoulder_z" gear="500"/>
    <motor name="R_Elbow_x" joint="R_Elbow_x" gear="500"/>
    <motor name="R_Elbow_y" joint="R_Elbow_y" gear="500"/>
    <motor name="R_Elbow_z" joint="R_Elbow_z" gear="500"/>
    <motor name="R_Wrist_x" joint="R_Wrist_x" gear="500"/>
    <motor name="R_Wrist_y" joint="R_Wrist_y" gear="500"/>
    <motor name="R_Wrist_z" joint="R_Wrist_z" gear="500"/>
    <motor name="R_Hand_x" joint="R_Hand_x" gear="500"/>
    <motor name="R_Hand_y" joint="R_Hand_y" gear="500"/>
    <motor name="R_Hand_z" joint="R_Hand_z" gear="500"/>
  </actuator>
  <contact>
    <exclude body1="Torso" body2="Chest"/>
    <exclude body1="Head" body2="Chest"/>
    <exclude body1="R_Knee" body2="R_Toe"/>
    <exclude body1="R_Knee" body2="L_Ankle"/>
    <exclude body1="R_Knee" body2="L_Toe"/>
    <exclude body1="L_Knee" body2="L_Toe"/>
    <exclude body1="L_Knee" body2="R_Ankle"/>
    <exclude body1="L_Knee" body2="R_Toe"/>
    <exclude body1="L_Shoulder" body2="Chest"/>
    <exclude body1="R_Shoulder" body2="Chest"/>
  </contact>
  <sensor/>
  <size njmax="700" nconmax="700"/>
</mujoco>
