<mujoco model="humanoid">
  <compiler coordinate="local" angle="radian"/>
  <default>
    <joint damping="0.0" armature="0.01" stiffness="0.0" limited="true"/>
    <geom conaffinity="1" condim="3" contype="7" margin="0.001" rgba="0.8 0.6 .4 1"/>
  </default>
  <asset>
    <texture type="skybox" builtin="gradient" rgb1=".4 .5 .6" rgb2="0 0 0" width="100" height="100"/>
    <texture builtin="flat" height="1278" mark="cross" markrgb="1 1 1" name="texgeom" random="0.01" rgb1="0.8 0.6 0.4" rgb2="0.8 0.6 0.4" type="cube" width="127"/>
    <texture builtin="checker" height="100" name="texplane" rgb1="0 0 0" rgb2="0.8 0.8 0.8" type="2d" width="100"/>
    <material name="MatPlane" reflectance="0.5" shininess="1" specular="1" texrepeat="60 60" texture="texplane"/>
    <material name="geom" texture="texgeom" texuniform="true"/>
  </asset>
  <worldbody>
    <light cutoff="100" diffuse="1 1 1" dir="-0 0 -1.3" directional="true" exponent="1" pos="0 0 1.3" specular=".1 .1 .1"/>
    <geom conaffinity="1" condim="3" name="floor" pos="0 0 0" rgba="0.8 0.9 0.8 1" size="100 100 .2" type="plane" material="MatPlane"/>
    <body name="Pelvis" pos="-0.0035 -0.2119 0.0206">
      <freejoint name="Pelvis"/>
      <geom type="sphere" contype="1" conaffinity="1" density="500" size="0.0825" pos="0.0000 0.0000 0.0000" name="Pelvis"/>
      <body name="L_Hip" pos="-0.022 0.0491 -0.0785">
        <joint name="L_Hip_x" type="hinge" pos="0 0 0" axis="1 0 0" stiffness="800" damping="80" armature="0.02" range="-180.0000 180.0000"/>
        <joint name="L_Hip_y" type="hinge" pos="0 0 0" axis="0 1 0" stiffness="800" damping="80" armature="0.02" range="-180.0000 180.0000"/>
        <joint name="L_Hip_z" type="hinge" pos="0 0 0" axis="0 0 1" stiffness="800" damping="80" armature="0.02" range="-180.0000 180.0000"/>
        <geom type="capsule" contype="1" conaffinity="1" density="500" fromto="0.0034 0.0118 -0.0905 0.0136 0.0471 -0.3620" size="0.0551" name="L_Hip"/>
        <body name="L_Knee" pos="0.017 0.0589 -0.4524">
          <joint name="L_Knee_x" type="hinge" pos="0 0 0" axis="1 0 0" stiffness="800" damping="80" armature="0.02" range="-180.0000 180.0000"/>
          <joint name="L_Knee_y" type="hinge" pos="0 0 0" axis="0 1 0" stiffness="800" damping="80" armature="0.02" range="-180.0000 180.0000"/>
          <joint name="L_Knee_z" type="hinge" pos="0 0 0" axis="0 0 1" stiffness="800" damping="80" armature="0.02" range="-180.0000 180.0000"/>
          <geom type="capsule" contype="1" conaffinity="1" density="500" fromto="-0.0063 -0.0025 -0.0996 -0.0251 -0.0101 -0.3986" size="0.0497" name="L_Knee"/>
          <body name="L_Ankle" pos="-0.0313 -0.0126 -0.4982">
            <joint name="L_Ankle_x" type="hinge" pos="0 0 0" axis="1 0 0" stiffness="800" damping="80" armature="0.02" range="-180.0000 180.0000"/>
            <joint name="L_Ankle_y" type="hinge" pos="0 0 0" axis="0 1 0" stiffness="800" damping="80" armature="0.02" range="-180.0000 180.0000"/>
            <joint name="L_Ankle_z" type="hinge" pos="0 0 0" axis="0 0 1" stiffness="800" damping="80" armature="0.02" range="-180.0000 180.0000"/>
            <geom type="box" contype="1" conaffinity="1" density="500" pos="0.0641 0.0276 -0.0341" size="0.091 0.0576 0.02" quat="0.9794 0.0000 0.0000 0.2020" name="L_Ankle"/>
            <body name="L_Toe" pos="0.1282 0.0552 -0.0682">
              <joint name="L_Toe_x" type="hinge" pos="0 0 0" axis="1 0 0" stiffness="500" damping="50" armature="0.02" range="-180.0000 180.0000"/>
              <joint name="L_Toe_y" type="hinge" pos="0 0 0" axis="0 1 0" stiffness="500" damping="50" armature="0.02" range="-180.0000 180.0000"/>
              <joint name="L_Toe_z" type="hinge" pos="0 0 0" axis="0 0 1" stiffness="500" damping="50" armature="0.02" range="-180.0000 180.0000"/>
              <geom type="box" contype="1" conaffinity="1" density="500" pos="0.0000 0.0000 0.0369" size="0.001 0.0027 0.0011" quat="0.9786 0.0000 0.0000 0.2056" name="L_Toe"/>
            </body>
          </body>
        </body>
      </body>
      <body name="R_Hip" pos="-0.0204 -0.0491 -0.0866">
        <joint name="R_Hip_x" type="hinge" pos="0 0 0" axis="1 0 0" stiffness="800" damping="80" armature="0.02" range="-180.0000 180.0000"/>
        <joint name="R_Hip_y" type="hinge" pos="0 0 0" axis="0 1 0" stiffness="800" damping="80" armature="0.02" range="-180.0000 180.0000"/>
        <joint name="R_Hip_z" type="hinge" pos="0 0 0" axis="0 0 1" stiffness="800" damping="80" armature="0.02" range="-180.0000 180.0000"/>
        <geom type="capsule" contype="1" conaffinity="1" density="500" fromto="0.0003 -0.0114 -0.0888 0.0012 -0.0457 -0.3552" size="0.0538" name="R_Hip"/>
        <body name="R_Knee" pos="0.0016 -0.0571 -0.444">
          <joint name="R_Knee_x" type="hinge" pos="0 0 0" axis="1 0 0" stiffness="800" damping="80" armature="0.02" range="-180.0000 180.0000"/>
          <joint name="R_Knee_y" type="hinge" pos="0 0 0" axis="0 1 0" stiffness="800" damping="80" armature="0.02" range="-180.0000 180.0000"/>
          <joint name="R_Knee_z" type="hinge" pos="0 0 0" axis="0 0 1" stiffness="800" damping="80" armature="0.02" range="-180.0000 180.0000"/>
          <geom type="capsule" contype="1" conaffinity="1" density="500" fromto="-0.0057 0.0040 -0.0981 -0.0227 0.0159 -0.3923" size="0.0502" name="R_Knee"/>
          <body name="R_Ankle" pos="-0.0284 0.0199 -0.4903">
            <joint name="R_Ankle_x" type="hinge" pos="0 0 0" axis="1 0 0" stiffness="800" damping="80" armature="0.02" range="-180.0000 180.0000"/>
            <joint name="R_Ankle_y" type="hinge" pos="0 0 0" axis="0 1 0" stiffness="800" damping="80" armature="0.02" range="-180.0000 180.0000"/>
            <joint name="R_Ankle_z" type="hinge" pos="0 0 0" axis="0 0 1" stiffness="800" damping="80" armature="0.02" range="-180.0000 180.0000"/>
            <geom type="box" contype="1" conaffinity="1" density="500" pos="0.0687 -0.0183 -0.0361" size="0.0964 0.0489 0.0222" quat="0.9915 0.0000 0.0000 -0.1301" name="R_Ankle"/>
            <body name="R_Toe" pos="0.1374 -0.0367 -0.0721">
              <joint name="R_Toe_x" type="hinge" pos="0 0 0" axis="1 0 0" stiffness="500" damping="50" armature="0.02" range="-180.0000 180.0000"/>
              <joint name="R_Toe_y" type="hinge" pos="0 0 0" axis="0 1 0" stiffness="500" damping="50" armature="0.02" range="-180.0000 180.0000"/>
              <joint name="R_Toe_z" type="hinge" pos="0 0 0" axis="0 0 1" stiffness="500" damping="50" armature="0.02" range="-180.0000 180.0000"/>
              <geom type="box" contype="1" conaffinity="1" density="500" pos="0.0000 0.0000 0.0366" size="0.001 0.0024 0.0011" quat="0.9926 0.0000 0.0000 -0.1217" name="R_Toe"/>
            </body>
          </body>
        </body>
      </body>
      <body name="Torso" pos="-0.0296 0.0048 0.1158">
        <joint name="Torso_x" type="hinge" pos="0 0 0" axis="1 0 0" stiffness="1000" damping="100" armature="0.02" range="-180.0000 180.0000"/>
        <joint name="Torso_y" type="hinge" pos="0 0 0" axis="0 1 0" stiffness="1000" damping="100" armature="0.02" range="-180.0000 180.0000"/>
        <joint name="Torso_z" type="hinge" pos="0 0 0" axis="0 0 1" stiffness="1000" damping="100" armature="0.02" range="-180.0000 180.0000"/>
        <geom type="capsule" contype="1" conaffinity="1" density="500" fromto="0.0149 0.0021 0.0778 0.0099 0.0014 0.0519" size="0.0653" name="Torso"/>
        <body name="Spine" pos="0.0248 0.0035 0.1297">
          <joint name="Spine_x" type="hinge" pos="0 0 0" axis="1 0 0" stiffness="1000" damping="100" armature="0.02" range="-180.0000 180.0000"/>
          <joint name="Spine_y" type="hinge" pos="0 0 0" axis="0 1 0" stiffness="1000" damping="100" armature="0.02" range="-180.0000 180.0000"/>
          <joint name="Spine_z" type="hinge" pos="0 0 0" axis="0 0 1" stiffness="1000" damping="100" armature="0.02" range="-180.0000 180.0000"/>
          <geom type="capsule" contype="1" conaffinity="1" density="500" fromto="-0.0019 -0.0009 0.0315 -0.0012 -0.0006 0.0210" size="0.0667" name="Spine"/>
          <body name="Chest" pos="-0.0031 -0.0016 0.0525">
            <joint name="Chest_x" type="hinge" pos="0 0 0" axis="1 0 0" stiffness="1000" damping="100" armature="0.02" range="-180.0000 180.0000"/>
            <joint name="Chest_y" type="hinge" pos="0 0 0" axis="0 1 0" stiffness="1000" damping="100" armature="0.02" range="-180.0000 180.0000"/>
            <joint name="Chest_z" type="hinge" pos="0 0 0" axis="0 0 1" stiffness="1000" damping="100" armature="0.02" range="-180.0000 180.0000"/>
            <geom type="capsule" contype="1" conaffinity="1" density="500" fromto="-0.0112 -0.0050 0.0886 -0.0075 -0.0034 0.0590" size="0.0955" name="Chest"/>
            <body name="Neck" pos="-0.0201 -0.0144 0.2147">
              <joint name="Neck_x" type="hinge" pos="0 0 0" axis="1 0 0" stiffness="500" damping="50" armature="0.02" range="-180.0000 180.0000"/>
              <joint name="Neck_y" type="hinge" pos="0 0 0" axis="0 1 0" stiffness="500" damping="50" armature="0.02" range="-180.0000 180.0000"/>
              <joint name="Neck_z" type="hinge" pos="0 0 0" axis="0 0 1" stiffness="500" damping="50" armature="0.02" range="-180.0000 180.0000"/>
              <geom type="capsule" contype="1" conaffinity="1" density="500" fromto="0.0101 0.0022 0.0198 0.0403 0.0087 0.0791" size="0.0438" name="Neck"/>
              <body name="Head" pos="0.0504 0.0109 0.0989">
                <joint name="Head_x" type="hinge" pos="0 0 0" axis="1 0 0" stiffness="500" damping="50" armature="0.02" range="-180.0000 180.0000"/>
                <joint name="Head_y" type="hinge" pos="0 0 0" axis="0 1 0" stiffness="500" damping="50" armature="0.02" range="-180.0000 180.0000"/>
                <joint name="Head_z" type="hinge" pos="0 0 0" axis="0 0 1" stiffness="500" damping="50" armature="0.02" range="-180.0000 180.0000"/>
                <geom type="sphere" contype="1" conaffinity="1" density="500" size="0.0998" pos="0.0000 0.0000 0.0000" name="Head"/>
              </body>
            </body>
            <body name="L_Thorax" pos="-0.0157 0.0717 0.1151">
              <joint name="L_Thorax_x" type="hinge" pos="0 0 0" axis="1 0 0" stiffness="500" damping="50" armature="0.02" range="-180.0000 180.0000"/>
              <joint name="L_Thorax_y" type="hinge" pos="0 0 0" axis="0 1 0" stiffness="500" damping="50" armature="0.02" range="-180.0000 180.0000"/>
              <joint name="L_Thorax_z" type="hinge" pos="0 0 0" axis="0 0 1" stiffness="500" damping="50" armature="0.02" range="-180.0000 180.0000"/>
              <geom type="capsule" contype="1" conaffinity="1" density="500" fromto="-0.0024 0.0240 0.0107 -0.0096 0.0961 0.0430" size="0.0522" name="L_Thorax"/>
              <body name="L_Shoulder" pos="-0.012 0.1202 0.0537">
                <joint name="L_Shoulder_x" type="hinge" pos="0 0 0" axis="1 0 0" stiffness="500" damping="50" armature="0.02" range="-720.0000 720.0000"/>
                <joint name="L_Shoulder_y" type="hinge" pos="0 0 0" axis="0 1 0" stiffness="500" damping="50" armature="0.02" range="-720.0000 720.0000"/>
                <joint name="L_Shoulder_z" type="hinge" pos="0 0 0" axis="0 0 1" stiffness="500" damping="50" armature="0.02" range="-720.0000 720.0000"/>
                <geom type="capsule" contype="1" conaffinity="1" density="500" fromto="-0.0048 0.0588 -0.0049 -0.0190 0.2354 -0.0196" size="0.0522" name="L_Shoulder"/>
                <body name="L_Elbow" pos="-0.0238 0.2942 -0.0245">
                  <joint name="L_Elbow_x" type="hinge" pos="0 0 0" axis="1 0 0" stiffness="500" damping="50" armature="0.02" range="-720.0000 720.0000"/>
                  <joint name="L_Elbow_y" type="hinge" pos="0 0 0" axis="0 1 0" stiffness="500" damping="50" armature="0.02" range="-720.0000 720.0000"/>
                  <joint name="L_Elbow_z" type="hinge" pos="0 0 0" axis="0 0 1" stiffness="500" damping="50" armature="0.02" range="-720.0000 720.0000"/>
                  <geom type="capsule" contype="1" conaffinity="1" density="500" fromto="-0.0017 0.0599 0.0029 -0.0070 0.2394 0.0117" size="0.0401" name="L_Elbow"/>
                  <body name="L_Wrist" pos="-0.0087 0.2993 0.0146">
                    <joint name="L_Wrist_x" type="hinge" pos="0 0 0" axis="1 0 0" stiffness="300" damping="30" armature="0.02" range="-180.0000 180.0000"/>
                    <joint name="L_Wrist_y" type="hinge" pos="0 0 0" axis="0 1 0" stiffness="300" damping="30" armature="0.02" range="-180.0000 180.0000"/>
                    <joint name="L_Wrist_z" type="hinge" pos="0 0 0" axis="0 0 1" stiffness="300" damping="30" armature="0.02" range="-180.0000 180.0000"/>
                    <geom type="capsule" contype="1" conaffinity="1" density="500" fromto="-0.0034 0.0185 -0.0022 -0.0137 0.0740 -0.0088" size="0.0351" name="L_Wrist"/>
                    <body name="L_Hand" pos="-0.0172 0.0925 -0.011">
                      <joint name="L_Hand_x" type="hinge" pos="0 0 0" axis="1 0 0" stiffness="300" damping="30" armature="0.02" range="-180.0000 180.0000"/>
                      <joint name="L_Hand_y" type="hinge" pos="0 0 0" axis="0 1 0" stiffness="300" damping="30" armature="0.02" range="-180.0000 180.0000"/>
                      <joint name="L_Hand_z" type="hinge" pos="0 0 0" axis="0 0 1" stiffness="300" damping="30" armature="0.02" range="-180.0000 180.0000"/>
                      <geom type="sphere" contype="1" conaffinity="1" density="500" size="0.0375" pos="0.0000 0.0000 0.0000" name="L_Hand"/>
                    </body>
                  </body>
                </body>
              </body>
            </body>
            <body name="R_Thorax" pos="-0.0203 -0.0825 0.1131">
              <joint name="R_Thorax_x" type="hinge" pos="0 0 0" axis="1 0 0" stiffness="500" damping="50" armature="0.02" range="-180.0000 180.0000"/>
              <joint name="R_Thorax_y" type="hinge" pos="0 0 0" axis="0 1 0" stiffness="500" damping="50" armature="0.02" range="-180.0000 180.0000"/>
              <joint name="R_Thorax_z" type="hinge" pos="0 0 0" axis="0 0 1" stiffness="500" damping="50" armature="0.02" range="-180.0000 180.0000"/>
              <geom type="capsule" contype="1" conaffinity="1" density="500" fromto="-0.0006 -0.0221 0.0113 -0.0024 -0.0883 0.0451" size="0.0525" name="R_Thorax"/>
              <body name="R_Shoulder" pos="-0.003 -0.1104 0.0564">
                <joint name="R_Shoulder_x" type="hinge" pos="0 0 0" axis="1 0 0" stiffness="500" damping="50" armature="0.02" range="-720.0000 720.0000"/>
                <joint name="R_Shoulder_y" type="hinge" pos="0 0 0" axis="0 1 0" stiffness="500" damping="50" armature="0.02" range="-720.0000 720.0000"/>
                <joint name="R_Shoulder_z" type="hinge" pos="0 0 0" axis="0 0 1" stiffness="500" damping="50" armature="0.02" range="-720.0000 720.0000"/>
                <geom type="capsule" contype="1" conaffinity="1" density="500" fromto="-0.0054 -0.0593 -0.0058 -0.0216 -0.2370 -0.0232" size="0.0538" name="R_Shoulder"/>
                <body name="R_Elbow" pos="-0.027 -0.2963 -0.029">
                  <joint name="R_Elbow_x" type="hinge" pos="0 0 0" axis="1 0 0" stiffness="500" damping="50" armature="0.02" range="-720.0000 720.0000"/>
                  <joint name="R_Elbow_y" type="hinge" pos="0 0 0" axis="0 1 0" stiffness="500" damping="50" armature="0.02" range="-720.0000 720.0000"/>
                  <joint name="R_Elbow_z" type="hinge" pos="0 0 0" axis="0 0 1" stiffness="500" damping="50" armature="0.02" range="-720.0000 720.0000"/>
                  <geom type="capsule" contype="1" conaffinity="1" density="500" fromto="-0.0011 -0.0610 0.0024 -0.0046 -0.2439 0.0094" size="0.0405" name="R_Elbow"/>
                  <body name="R_Wrist" pos="-0.0057 -0.3048 0.0118">
                    <joint name="R_Wrist_x" type="hinge" pos="0 0 0" axis="1 0 0" stiffness="300" damping="30" armature="0.02" range="-180.0000 180.0000"/>
                    <joint name="R_Wrist_y" type="hinge" pos="0 0 0" axis="0 1 0" stiffness="300" damping="30" armature="0.02" range="-180.0000 180.0000"/>
                    <joint name="R_Wrist_z" type="hinge" pos="0 0 0" axis="0 0 1" stiffness="300" damping="30" armature="0.02" range="-180.0000 180.0000"/>
                    <geom type="capsule" contype="1" conaffinity="1" density="500" fromto="-0.0023 -0.0186 -0.0017 -0.0091 -0.0742 -0.0070" size="0.0351" name="R_Wrist"/>
                    <body name="R_Hand" pos="-0.0114 -0.0928 -0.0087">
                      <joint name="R_Hand_x" type="hinge" pos="0 0 0" axis="1 0 0" stiffness="300" damping="30" armature="0.02" range="-180.0000 180.0000"/>
                      <joint name="R_Hand_y" type="hinge" pos="0 0 0" axis="0 1 0" stiffness="300" damping="30" armature="0.02" range="-180.0000 180.0000"/>
                      <joint name="R_Hand_z" type="hinge" pos="0 0 0" axis="0 0 1" stiffness="300" damping="30" armature="0.02" range="-180.0000 180.0000"/>
                      <geom type="sphere" contype="1" conaffinity="1" density="500" size="0.0373" pos="0.0000 0.0000 0.0000" name="R_Hand"/>
                    </body>
                  </body>
                </body>
              </body>
            </body>
          </body>
        </body>
      </body>
    </body>
  </worldbody>
  <actuator>
    <motor name="L_Hip_x" joint="L_Hip_x" gear="500"/>
    <motor name="L_Hip_y" joint="L_Hip_y" gear="500"/>
    <motor name="L_Hip_z" joint="L_Hip_z" gear="500"/>
    <motor name="L_Knee_x" joint="L_Knee_x" gear="500"/>
    <motor name="L_Knee_y" joint="L_Knee_y" gear="500"/>
    <motor name="L_Knee_z" joint="L_Knee_z" gear="500"/>
    <motor name="L_Ankle_x" joint="L_Ankle_x" gear="500"/>
    <motor name="L_Ankle_y" joint="L_Ankle_y" gear="500"/>
    <motor name="L_Ankle_z" joint="L_Ankle_z" gear="500"/>
    <motor name="L_Toe_x" joint="L_Toe_x" gear="500"/>
    <motor name="L_Toe_y" joint="L_Toe_y" gear="500"/>
    <motor name="L_Toe_z" joint="L_Toe_z" gear="500"/>
    <motor name="R_Hip_x" joint="R_Hip_x" gear="500"/>
    <motor name="R_Hip_y" joint="R_Hip_y" gear="500"/>
    <motor name="R_Hip_z" joint="R_Hip_z" gear="500"/>
    <motor name="R_Knee_x" joint="R_Knee_x" gear="500"/>
    <motor name="R_Knee_y" joint="R_Knee_y" gear="500"/>
    <motor name="R_Knee_z" joint="R_Knee_z" gear="500"/>
    <motor name="R_Ankle_x" joint="R_Ankle_x" gear="500"/>
    <motor name="R_Ankle_y" joint="R_Ankle_y" gear="500"/>
    <motor name="R_Ankle_z" joint="R_Ankle_z" gear="500"/>
    <motor name="R_Toe_x" joint="R_Toe_x" gear="500"/>
    <motor name="R_Toe_y" joint="R_Toe_y" gear="500"/>
    <motor name="R_Toe_z" joint="R_Toe_z" gear="500"/>
    <motor name="Torso_x" joint="Torso_x" gear="500"/>
    <motor name="Torso_y" joint="Torso_y" gear="500"/>
    <motor name="Torso_z" joint="Torso_z" gear="500"/>
    <motor name="Spine_x" joint="Spine_x" gear="500"/>
    <motor name="Spine_y" joint="Spine_y" gear="500"/>
    <motor name="Spine_z" joint="Spine_z" gear="500"/>
    <motor name="Chest_x" joint="Chest_x" gear="500"/>
    <motor name="Chest_y" joint="Chest_y" gear="500"/>
    <motor name="Chest_z" joint="Chest_z" gear="500"/>
    <motor name="Neck_x" joint="Neck_x" gear="500"/>
    <motor name="Neck_y" joint="Neck_y" gear="500"/>
    <motor name="Neck_z" joint="Neck_z" gear="500"/>
    <motor name="Head_x" joint="Head_x" gear="500"/>
    <motor name="Head_y" joint="Head_y" gear="500"/>
    <motor name="Head_z" joint="Head_z" gear="500"/>
    <motor name="L_Thorax_x" joint="L_Thorax_x" gear="500"/>
    <motor name="L_Thorax_y" joint="L_Thorax_y" gear="500"/>
    <motor name="L_Thorax_z" joint="L_Thorax_z" gear="500"/>
    <motor name="L_Shoulder_x" joint="L_Shoulder_x" gear="500"/>
    <motor name="L_Shoulder_y" joint="L_Shoulder_y" gear="500"/>
    <motor name="L_Shoulder_z" joint="L_Shoulder_z" gear="500"/>
    <motor name="L_Elbow_x" joint="L_Elbow_x" gear="500"/>
    <motor name="L_Elbow_y" joint="L_Elbow_y" gear="500"/>
    <motor name="L_Elbow_z" joint="L_Elbow_z" gear="500"/>
    <motor name="L_Wrist_x" joint="L_Wrist_x" gear="500"/>
    <motor name="L_Wrist_y" joint="L_Wrist_y" gear="500"/>
    <motor name="L_Wrist_z" joint="L_Wrist_z" gear="500"/>
    <motor name="L_Hand_x" joint="L_Hand_x" gear="500"/>
    <motor name="L_Hand_y" joint="L_Hand_y" gear="500"/>
    <motor name="L_Hand_z" joint="L_Hand_z" gear="500"/>
    <motor name="R_Thorax_x" joint="R_Thorax_x" gear="500"/>
    <motor name="R_Thorax_y" joint="R_Thorax_y" gear="500"/>
    <motor name="R_Thorax_z" joint="R_Thorax_z" gear="500"/>
    <motor name="R_Shoulder_x" joint="R_Shoulder_x" gear="500"/>
    <motor name="R_Shoulder_y" joint="R_Shoulder_y" gear="500"/>
    <motor name="R_Shoulder_z" joint="R_Shoulder_z" gear="500"/>
    <motor name="R_Elbow_x" joint="R_Elbow_x" gear="500"/>
    <motor name="R_Elbow_y" joint="R_Elbow_y" gear="500"/>
    <motor name="R_Elbow_z" joint="R_Elbow_z" gear="500"/>
    <motor name="R_Wrist_x" joint="R_Wrist_x" gear="500"/>
    <motor name="R_Wrist_y" joint="R_Wrist_y" gear="500"/>
    <motor name="R_Wrist_z" joint="R_Wrist_z" gear="500"/>
    <motor name="R_Hand_x" joint="R_Hand_x" gear="500"/>
    <motor name="R_Hand_y" joint="R_Hand_y" gear="500"/>
    <motor name="R_Hand_z" joint="R_Hand_z" gear="500"/>
  </actuator>
  <contact>
    <exclude body1="Torso" body2="Chest"/>
    <exclude body1="Head" body2="Chest"/>
    <exclude body1="R_Knee" body2="R_Toe"/>
    <exclude body1="R_Knee" body2="L_Ankle"/>
    <exclude body1="R_Knee" body2="L_Toe"/>
    <exclude body1="L_Knee" body2="L_Toe"/>
    <exclude body1="L_Knee" body2="R_Ankle"/>
    <exclude body1="L_Knee" body2="R_Toe"/>
    <exclude body1="L_Shoulder" body2="Chest"/>
    <exclude body1="R_Shoulder" body2="Chest"/>
  </contact>
  <sensor/>
  <size njmax="700" nconmax="700"/>
</mujoco>
